{
  "name": "multi_filmworkstower_9_floor4",
  "refpalette": "deceasedcraft:multi_filmworkstower_9/multi_filmworkstower_9_floor4_palette",
  "xsize": 16,
  "zsize": 16,
  "slices": [
    [
      "aaab            ",
      "aaabc           ",
      "aaab            ",
      "aaab            ",
      "aaabc           ",
      "aaab            ",
      "aaab            ",
      "aaabc           ",
      "aaab            ",
      "aaab            ",
      "aaabc           ",
      "aaab            ",
      "aaa dde         ",
      "aaab            ",
      "aaabc           ",
      "bbb             "
    ],
    [
      "   b            ",
      "fghbc           ",
      "iiib            ",
      "iiib            ",
      "jklbc           ",
      "   b            ",
      "mmmb            ",
      "   bc           ",
      "fghb            ",
      "iiib            ",
      "jklbc           ",
      "   b            ",
      "mmmndde         ",
      "   b            ",
      "fghbc           ",
      "bbb             "
    ],
    [
      "   b            ",
      "   bc           ",
      "opob            ",
      "ooob            ",
      "   bc           ",
      "   b            ",
      "q rb            ",
      "   bc           ",
      "   b            ",
      "ooob            ",
      "   bc           ",
      "   b            ",
      "!s ndde         ",
      "   b            ",
      "   bc           ",
      "bbb             "
    ],
    [
      "   b            ",
      "   bc           ",
      "   b            ",
      "   b            ",
      "   bc           ",
      "   b            ",
      "   b            ",
      "   bc           ",
      "   b            ",
      "   b            ",
      "   bc           ",
      "   b            ",
      "   ndde         ",
      "   b            ",
      "   bc           ",
      "bbb             "
    ],
    [
      "   b            ",
      "   bc           ",
      "   b            ",
      "   b            ",
      "   bc           ",
      "   b            ",
      "   b            ",
      "   bc           ",
      "   b            ",
      "   b            ",
      "   bc           ",
      "   b            ",
      "   ndde         ",
      "   b            ",
      "   bc           ",
      "bbb             "
    ],
    [
      "tttb            ",
      "tttbc           ",
      "tttb            ",
      "uttb            ",
      "tttbc           ",
      "tttb            ",
      "tttb            ",
      "tttbc           ",
      "uttb            ",
      "tttb            ",
      "tttbc           ",
      "tttb            ",
      "wwwwdde         ",
      "uttb            ",
      "tttbc           ",
      "bbb             "
    ]
  ]
}