{
  "name": "multi_filmworkstower_9_floor7",
  "refpalette": "deceasedcraft:multi_filmworkstower_9/multi_filmworkstower_9_floor7_palette",
  "xsize": 16,
  "zsize": 16,
  "slices": [
    [
      "aaab            ",
      "aaabc           ",
      "aaab            ",
      "aaab            ",
      "aaabc           ",
      "aaab            ",
      "aaab            ",
      "aaabc           ",
      "aaab            ",
      "aaab            ",
      "aaabc           ",
      "aaab            ",
      "aaa dde         ",
      "aaab            ",
      "aaabc           ",
      "bbb             "
    ],
    [
      " fgb            ",
      "  gbc           ",
      "  hb            ",
      " ijb            ",
      "  kbc           ",
      "  gb            ",
      "  gb            ",
      "  hbc           ",
      " ijb            ",
      "  kb            ",
      "  gbc           ",
      " lgb            ",
      "l hmdde         ",
      " ijb            ",
      "  kbc           ",
      "bbb             "
    ],
    [
      "  nb            ",
      "  obc           ",
      "  fb            ",
      "  pb            ",
      "  qbc           ",
      "  lb            ",
      "  rb            ",
      "  sbc           ",
      "  pb            ",
      "  qb            ",
      "  tbc           ",
      "  ob            ",
      "  omdde         ",
      "  pb            ",
      "  qbc           ",
      "bbb             "
    ],
    [
      "   b            ",
      "   bc           ",
      "   b            ",
      "   b            ",
      "   bc           ",
      "   b            ",
      "   b            ",
      "   bc           ",
      "   b            ",
      "   b            ",
      "   bc           ",
      "   b            ",
      "   mdde         ",
      "   b            ",
      "   bc           ",
      "bbb             "
    ],
    [
      "   b            ",
      "   bc           ",
      "   b            ",
      "   b            ",
      "   bc           ",
      "   b            ",
      "   b            ",
      "   bc           ",
      "   b            ",
      "   b            ",
      "   bc           ",
      "   b            ",
      "   mdde         ",
      "   b            ",
      "   bc           ",
      "bbb             "
    ],
    [
      "uuub            ",
      "uuubc           ",
      "uuub            ",
      "wuub            ",
      "uuubc           ",
      "uuub            ",
      "uuub            ",
      "uuubc           ",
      "wuub            ",
      "uuub            ",
      "uuubc           ",
      "uuub            ",
      "xxxxdde         ",
      "wuub            ",
      "uuubc           ",
      "bbb             "
    ]
  ]
}