{
  "name": "multi_filmworkstower_9_floor9",
  "refpalette": "deceasedcraft:multi_filmworkstower_9/multi_filmworkstower_9_floor9_palette",
  "xsize": 16,
  "zsize": 16,
  "slices": [
    [
      "aaab            ",
      "aaabc           ",
      "aaab            ",
      "aaab            ",
      "aaabc           ",
      "aaab            ",
      "aaab            ",
      "aaabc           ",
      "aaab            ",
      "aaab            ",
      "aaabc           ",
      "aaab            ",
      "aaa dde         ",
      "aaab            ",
      "aaabc           ",
      "bbb             "
    ],
    [
      "f gb            ",
      "h ibc           ",
      "jjkb            ",
      "llmb            ",
      "n obc           ",
      "p gb            ",
      "f gb            ",
      "h ibc           ",
      "jjkb            ",
      "llmb            ",
      "n obc           ",
      "p gb            ",
      "f gqdde         ",
      "h ib            ",
      "jjkbc           ",
      "bbb             "
    ],
    [
      "  rb            ",
      "  sbc           ",
      "tu b            ",
      "wxyb            ",
      "  sbc           ",
      "  Ab            ",
      "  rb            ",
      "  Bbc           ",
      "tCsb            ",
      "wDEb            ",
      "  Fbc           ",
      "  Ib            ",
      "  rqdde         ",
      "   b            ",
      "tCCbc           ",
      "bbb             "
    ],
    [
      "   b            ",
      "   bc           ",
      "   b            ",
      "   b            ",
      "   bc           ",
      "   b            ",
      "   b            ",
      "   bc           ",
      "   b            ",
      "   b            ",
      "   bc           ",
      "   b            ",
      "   qdde         ",
      "   b            ",
      "   bc           ",
      "bbb             "
    ],
    [
      "   b            ",
      "   bc           ",
      "   b            ",
      "   b            ",
      "   bc           ",
      "   b            ",
      "   b            ",
      "   bc           ",
      "   b            ",
      "   b            ",
      "   bc           ",
      "   b            ",
      "   qdde         ",
      "   b            ",
      "   bc           ",
      "bbb             "
    ],
    [
      "JJJb            ",
      "JJJbc           ",
      "JJJb            ",
      "KJJb            ",
      "JJJbc           ",
      "JJJb            ",
      "JJJb            ",
      "JJJbc           ",
      "KJJb            ",
      "JJJb            ",
      "JJJbc           ",
      "JJJb            ",
      "LLLLdde         ",
      "KJJb            ",
      "JJJbc           ",
      "bbb             "
    ]
  ]
}