{
  "name": "multi_filmworkstower_9_base1",
  "refpalette": "deceasedcraft:multi_filmworkstower_9/multi_filmworkstower_9_base1_palette",
  "xsize": 16,
  "zsize": 16,
  "slices": [
    [
      "                ",
      "                ",
      "                ",
      "                ",
      "                ",
      "                ",
      "                ",
      "                ",
      "                ",
      "                ",
      "                ",
      "                ",
      "                ",
      "                ",
      "                ",
      "                "
    ],
    [
      "                ",
      "                ",
      "                ",
      "                ",
      "                ",
      "                ",
      "                ",
      "                ",
      "                ",
      "                ",
      "                ",
      "                ",
      "                ",
      "                ",
      "                ",
      "                "
    ],
    [
      "                ",
      "                ",
      "                ",
      "                ",
      "                ",
      "                ",
      "                ",
      "                ",
      "                ",
      "                ",
      "                ",
      "                ",
      "                ",
      "                ",
      "                ",
      "                "
    ],
    [
      "                ",
      "   a   a   a    ",
      "   a   a   a    ",
      "   a   a   a    ",
      "   a   a   a    ",
      "   a   a   a    ",
      "   b   b   b    ",
      "   a   a   a    ",
      "   a   a   a    ",
      "   a   a   a    ",
      "   a   a   a    ",
      "   b   b   b    ",
      "   a   a   a    ",
      "   a   a   a    ",
      "   a   a   a    ",
      "   a   a   a    "
    ],
    [
      "cccccccccccccccc",
      "dddddddddddddddd",
      "efeeefeeefeeefed",
      "egeeegeeegeeeged",
      "egeeegeeegeeeged",
      "egeeegeeegeeeged",
      "hihdhihdhihdhihd",
      "egeeegeeegeeeged",
      "egeeegeeegeeeged",
      "egeeegeeegeeeged",
      "egeeegeeegeeeged",
      "hihdhihdhihdhihd",
      "egeeegeeegeeeged",
      "egeeegeeegeeeged",
      "egeeegeeegeeeged",
      "egeeegeeegeeeged"
    ],
    [
      "jjjjjjjjjjjjjjjj",
      "jjjjjjjjjjjjjjjj",
      "jjjjjjjjjjjjjjjj",
      "jjjjjjjjjjjjjjjj",
      "jjjjjjjjjjjjjjjj",
      "jjjjjjjjjjjjjjjj",
      "jjjjjjjjjjjjjjjj",
      "jjjjjjjjjjjjjjjj",
      "jjjjjjjjjjjjjjjj",
      "jjjjjjjjjjjjjjjj",
      "jjjjjjjjjjjjjjjj",
      "jjjjjjjjjjjjjjjj",
      "jjjjjjjjjjjjjjjj",
      "jjjjjjjjjjjjjjjj",
      "jjjjjjjjjjjjjjjj",
      "jjjjjjjjjjjjjjjj"
    ]
  ]
}