{
  "name": "multi_filmworkstower_9_floor1",
  "refpalette": "deceasedcraft:multi_filmworkstower_9/multi_filmworkstower_9_floor1_palette",
  "xsize": 16,
  "zsize": 16,
  "slices": [
    [
      "                ",
      "a               ",
      "                ",
      "                ",
      "a               ",
      "                ",
      "                ",
      "a               ",
      "                ",
      "                ",
      "a               ",
      "                ",
      "bbc         de  ",
      "                ",
      "                ",
      "                "
    ],
    [
      "                ",
      "aa              ",
      "                ",
      "                ",
      "aa              ",
      "                ",
      "                ",
      "aa              ",
      "                ",
      "                ",
      "aa              ",
      "                ",
      "bbbc       de   ",
      "                ",
      "fggggggggggggggg",
      "hhihhhhihhhhihhh"
    ],
    [
      "j               ",
      "jaa             ",
      "j               ",
      "j               ",
      "jaa             ",
      "j               ",
      "j               ",
      "jaa             ",
      "j               ",
      "j               ",
      "jaa             ",
      "j               ",
      "kbbbcl m lde    ",
      "j               ",
      "       n        ",
      "oooooooooooooooo"
    ],
    [
      " j              ",
      " jaa            ",
      " j              ",
      " j              ",
      " jaa            ",
      " j              ",
      " j              ",
      " jaa            ",
      " j              ",
      " j              ",
      " jaa            ",
      " j              ",
      " kbbbbbbbbe     ",
      "pj     q        ",
      "       r        ",
      "       s        "
    ],
    [
      "  j             ",
      "  ja            ",
      "  j             ",
      "  j             ",
      "  ja            ",
      "  j             ",
      "  j             ",
      "  ja            ",
      "  j             ",
      "  j             ",
      "  ja            ",
      "  j             ",
      "  kbbbbbbe      ",
      "ppj             ",
      "                ",
      "                "
    ],
    [
      "ttj             ",
      "ttjaa           ",
      "ttj             ",
      "ttj             ",
      "ttjaa           ",
      "ttj             ",
      "ttj             ",
      "ttjaa           ",
      "ttj             ",
      "ttj             ",
      "ttjaa           ",
      "ttj             ",
      "pppbbbbbe       ",
      "ppj             ",
      "aaaaa           ",
      "                "
    ]
  ]
}