{
  "name": "multi_filmworkstower_9_floor3",
  "refpalette": "deceasedcraft:multi_filmworkstower_9/multi_filmworkstower_9_floor3_palette",
  "xsize": 16,
  "zsize": 16,
  "slices": [
    [
      "   a            ",
      "   ab           ",
      "   a            ",
      "   a            ",
      "   ab           ",
      "   a            ",
      "   a            ",
      "   ab           ",
      "   a            ",
      "   a            ",
      "   ab           ",
      "   a            ",
      "   cdde         ",
      "   a            ",
      "   ab           ",
      "aaa             "
    ],
    [
      "   a            ",
      "   ab           ",
      "   a            ",
      "   a            ",
      "   ab           ",
      "   a            ",
      "   a            ",
      "   ab           ",
      "   a            ",
      "   a            ",
      "   ab           ",
      "   a            ",
      "   cdde         ",
      "   a            ",
      "   ab           ",
      "aaa             "
    ],
    [
      "   a            ",
      "   ab           ",
      "   a            ",
      "   a            ",
      "   ab           ",
      "   a            ",
      "   a            ",
      "   ab           ",
      "   a            ",
      "   a            ",
      "   ab           ",
      "   a            ",
      "   cdde         ",
      "   a            ",
      "   ab           ",
      "aaa             "
    ],
    [
      "   a            ",
      "   ab           ",
      "   a            ",
      "   a            ",
      "   ab           ",
      "   a            ",
      "   a            ",
      "   ab           ",
      "   a            ",
      "   a            ",
      "   ab           ",
      "   a            ",
      "   cdde         ",
      "   a            ",
      "   ab           ",
      "aaa             "
    ],
    [
      "   a            ",
      "   ab           ",
      "   a            ",
      "   a            ",
      "   ab           ",
      "   a            ",
      "   a            ",
      "   ab           ",
      "   a            ",
      "   a            ",
      "   ab           ",
      "   a            ",
      "   cdde         ",
      "   a            ",
      "   ab           ",
      "aaa             "
    ],
    [
      "fffa            ",
      "gffab           ",
      "ggfa            ",
      "hgfa            ",
      "hgfab           ",
      "hgfa            ",
      "hgfa            ",
      "hgfab           ",
      "hgfa            ",
      "ggfa            ",
      "gffab           ",
      "fffa            ",
      "iiiidde         ",
      "fffa            ",
      "fffab           ",
      "aaa             "
    ]
  ]
}