{
  "name": "multi_filmworkstower_9_floor5",
  "refpalette": "deceasedcraft:multi_filmworkstower_9/multi_filmworkstower_9_floor5_palette",
  "xsize": 16,
  "zsize": 16,
  "slices": [
    [
      "aaab            ",
      "aaabc           ",
      "aaab            ",
      "aaab            ",
      "aaabc           ",
      "aaab            ",
      "aaab            ",
      "aaabc           ",
      "aaab            ",
      "aaab            ",
      "aaabc           ",
      "aaab            ",
      "aaa dde         ",
      "aaab            ",
      "aaabc           ",
      "bbb             "
    ],
    [
      "  fb            ",
      "  fbc           ",
      "  gb            ",
      " hib            ",
      "  jbc           ",
      "  fb            ",
      "  fb            ",
      "  gbc           ",
      " hib            ",
      "  jb            ",
      " kfbc           ",
      "  fb            ",
      "  gldde         ",
      " hib            ",
      "  jbc           ",
      "bbb             "
    ],
    [
      "  mb            ",
      "   bc           ",
      "  kb            ",
      "  nb            ",
      "  obc           ",
      "  pb            ",
      "  qb            ",
      "   bc           ",
      "  nb            ",
      "  ob            ",
      "  rbc           ",
      "  qb            ",
      "  !ldde         ",
      "  nb            ",
      "  obc           ",
      "bbb             "
    ],
    [
      "   b            ",
      "   bc           ",
      "   b            ",
      "   b            ",
      "   bc           ",
      "   b            ",
      "   b            ",
      "   bc           ",
      "   b            ",
      "   b            ",
      "   bc           ",
      "   b            ",
      "   ldde         ",
      "   b            ",
      "   bc           ",
      "bbb             "
    ],
    [
      "   b            ",
      "   bc           ",
      "   b            ",
      "   b            ",
      "   bc           ",
      "   b            ",
      "   b            ",
      "   bc           ",
      "   b            ",
      "   b            ",
      "   bc           ",
      "   b            ",
      "   ldde         ",
      "   b            ",
      "   bc           ",
      "bbb             "
    ],
    [
      "sssb            ",
      "sssbc           ",
      "sssb            ",
      "tssb            ",
      "sssbc           ",
      "sssb            ",
      "sssb            ",
      "sssbc           ",
      "tssb            ",
      "sssb            ",
      "sssbc           ",
      "sssb            ",
      "uuuudde         ",
      "tssb            ",
      "sssbc           ",
      "bbb             "
    ]
  ]
}