{
  "name": "multi_filmworkstower_9_base3",
  "refpalette": "deceasedcraft:multi_filmworkstower_9/multi_filmworkstower_9_base3_palette",
  "xsize": 16,
  "zsize": 16,
  "slices": [
    [
      "aaaaaaaaaaaaaaaa",
      "aaaaaaaaaaaaaaaa",
      "aaaaaaaaaaaaaaaa",
      "aaaaaaaaaaaaaaaa",
      "aaaaaaaaaaaaaaaa",
      "aaaaaaaaaaaaaaaa",
      "aaaaaaaaaaaaaaaa",
      "aaaaaaaaaaaaaaaa",
      "aaaaaaaaaaaaaaaa",
      "aaaaaaaaaaaaaaaa",
      "aaaaaaaaaaaaaaaa",
      "aaaaaaaaaaaaaaaa",
      "aaaaaaaaaaaaaaaa",
      "aaaaaaaaaaaaaaaa",
      "aaaaaaaaaaaaaaaa",
      "aaaaaaaaaaaaaaaa"
    ],
    [
      "bbbbbbbcddbbbeee",
      "febbbbdcdbdbbfgg",
      "ggbbdbbcdddddggg",
      "ggddddbcddddgggg",
      "ggddbdd!dddddggg",
      "ggdbddddddbbbfgg",
      "febbbbdddddbbeee",
      "bbbbbbbdddbbbbbb",
      "bbbbbbbdddbbffff",
      "fbbbbbdddbbbfhhf",
      "gddddddddbdbfhhi",
      "ggddbdddddbbfhhi",
      "gbdddbddddbbfhhi",
      "fbbbbbddddbbfhhi",
      "bbbbbddddbbbfhhi",
      "eeebbdddddbbgfgf"
    ],
    [
      "       j    klll",
      "mn     o     mgg",
      "pq     o     grr",
      "gs     o    tgrr",
      "gs     u     grr",
      "gw           mgp",
      "mn          klll",
      "             xxx",
      "            yAAA",
      "BC          D  m",
      "g           D  g",
      "gE          D  g",
      "g           D  g",
      "B           D  g",
      "FFF         D  g",
      "lllI        Jmgf"
    ],
    [
      "       K     LLM",
      "mN           mgg",
      "g            g O",
      "P            Q  ",
      "R            g  ",
      "g            mgg",
      "mN           LML",
      "                ",
      "                ",
      "B              m",
      "g              r",
      "S              r",
      "g              r",
      "B              r",
      "               r",
      "TTT          mrm"
    ],
    [
      "                ",
      "m            mUV",
      "W            g  ",
      "X            Y  ",
      "Z            g  ",
      "W            mUV",
      "m               ",
      "                ",
      "                ",
      "B              m",
      "g              r",
      "0              W",
      "g              V",
      "B              W",
      "               r",
      "             mrm"
    ],
    [
      "11              ",
      "m2           mgg",
      "g            g3 ",
      "g            g4 ",
      "g            g5 ",
      "g            mgg",
      "m6              ",
      "77              ",
      "              t8",
      "B             tm",
      "g             tr",
      "g             tr",
      "p             tr",
      "B             tr",
      "            119r",
      "            2mrm"
    ]
  ]
}