{
  "name": "multi_filmworkstower_9_floor10",
  "refpalette": "deceasedcraft:multi_filmworkstower_9/multi_filmworkstower_9_floor10_palette",
  "xsize": 16,
  "zsize": 16,
  "slices": [
    [
      "aaab            ",
      "aaabc           ",
      "aaab            ",
      "aaab            ",
      "aaabc           ",
      "aaab            ",
      "aaab            ",
      "aaabc           ",
      "aaab            ",
      "aaab            ",
      "aaabc           ",
      "aaab            ",
      "aaa dde         ",
      "aaab            ",
      "aaabc           ",
      "bbb             "
    ],
    [
      "  fb            ",
      " ghbc           ",
      "iijb            ",
      "kklb            ",
      "m nbc           ",
      "o fb            ",
      "p fb            ",
      "q hbc           ",
      "iijb            ",
      "kklb            ",
      "!rnbc           ",
      " gfb            ",
      "p fsdde         ",
      "q hb            ",
      "iijbc           ",
      "bbb             "
    ],
    [
      "  tb            ",
      "   bc           ",
      "uwxb            ",
      "yABb            ",
      "  rbc           ",
      "  Cb            ",
      "  Db            ",
      "  rbc           ",
      "uEwb            ",
      "yFIb            ",
      "  xbc           ",
      "  Jb            ",
      "  Ksdde         ",
      "  Lb            ",
      "uEMbc           ",
      "bbb             "
    ],
    [
      "   b            ",
      "   bc           ",
      "   b            ",
      "   b            ",
      "   bc           ",
      "   b            ",
      "   b            ",
      "   bc           ",
      "   b            ",
      "   b            ",
      "   bc           ",
      "   b            ",
      "   sdde         ",
      "   b            ",
      "   bc           ",
      "bbb             "
    ],
    [
      "   b            ",
      "   bc           ",
      "   b            ",
      "   b            ",
      "   bc           ",
      "   b            ",
      "   b            ",
      "   bc           ",
      "   b            ",
      "   b            ",
      "   bc           ",
      "   b            ",
      "   sdde         ",
      "   b            ",
      "   bc           ",
      "bbb             "
    ],
    [
      "NNNb            ",
      "NNNbc           ",
      "NNNb            ",
      "ONNb            ",
      "NNNbc           ",
      "NNNb            ",
      "NNNb            ",
      "NNNbc           ",
      "ONNb            ",
      "NNNb            ",
      "NNNbc           ",
      "NNNb            ",
      "PPPPdde         ",
      "ONNb            ",
      "NNNbc           ",
      "bbb             "
    ]
  ]
}