{
  "name": "scattered_hideout_1_floor1",
  "refpalette": "deceasedcraft:scattered_hideout_1/scattered_hideout_1_floor1_palette",
  "xsize": 16,
  "zsize": 16,
  "slices": [
    [
      "abbbbcccccbbbaaa",
      "abbcccccccccbbba",
      "bbccccccccccccbb",
      "bbccccccccccccbb",
      "bccccdddddcccccb",
      "bccccdeffedccccb",
      "bcccddffffddcccb",
      "bcccddffffddcccb",
      "bbcdddffffddcccb",
      "bbbdddffffddccbb",
      "abbdddeffedcccbb",
      "abbbdddddddcccbb",
      "aabbdddddddcccbb",
      "aabbbdddddcccbbb",
      "aabbbbdddcccbbbb",
      "aaabbbbbbbbbbbba"
    ],
    [
      "aaaaabbbbbaaaaaa",
      "aaabbbbccbbbaaaa",
      "aabbbbcccccbbbaa",
      "aabbccccccccbbaa",
      "abbccccggcccbbba",
      "abbcccehhecccbba",
      "abbccijkklmccbba",
      "abbbcinaopqccbba",
      "aabbcqnaariccbba",
      "aaabcmsaaticcbaa",
      "aaabbceuvecccbaa",
      "aaaabcdaadcccbaa",
      "aaaabddwadccbbaa",
      "aaaaxbyaadccbaaa",
      "aaaaaaxazbbbaaaa",
      "aaaaaaaaaaaaaaaa"
    ],
    [
      "aaaaaaaaaaaaaaaa",
      "aaaaaaabbaaaaaaa",
      "aaaaaabbbbbaaaaa",
      "aaaabbbbbbbbaaaa",
      "aaabbccggcbbaaaa",
      "aaabbceoaecbbaaa",
      "aaabbiAaaBqcbaaa",
      "aaaabmAaaCicbaaa",
      "aaaabiAaaDmcbaaa",
      "aaaabqAaaEicbaaa",
      "aaaaaceFGeccbaaa",
      "aaaaabdHHdcbbaaa",
      "aaaaaydHHdbbaaaa",
      "aaaaaaaaabbbaaaa",
      "aaaaaaaaaaaaaaaa",
      "aaaaaaaaaaaaaaaa"
    ],
    [
      "aaaaaaaaaaaaaaaa",
      "aaaaaaaaaaaaaaaa",
      "aaaaaaaaaaaaaaaa",
      "aaaaaaaaaaaaaaaa",
      "aaaaabbbbbaaaaaa",
      "aaaaabIIIIbaaaaa",
      "aaaaabIJJIbbaaaa",
      "aaaaabIJJIbbaaaa",
      "aaaaabIJJIbbaaaa",
      "aaaaabIJJIbbaaaa",
      "aaaaabIIIIbbaaaa",
      "aaaaaabbbbbaaaaa",
      "aaaaaaxbbbaaaaaa",
      "aaaaaaaaaaaaaaaa",
      "aaaaaaaaaaaaaaaa",
      "aaaaaaaaaaaaaaaa"
    ],
    [
      "aaaaaaaaaaaaaaaa",
      "aaaaaaaaaaaaaaaa",
      "aaaaaaaaaaaaaaaa",
      "aaaaaaaaaaaaaaaa",
      "aaaaaaaaaaaaaaaa",
      "aaaaaaKKKKaaaaaa",
      "aaaaaaKaaKaaaaaa",
      "aaaaaaKaaKaaaaaa",
      "aaaaaaKaaKaaaaaa",
      "aaaaaaKaaKaaaaaa",
      "aaaaaaKKKKaaaaaa",
      "aaaaaaaaaaaaaaaa",
      "aaaaaaaaaaaaaaaa",
      "aaaaaaaaaaaaaaaa",
      "aaaaaaaaaaaaaaaa",
      "aaaaaaaaaaaaaaaa"
    ],
    [
      "aaaaaaaaaaaaaaaa",
      "aaaaaaaaaaaaaaaa",
      "aaaaaaaaaaaaaaaa",
      "aaaaaaaaaaaaaaaa",
      "aaaaaaaaaaaaaaaa",
      "aaaaaaaaaaaaaaaa",
      "aaaaaaaaaaaaaaaa",
      "aaaaaaaaaaaaaaaa",
      "aaaaaaaaaaaaaaaa",
      "aaaaaaaaaaaaaaaa",
      "aaaaaaaaaaaaaaaa",
      "aaaaaaaaaaaaaaaa",
      "aaaaaaaaaaaaaaaa",
      "aaaaaaaaaaaaaaaa",
      "aaaaaaaaaaaaaaaa",
      "aaaaaaaaaaaaaaaa"
    ]
  ]
}