{
  "name": "building_office3c_floor1",
  "refpalette": "deceasedcraft:building_office3c/building_office3c_floor1_palette",
  "xsize": 16,
  "zsize": 16,
  "slices": [
    [
      "                ",
      " aaaaaaaaaaaaaa ",
      "  bcddddddddce  ",
      "  fggggggggggh  ",
      "  iggggggggggj  ",
      "  iggggggggggj  ",
      "  iggggggggggj  ",
      "  iggggggggggj  ",
      "  iggggggggggj  ",
      "  iggggggggggj  ",
      "  iggggggggggj  ",
      "  iggggggggggj  ",
      "  kggggggggggl  ",
      "  bcdmn   odce  ",
      " pppppppppppppp ",
      "                "
    ],
    [
      "                ",
      " aaaaaaaaaaaaaa ",
      "  bcqrst uwxce  ",
      "  yA  BBCBDEAF  ",
      "  IA        AJ  ",
      "  KALMN  LMNAJ  ",
      "  yA        AF  ",
      "  yALMN  LMNAO  ",
      "  PA M    M AJ  ",
      "  KALMN  LMNAO  ",
      "  yA        AQ  ",
      "  yR  SSSS  AO  ",
      "  yR TUVVWXYAQ  ",
      "  bc n   om ce  ",
      " pppppppppppppp ",
      "                "
    ],
    [
      "                ",
      " aaaaaaaaaaaaaa ",
      "  bcZZs  uw0ce  ",
      "   A  BB1B23A   ",
      "   A        A   ",
      "   A 4    5 A   ",
      "   A        A   ",
      "   A 6    7 A   ",
      "   A      8 A   ",
      "   A 9    # A   ",
      "   A        A   ",
      "   R        A   ",
      "   R  $% XX^A   ",
      "  bc    omn ce  ",
      " pppppppppppppp ",
      "                "
    ],
    [
      "                ",
      " aaaaaaaaaaaaaa ",
      "  bc&*s  u()ce  ",
      "   A  BB+B23A   ",
      "   A        A   ",
      "   A        A   ",
      "   A        A   ",
      "   A        A   ",
      "   A        A   ",
      "   A        A   ",
      "   A        A   ",
      "   R        A   ",
      "   R    XXXXA   ",
      "  bc   omn  ce  ",
      " pppppppppppppp ",
      "                "
    ],
    [
      "                ",
      " aaaaaaaaaaaaaa ",
      "  bc  s  u-[ce  ",
      "   A  BBBB23A   ",
      "   A        A   ",
      "   A ]    ] A   ",
      "   A        A   ",
      "   A        A   ",
      "   A        A   ",
      "   A        A   ",
      "   A ]    ] A   ",
      "   A        A   ",
      "   R   XXXXXA   ",
      "  bc  omn   ce  ",
      " pppppppppppppp ",
      "                "
    ],
    [
      "                ",
      " aaaaaaaaaaaaaa ",
      "  bc{{s! u}}ce  ",
      "   A|+BBBB;:A   ",
      "   A        A   ",
      "   A '    ' A   ",
      "   A        A   ",
      "   A        A   ",
      "   A        A   ",
      "   A        A   ",
      "   A '    ' A   ",
      "   R        A   ",
      "   R  XXXXXXA   ",
      "  bc omn    ce  ",
      " pppppppppppppp ",
      "                "
    ]
  ]
}