{
  "name": "building_office3c_floor2_270",
  "refpalette": "deceasedcraft:building_office3c/building_office3c_floor2_palette_270",
  "xsize": 16,
  "zsize": 16,
  "slices": [
    [
      "                ",
      " o            a ",
      " objhhhhhhhheba ",
      " ocffffffffffca ",
      " ocffffffffffca ",
      " olffffffffffca ",
      " omffffffffffca ",
      " o ffffffffffca ",
      " o ffffffffffca ",
      " o ffffffffffca ",
      " onffffffffffca ",
      " ocffffffffffca ",
      " ocffffffffffca ",
      " odkiiiiiiiigda ",
      " o            a ",
      "                "
    ],
    [
      "                ",
      " o            a ",
      " obwwwwwwwwwwba ",
      " o          xpa ",
      " o S    K   x a ",
      " omT BPLLEC y a ",
      " o U AQMMFD xqa ",
      " o T  RON   xra ",
      " o U    !I  Asa ",
      " onV BPLLEC   a ",
      " olD AQMMFD  ta ",
      " o     O J    a ",
      " o          Bua ",
      " odwwwwwwwwwwda ",
      " o            a ",
      "                "
    ],
    [
      "                ",
      " o            a ",
      " obwwwwwwwwwwba ",
      " o          x a ",
      " o 6        x a ",
      " o 7  Y42Y  X a ",
      " o 7  153Z  xWa ",
      " o 7        xra ",
      " onV          a ",
      " olD  Y420    a ",
      " om   1531    a ",
      " o            a ",
      " o            a ",
      " odwwwwwwwwwwda ",
      " o            a ",
      "                "
    ],
    [
      "                ",
      " o            a ",
      " obwwwwwwwwwwba ",
      " o          x a ",
      " o 6        x a ",
      " o 7        B a ",
      " o 7        x8a ",
      " onV        xra ",
      " olD          a ",
      " om           a ",
      " o            a ",
      " o            a ",
      " o            a ",
      " odwwwwwwwwwwda ",
      " o            a ",
      "                "
    ],
    [
      "                ",
      " o            a ",
      " obwwwwwwwwwwba ",
      " o          x a ",
      " o 6        x a ",
      " o 7        x a ",
      " onV        x a ",
      " olD        xra ",
      " om           a ",
      " o            a ",
      " o            a ",
      " o            a ",
      " o            a ",
      " odwwwwwwwwwwda ",
      " o            a ",
      "                "
    ],
    [
      "                ",
      " o            a ",
      " obwwwwwwwwwwba ",
      " o          x a ",
      " o $        x a ",
      " onV        x a ",
      " olD        x a ",
      " om         xra ",
      " o          B9a ",
      " o          B9a ",
      " o          B9a ",
      " o          B#a ",
      " o          B#a ",
      " odwwwwwwwwwwda ",
      " o            a ",
      "                "
    ]
  ]
}