{
  "name": "building_office3c_floor1_180",
  "refpalette": "deceasedcraft:building_office3c/building_office3c_floor1_palette_180",
  "xsize": 16,
  "zsize": 16,
  "slices": [
    [
      "                ",
      " pppppppppppppp ",
      "  ecdo   nmdcb  ",
      "  lggggggggggk  ",
      "  jggggggggggi  ",
      "  jggggggggggi  ",
      "  jggggggggggi  ",
      "  jggggggggggi  ",
      "  jggggggggggi  ",
      "  jggggggggggi  ",
      "  jggggggggggi  ",
      "  jggggggggggi  ",
      "  hggggggggggf  ",
      "  ecddddddddcb  ",
      " aaaaaaaaaaaaaa ",
      "                "
    ],
    [
      "                ",
      " pppppppppppppp ",
      "  ec mo   n cb  ",
      "  QAYXWVVUT Ry  ",
      "  OA  SSSS  Ry  ",
      "  QA        Ay  ",
      "  OANML  NMLAK  ",
      "  JA M    M AP  ",
      "  OANML  NMLAy  ",
      "  FA        Ay  ",
      "  JANML  NMLAK  ",
      "  JA        AI  ",
      "  FAEDBCBB  Ay  ",
      "  ecxwu tsrqcb  ",
      " aaaaaaaaaaaaaa ",
      "                "
    ],
    [
      "                ",
      " pppppppppppppp ",
      "  ec nmo    cb  ",
      "   A^XX %$  R   ",
      "   A        R   ",
      "   A        A   ",
      "   A #    9 A   ",
      "   A 8      A   ",
      "   A 7    6 A   ",
      "   A        A   ",
      "   A 5    4 A   ",
      "   A        A   ",
      "   A32B1BB  A   ",
      "  ec0wu  sZZcb  ",
      " aaaaaaaaaaaaaa ",
      "                "
    ],
    [
      "                ",
      " pppppppppppppp ",
      "  ec  nmo   cb  ",
      "   AXXXX    R   ",
      "   A        R   ",
      "   A        A   ",
      "   A        A   ",
      "   A        A   ",
      "   A        A   ",
      "   A        A   ",
      "   A        A   ",
      "   A        A   ",
      "   A32B+BB  A   ",
      "  ec)(u  s*&cb  ",
      " aaaaaaaaaaaaaa ",
      "                "
    ],
    [
      "                ",
      " pppppppppppppp ",
      "  ec   nmo  cb  ",
      "   AXXXXX   R   ",
      "   A        A   ",
      "   A ]    ] A   ",
      "   A        A   ",
      "   A        A   ",
      "   A        A   ",
      "   A        A   ",
      "   A ]    ] A   ",
      "   A        A   ",
      "   A32BBBB  A   ",
      "  ec[-u  s  cb  ",
      " aaaaaaaaaaaaaa ",
      "                "
    ],
    [
      "                ",
      " pppppppppppppp ",
      "  ec    nmo cb  ",
      "   AXXXXXX  R   ",
      "   A        R   ",
      "   A '    ' A   ",
      "   A        A   ",
      "   A        A   ",
      "   A        A   ",
      "   A        A   ",
      "   A '    ' A   ",
      "   A        A   ",
      "   A:;BBBB+|A   ",
      "  ec}}u !s{{cb  ",
      " aaaaaaaaaaaaaa ",
      "                "
    ]
  ]
}