{
  "name": "building_office3c_top",
  "refpalette": "deceasedcraft:building_office3c/building_office3c_top_palette",
  "xsize": 16,
  "zsize": 16,
  "slices": [
    [
      "                ",
      " aaaaaaaaaaaaaa ",
      "  bccccccccccd  ",
      "  effffffffffg  ",
      "  hffffffffffi  ",
      "  hffffffffffi  ",
      "  hffffffffffi  ",
      "  hffffffffffi  ",
      "  hffffffffffi  ",
      "  hffffffffffi  ",
      "  hffffffffffi  ",
      "  hffffffffffi  ",
      "  jffffffffffk  ",
      "  bcclm      d  ",
      " nnnnnnnnnnnnnn ",
      "                "
    ],
    [
      "                ",
      " aaaaaaaaaaaaaa ",
      "  bo  pqrrrrrd  ",
      "  sttuttw!wxws  ",
      "  s      yABCs  ",
      "  sDEFD  yI  s  ",
      "  sDDDD JyKL s  ",
      "  sDMMD  yKNOs  ",
      "  sDDDD JyKC s  ",
      "  sDPQD  yR  s  ",
      "  s      ST  s  ",
      "  s       O  s  ",
      "  s Uwwwwwwwws  ",
      "  b  m       d  ",
      " nnnnnnnnnnnnnn ",
      "                "
    ],
    [
      "                ",
      " aaaaaaaaaaaaaa ",
      "  b  VWqXXXXXd  ",
      "  sttYttZZZZZs  ",
      "  s      01  s  ",
      "  s       2  s  ",
      "  s       3  s  ",
      "  s       4  s  ",
      "  s      5   s  ",
      "  s       6  s  ",
      "  s          s  ",
      "  s          s  ",
      "  s 7ZZZZZZZZs  ",
      "  b          d  ",
      " nnnnnnnnnnnnnn ",
      "                "
    ],
    [
      "                ",
      " aaaaaaaaaaaaaa ",
      "  b   8q9#99#d  ",
      "  sttCtt$$$$$s  ",
      "  s          s  ",
      "  s          s  ",
      "  s          s  ",
      "  s          s  ",
      "  s          s  ",
      "  s          s  ",
      "  s          s  ",
      "  s          s  ",
      "  s  $$$$$$$$s  ",
      "  b          d  ",
      " nnnnnnnnnnnnnn ",
      "                "
    ],
    [
      "                ",
      " aaaaaaaaaaaaaa ",
      "  b    q99%9 d  ",
      "  sttttt     s  ",
      "  s          s  ",
      "  s          s  ",
      "  s          s  ",
      "  s          s  ",
      "  s          s  ",
      "  s          s  ",
      "  s          s  ",
      "  s          s  ",
      "  s   ^   ^  s  ",
      "  b          d  ",
      " nnnnnnnnnnnnnn ",
      "                "
    ],
    [
      "                ",
      " aaaaaaaaaaaaaa ",
      "  b&   q    yd  ",
      "  sttttt*  * s  ",
      "  s          s  ",
      "  s          s  ",
      "  s          s  ",
      "  s          s  ",
      "  s          s  ",
      "  s          s  ",
      "  s          s  ",
      "  s          s  ",
      "  s  ^^ ^ ^^ s  ",
      "  b&        yd  ",
      " nnnnnnnnnnnnnn ",
      "                "
    ],
    [
      "                ",
      " aaaaaaaaaaaaaa ",
      "   (&))))))y+   ",
      "  ss********ss  ",
      "  ss        ss  ",
      "  ss        ss  ",
      "  ss        ss  ",
      "  ss        ss  ",
      "  ss        ss  ",
      "  ss        ss  ",
      "  ss        ss  ",
      "  ss        ss  ",
      "  ss^^^^^^^^ss  ",
      "   (&))))))y+   ",
      " nnnnnnnnnnnnnn ",
      "                "
    ],
    [
      "                ",
      " aaaaaaaaaaaaaa ",
      "    $$$$$$$$    ",
      "  -s[[[[[[[[s-  ",
      "  -s        s-  ",
      "  -s ]    ] s-  ",
      "  -s        s-  ",
      "  -s        s-  ",
      "  -s        s-  ",
      "  -s        s-  ",
      "  -s {    } s-  ",
      "  -s        s-  ",
      "  -s||||||||s-  ",
      "    $$$$$$$$    ",
      " nnnnnnnnnnnnnn ",
      "                "
    ],
    [
      "                ",
      " aaaaaaaaaaaaaa ",
      "                ",
      "   -;;;;;;;;-   ",
      "   -;;;;;;;;-   ",
      "   -;;;;;;;;-   ",
      "   -;;;;;;;;-   ",
      "   -;;;;;;;;-   ",
      "   -;;;;;;;;-   ",
      "   -;;;;;;;;-   ",
      "   -;;;;;;;;-   ",
      "   -;;;;;;;;-   ",
      "   -;;;;;;;;-   ",
      "                ",
      " nnnnnnnnnnnnnn ",
      "                "
    ],
    [
      "                ",
      " aaaaaaaaaaaaaa ",
      "                ",
      "                ",
      "                ",
      "                ",
      "                ",
      "                ",
      "                ",
      "                ",
      "                ",
      "                ",
      "                ",
      "                ",
      " nnnnnnnnnnnnnn ",
      "                "
    ]
  ]
}