{
  "name": "building_office3c_ground_180",
  "refpalette": "deceasedcraft:building_office3c/building_office3c_ground_palette_180",
  "xsize": 16,
  "zsize": 16,
  "slices": [
    [
      "aaaaaaaaaaaaaaaa",
      "aaaaaaaaaaaaaaaa",
      "aaabee!eeeeebaaa",
      "ddeffffffffffedd",
      "ddeffffffffffedd",
      "ddeffffffffffedd",
      "ddeffffffffffedd",
      "ddeffffffffffedd",
      "ddeffffffffffedd",
      "ddeffffffffffedd",
      "ddeffffffffffedd",
      "ddeffffffffffedd",
      "ddeffffffffffedd",
      "aaabccccccccbaaa",
      "aaaaaaaaaaaaaaaa",
      "aaaaaaaaaaaaaaaa"
    ],
    [
      "                ",
      " VVVVVVVVVVVVVV ",
      "  jb UTRSRQPbh  ",
      " sl  ON      ls ",
      " ol   M      lo ",
      " kl  LKKKKJJJlk ",
      " Dl   IFFFFFElD ",
      "  C          B  ",
      "  A  y    y  x  ",
      " ul rwp  rwp lu ",
      " sl  t    t  ls ",
      " ol rqp  rqp lo ",
      " kl  mn   m  lk ",
      "  jbiiiiiiiibh  ",
      " gggggggggggggg ",
      "                "
    ],
    [
      "                ",
      " VVVVVVVVVVVVVV ",
      "  jb )UT (*&bh  ",
      "  l   O      l  ",
      "  l          l  ",
      "  l   ^ %$#98l  ",
      " Dl          lD ",
      "  7          6  ",
      "  5          4  ",
      " ul  3    2  lu ",
      "  l  1       l  ",
      "  l  0    Z  l  ",
      "  l  Y    Y  l  ",
      "  jbWXXWXXXWbh  ",
      " gggggggggggggg ",
      "                "
    ],
    [
      "                ",
      " VVVVVVVVVVVVVV ",
      "  jb  )UT}{]bh  ",
      "  l    O     l  ",
      "  l          l  ",
      "  l          l  ",
      " Dl          lD ",
      " +N          [+ ",
      " +M          -+ ",
      " ul          lu ",
      "  l          l  ",
      "  l          l  ",
      "  l          l  ",
      "  jbX  XXX Xbh  ",
      " gggggggggggggg ",
      "                "
    ],
    [
      "                ",
      " VVVVVVVVVVVVVV ",
      "  jb   )UT;|bh  ",
      "  l     O    l  ",
      "  l          l  ",
      "  l          l  ",
      "  l          l  ",
      "  l          l  ",
      "  l          l  ",
      "  l          l  ",
      "  l          l  ",
      "  l          l  ",
      "  l          l  ",
      "  jb        bh  ",
      " gggggggggggggg ",
      "                "
    ],
    [
      "                ",
      " VVVVVVVVVVVVVV ",
      "  jb    )UT>bh  ",
      "  l      O   l  ",
      "  l          l  ",
      "  l          l  ",
      "  l          l  ",
      "  l          l  ",
      "  l          l  ",
      "  l          l  ",
      "  l          l  ",
      "  l          l  ",
      "  l <<<<'''' l  ",
      "  jb::::::::bh  ",
      " gggggggggggggg ",
      "                "
    ]
  ]
}