{
  "name": "building_office3c_floor3_180",
  "refpalette": "deceasedcraft:building_office3c/building_office3c_floor3_palette_180",
  "xsize": 16,
  "zsize": 16,
  "slices": [
    [
      "                ",
      " oooooooooooooo ",
      "  dccn   mlccb  ",
      "  kffffffffffj  ",
      "  iffffffffffh  ",
      "  iffffffffffh  ",
      "  iffffffffffh  ",
      "  iffffffffffh  ",
      "  iffffffffffh  ",
      "  iffffffffffh  ",
      "  iffffffffffh  ",
      "  iffffffffffh  ",
      "  gffffffffffe  ",
      "  dccccccccccb  ",
      " aaaaaaaaaaaaaa ",
      "                "
    ],
    [
      "                ",
      " oooooooooooooo ",
      "  d  ln   m  b  ",
      "  w  DSRQRQP w  ",
      "  w          w  ",
      "  w  AB  AB  w  ",
      "  w  ON  ON  w  ",
      "  w MKJ LKJ  w  ",
      "  w  KJI KJI w  ",
      "  w  FE  FE  w  ",
      "  w  DC  DC  w  ",
      "  w          w  ",
      "  wB   Axxyxxw  ",
      "  du t srq  pb  ",
      " aaaaaaaaaaaaaa ",
      "                "
    ],
    [
      "                ",
      " oooooooooooooo ",
      "  d  mln     b  ",
      "  w   DS6665 w  ",
      "  w          w  ",
      "  w          w  ",
      "  w  42  32  w  ",
      "  w  10  10  w  ",
      "  w  ZY  ZY  w  ",
      "  w  XV  WV  w  ",
      "  w          w  ",
      "  w          w  ",
      "  w     xxUxxw  ",
      "  d     rT   b  ",
      " aaaaaaaaaaaaaa ",
      "                "
    ],
    [
      "                ",
      " oooooooooooooo ",
      "  d   mln    b  ",
      "  w    DS665 w  ",
      "  w          w  ",
      "  w          w  ",
      "  w          w  ",
      "  w          w  ",
      "  w          w  ",
      "  w          w  ",
      "  w          w  ",
      "  w          w  ",
      "  w     xxBxxw  ",
      "  d     r7   b  ",
      " aaaaaaaaaaaaaa ",
      "                "
    ],
    [
      "                ",
      " oooooooooooooo ",
      "  d    mln   b  ",
      "  w     DS65 w  ",
      "  w          w  ",
      "  w          w  ",
      "  w          w  ",
      "  w          w  ",
      "  w          w  ",
      "  w          w  ",
      "  w          w  ",
      "  w          w  ",
      "  w     xxxxxw  ",
      "  d     r    b  ",
      " aaaaaaaaaaaaaa ",
      "                "
    ],
    [
      "                ",
      " oooooooooooooo ",
      "  d     mln  b  ",
      "  w      DS9 w  ",
      "  w          w  ",
      "  w          w  ",
      "  w          w  ",
      "  w          w  ",
      "  w          w  ",
      "  w          w  ",
      "  w          w  ",
      "  w          w  ",
      "  wBBBBBxxxxxw  ",
      "  d88!88r    b  ",
      " aaaaaaaaaaaaaa ",
      "                "
    ]
  ]
}