{
  "name": "building_office3c_ground_270",
  "refpalette": "deceasedcraft:building_office3c/building_office3c_ground_palette_270",
  "xsize": 16,
  "zsize": 16,
  "slices": [
    [
      "aaaddddddddddaaa",
      "aaaddddddddddaaa",
      "aaaeeeeeeeeeeaaa",
      "aabffffffffffbaa",
      "aaeffffffffffcaa",
      "aaeffffffffffcaa",
      "aaeffffffffffcaa",
      "aaeffffffffffcaa",
      "aaeffffffffffcaa",
      "aa!ffffffffffcaa",
      "aaeffffffffffcaa",
      "aaeffffffffffcaa",
      "aabffffffffffbaa",
      "aaaeeeeeeeeeeaaa",
      "aaaddddddddddaaa",
      "aaaddddddddddaaa"
    ],
    [
      "                ",
      " V sokD  usok g ",
      " VhllllBxllllhg ",
      " Vb  JE      bg ",
      " VP  JF  p p ig ",
      " VQ  JF ywtqmig ",
      " VR  KF  r r ig ",
      " VS  KF      ig ",
      " VR  KF      ig ",
      " VTNMKI  p pnig ",
      " VUO L  ywtqmig ",
      " V       r r ig ",
      " Vb          bg ",
      " VjllllCAlllljg ",
      " V sokD  usok g ",
      "                "
    ],
    [
      "                ",
      " V    D  u    g ",
      " Vhllll64llllhg ",
      " Vb  8       bg ",
      " V&  9       Wg ",
      " V*  #   2 ZYXg ",
      " V(  $       Xg ",
      " V   %       Xg ",
      " VT          Wg ",
      " VUO ^       Xg ",
      " V)      310YXg ",
      " V           Wg ",
      " Vb          bg ",
      " Vjllll75lllljg ",
      " V    D  u    g ",
      "                "
    ],
    [
      "                ",
      " V    D++u    g ",
      " Vhllll[-llllhg ",
      " Vb          bg ",
      " V]          Xg ",
      " V{           g ",
      " V}          Xg ",
      " VT          Xg ",
      " VUO         Xg ",
      " V)           g ",
      " V            g ",
      " V           Xg ",
      " Vb          bg ",
      " VjllllNMlllljg ",
      " V    D++u    g ",
      "                "
    ],
    [
      "                ",
      " V            g ",
      " Vhllllllllllhg ",
      " Vb          bg ",
      " V|           g ",
      " V;           g ",
      " VT           g ",
      " VUO          g ",
      " V)           g ",
      " V            g ",
      " V            g ",
      " V            g ",
      " Vb          bg ",
      " Vjlllllllllljg ",
      " V            g ",
      "                "
    ],
    [
      "                ",
      " V            g ",
      " Vhllllllllllhg ",
      " Vb          bg ",
      " V>         ':g ",
      " VT         ':g ",
      " VUO        ':g ",
      " V)         ':g ",
      " V          <:g ",
      " V          <:g ",
      " V          <:g ",
      " V          <:g ",
      " Vb          bg ",
      " Vjlllllllllljg ",
      " V            g ",
      "                "
    ]
  ]
}