{
  "name": "building_office3c_top_180",
  "refpalette": "deceasedcraft:building_office3c/building_office3c_top_palette_180",
  "xsize": 16,
  "zsize": 16,
  "slices": [
    [
      "                ",
      " nnnnnnnnnnnnnn ",
      "  d      mlccb  ",
      "  kffffffffffj  ",
      "  iffffffffffh  ",
      "  iffffffffffh  ",
      "  iffffffffffh  ",
      "  iffffffffffh  ",
      "  iffffffffffh  ",
      "  iffffffffffh  ",
      "  iffffffffffh  ",
      "  iffffffffffh  ",
      "  gffffffffffe  ",
      "  dccccccccccb  ",
      " aaaaaaaaaaaaaa ",
      "                "
    ],
    [
      "                ",
      " nnnnnnnnnnnnnn ",
      "  d       m  b  ",
      "  swwwwwwwwU s  ",
      "  s  O       s  ",
      "  s  TS      s  ",
      "  s  Ry  DQPDs  ",
      "  s CKyJ DDDDs  ",
      "  sONKy  DMMDs  ",
      "  s LKyJ DDDDs  ",
      "  s  Iy  DFEDs  ",
      "  sCBAy      s  ",
      "  swxw!wttutts  ",
      "  drrrrrqp  ob  ",
      " aaaaaaaaaaaaaa ",
      "                "
    ],
    [
      "                ",
      " nnnnnnnnnnnnnn ",
      "  d          b  ",
      "  sZZZZZZZZ7 s  ",
      "  s          s  ",
      "  s          s  ",
      "  s  6       s  ",
      "  s   5      s  ",
      "  s  4       s  ",
      "  s  3       s  ",
      "  s  2       s  ",
      "  s  10      s  ",
      "  sZZZZZttYtts  ",
      "  dXXXXXqWV  b  ",
      " aaaaaaaaaaaaaa ",
      "                "
    ],
    [
      "                ",
      " nnnnnnnnnnnnnn ",
      "  d          b  ",
      "  s$$$$$$$$  s  ",
      "  s          s  ",
      "  s          s  ",
      "  s          s  ",
      "  s          s  ",
      "  s          s  ",
      "  s          s  ",
      "  s          s  ",
      "  s          s  ",
      "  s$$$$$ttCtts  ",
      "  d#99#9q8   b  ",
      " aaaaaaaaaaaaaa ",
      "                "
    ],
    [
      "                ",
      " nnnnnnnnnnnnnn ",
      "  d          b  ",
      "  s  ^   ^   s  ",
      "  s          s  ",
      "  s          s  ",
      "  s          s  ",
      "  s          s  ",
      "  s          s  ",
      "  s          s  ",
      "  s          s  ",
      "  s          s  ",
      "  s     ttttts  ",
      "  d 9%99q    b  ",
      " aaaaaaaaaaaaaa ",
      "                "
    ],
    [
      "                ",
      " nnnnnnnnnnnnnn ",
      "  dy        &b  ",
      "  s ^^ ^ ^^  s  ",
      "  s          s  ",
      "  s          s  ",
      "  s          s  ",
      "  s          s  ",
      "  s          s  ",
      "  s          s  ",
      "  s          s  ",
      "  s          s  ",
      "  s *  *ttttts  ",
      "  dy    q   &b  ",
      " aaaaaaaaaaaaaa ",
      "                "
    ],
    [
      "                ",
      " nnnnnnnnnnnnnn ",
      "   +y))))))&(   ",
      "  ss^^^^^^^^ss  ",
      "  ss        ss  ",
      "  ss        ss  ",
      "  ss        ss  ",
      "  ss        ss  ",
      "  ss        ss  ",
      "  ss        ss  ",
      "  ss        ss  ",
      "  ss        ss  ",
      "  ss********ss  ",
      "   +y))))))&(   ",
      " aaaaaaaaaaaaaa ",
      "                "
    ],
    [
      "                ",
      " nnnnnnnnnnnnnn ",
      "    $$$$$$$$    ",
      "  -s||||||||s-  ",
      "  -s        s-  ",
      "  -s }    { s-  ",
      "  -s        s-  ",
      "  -s        s-  ",
      "  -s        s-  ",
      "  -s        s-  ",
      "  -s ]    ] s-  ",
      "  -s        s-  ",
      "  -s[[[[[[[[s-  ",
      "    $$$$$$$$    ",
      " aaaaaaaaaaaaaa ",
      "                "
    ],
    [
      "                ",
      " nnnnnnnnnnnnnn ",
      "                ",
      "   -;;;;;;;;-   ",
      "   -;;;;;;;;-   ",
      "   -;;;;;;;;-   ",
      "   -;;;;;;;;-   ",
      "   -;;;;;;;;-   ",
      "   -;;;;;;;;-   ",
      "   -;;;;;;;;-   ",
      "   -;;;;;;;;-   ",
      "   -;;;;;;;;-   ",
      "   -;;;;;;;;-   ",
      "                ",
      " aaaaaaaaaaaaaa ",
      "                "
    ],
    [
      "                ",
      " nnnnnnnnnnnnnn ",
      "                ",
      "                ",
      "                ",
      "                ",
      "                ",
      "                ",
      "                ",
      "                ",
      "                ",
      "                ",
      "                ",
      "                ",
      " aaaaaaaaaaaaaa ",
      "                "
    ]
  ]
}