{
  "name": "building_office3c_floor4_270",
  "refpalette": "deceasedcraft:building_office3c/building_office3c_floor4_palette_270",
  "xsize": 16,
  "zsize": 16,
  "slices": [
    [
      "                ",
      " o            a ",
      " objhhhhhhhheba ",
      " ocffffffffffca ",
      " ocffffffffffca ",
      " olffffffffffca ",
      " omffffffffffca ",
      " o ffffffffffca ",
      " o ffffffffffca ",
      " o ffffffffffca ",
      " onffffffffffca ",
      " ocffffffffffca ",
      " ocffffffffffca ",
      " odkiiiiiiiigda ",
      " o            a ",
      "                "
    ],
    [
      "                ",
      " o            a ",
      " obuuuuuuuuuuba ",
      " o          wpa ",
      " o I   CCCy w a ",
      " omJ  FCDCA xqa ",
      " o K   CDC  w!a ",
      " o J  FCDCB wra ",
      " o K   CDC    a ",
      " onL  FCDCB  sa ",
      " olM   CCC   ta ",
      " o      E    sa ",
      " o            a ",
      " oduuuuuuuuuuda ",
      " o            a ",
      "                "
    ],
    [
      "                ",
      " o            a ",
      " obuuuuuuuuuuba ",
      " o          w a ",
      " o S        w a ",
      " o T   Q y  P a ",
      " o T        wNa ",
      " o T   Q Q  wra ",
      " onL          a ",
      " olM          a ",
      " om     R    Oa ",
      " o            a ",
      " o            a ",
      " oduuuuuuuuuuda ",
      " o            a ",
      "                "
    ],
    [
      "                ",
      " o            a ",
      " obuuuuuuuuuuba ",
      " o          w a ",
      " o S        w a ",
      " o T        V a ",
      " o T        wUa ",
      " onL        wra ",
      " olM          a ",
      " om           a ",
      " o            a ",
      " o            a ",
      " o            a ",
      " oduuuuuuuuuuda ",
      " o            a ",
      "                "
    ],
    [
      "                ",
      " o            a ",
      " obuuuuuuuuuuba ",
      " o          w a ",
      " o S        w a ",
      " o T        w a ",
      " onL        w a ",
      " olM        wra ",
      " om           a ",
      " o            a ",
      " o            a ",
      " o            a ",
      " o            a ",
      " oduuuuuuuuuuda ",
      " o            a ",
      "                "
    ],
    [
      "                ",
      " o            a ",
      " obuuuuuuuuuuba ",
      " o          w a ",
      " o Y        w a ",
      " onL        w a ",
      " olM        w a ",
      " om         wra ",
      " o          VWa ",
      " o          VXa ",
      " o          VWa ",
      " o          VWa ",
      " o          VXa ",
      " oduuuuuuuuuuda ",
      " o            a ",
      "                "
    ]
  ]
}