{
  "name": "building_office3c_floor2",
  "refpalette": "deceasedcraft:building_office3c/building_office3c_floor2_palette",
  "xsize": 16,
  "zsize": 16,
  "slices": [
    [
      "                ",
      " aaaaaaaaaaaaaa ",
      "  bccccccccccd  ",
      "  effffffffffg  ",
      "  hffffffffffi  ",
      "  hffffffffffi  ",
      "  hffffffffffi  ",
      "  hffffffffffi  ",
      "  hffffffffffi  ",
      "  hffffffffffi  ",
      "  hffffffffffi  ",
      "  hffffffffffi  ",
      "  jffffffffffk  ",
      "  bcclm   nccd  ",
      " oooooooooooooo ",
      "                "
    ],
    [
      "                ",
      " aaaaaaaaaaaaaa ",
      "  bp  qrs t ud  ",
      "  wxxyxxA   Bw  ",
      "  w          w  ",
      "  w  CD  CD  w  ",
      "  w  EF IEFJ w  ",
      "  w KLMN!LM  w  ",
      "  w  LMO LMO w  ",
      "  w  PQR PQ  w  ",
      "  w  BA  BA  w  ",
      "  w          w  ",
      "  w STUTUVD  w  ",
      "  b  m   nl  d  ",
      " oooooooooooooo ",
      "                "
    ],
    [
      "                ",
      " aaaaaaaaaaaaaa ",
      "  b   Wr     d  ",
      "  wxxXxx     w  ",
      "  w          w  ",
      "  w          w  ",
      "  w  YZ  01  w  ",
      "  w  23  23  w  ",
      "  w  45  45  w  ",
      "  w  Y1  Y1  w  ",
      "  w          w  ",
      "  w          w  ",
      "  w 6777VD   w  ",
      "  b     nlm  d  ",
      " oooooooooooooo ",
      "                "
    ],
    [
      "                ",
      " aaaaaaaaaaaaaa ",
      "  b   8r     d  ",
      "  wxxBxx     w  ",
      "  w          w  ",
      "  w          w  ",
      "  w          w  ",
      "  w          w  ",
      "  w          w  ",
      "  w          w  ",
      "  w          w  ",
      "  w          w  ",
      "  w 677VD    w  ",
      "  b    nlm   d  ",
      " oooooooooooooo ",
      "                "
    ],
    [
      "                ",
      " aaaaaaaaaaaaaa ",
      "  b    r     d  ",
      "  wxxxxx     w  ",
      "  w          w  ",
      "  w          w  ",
      "  w          w  ",
      "  w          w  ",
      "  w          w  ",
      "  w          w  ",
      "  w          w  ",
      "  w          w  ",
      "  w 67VD     w  ",
      "  b   nlm    d  ",
      " oooooooooooooo ",
      "                "
    ],
    [
      "                ",
      " aaaaaaaaaaaaaa ",
      "  b    r999##d  ",
      "  wxxxxxBBBBBw  ",
      "  w          w  ",
      "  w          w  ",
      "  w          w  ",
      "  w          w  ",
      "  w          w  ",
      "  w          w  ",
      "  w          w  ",
      "  w          w  ",
      "  w $VD      w  ",
      "  b  nlm     d  ",
      " oooooooooooooo ",
      "                "
    ]
  ]
}