{
  "name": "building_office3c_floor1_270",
  "refpalette": "deceasedcraft:building_office3c/building_office3c_floor1_palette_270",
  "xsize": 16,
  "zsize": 16,
  "slices": [
    [
      "                ",
      " p            a ",
      " pbkiiiiiiiifba ",
      " pcggggggggggca ",
      " pdggggggggggda ",
      " pmggggggggggda ",
      " pnggggggggggda ",
      " p ggggggggggda ",
      " p ggggggggggda ",
      " p ggggggggggda ",
      " poggggggggggda ",
      " pdggggggggggda ",
      " pcggggggggggca ",
      " peljjjjjjjjhea ",
      " p            a ",
      "                "
    ],
    [
      "                ",
      " p            a ",
      " pbyyyKPyyKIyba ",
      " pcRRAAAAAAAAca ",
      " p    L L L  qa ",
      " pnT  MMM M  ra ",
      " p US N N N Bsa ",
      " p VS       Bta ",
      " p VS       C a ",
      " poWS L L L Bua ",
      " pmX  MMM M Dwa ",
      " p Y  N N N Exa ",
      " pcAAAAAAAAAAca ",
      " peQOQOJOFJJFea ",
      " p            a ",
      "                "
    ],
    [
      "                ",
      " p            a ",
      " pb          ba ",
      " pcRRAAAAAAAAca ",
      " p           Za ",
      " p    9 6 4  Za ",
      " p $        Bsa ",
      " p %        B a ",
      " po         1 a ",
      " pmX        Bua ",
      " pnX  #87 5 2wa ",
      " p ^        30a ",
      " pcAAAAAAAAAAca ",
      " pe          ea ",
      " p            a ",
      "                "
    ],
    [
      "                ",
      " p            a ",
      " pb          ba ",
      " pcRRAAAAAAAAca ",
      " p           &a ",
      " p           *a ",
      " p          Bsa ",
      " po         B a ",
      " pmX        + a ",
      " pnX        Bua ",
      " p X        2(a ",
      " p X        3)a ",
      " pcAAAAAAAAAAca ",
      " pe          ea ",
      " p            a ",
      "                "
    ],
    [
      "                ",
      " p            a ",
      " pb          ba ",
      " pcRAAAAAAAAAca ",
      " p            a ",
      " p   ]    ]   a ",
      " po         Bsa ",
      " pmX        B a ",
      " pnX        B a ",
      " p X        Bua ",
      " p X ]    ] 2-a ",
      " p X        3[a ",
      " pcAAAAAAAAAAca ",
      " pe          ea ",
      " p            a ",
      "                "
    ],
    [
      "                ",
      " p            a ",
      " pb          ba ",
      " pcRRAAAAAAAAca ",
      " p          |{a ",
      " po  '    ' +{a ",
      " pmX        Bsa ",
      " pnX        B!a ",
      " p X        B a ",
      " p X        Bua ",
      " p X '    ' ;}a ",
      " p X        :}a ",
      " pcAAAAAAAAAAca ",
      " pe          ea ",
      " p            a ",
      "                "
    ]
  ]
}