{
  "name": "building_office3c_floor2_180",
  "refpalette": "deceasedcraft:building_office3c/building_office3c_floor2_palette_180",
  "xsize": 16,
  "zsize": 16,
  "slices": [
    [
      "                ",
      " oooooooooooooo ",
      "  dccn   mlccb  ",
      "  kffffffffffj  ",
      "  iffffffffffh  ",
      "  iffffffffffh  ",
      "  iffffffffffh  ",
      "  iffffffffffh  ",
      "  iffffffffffh  ",
      "  iffffffffffh  ",
      "  iffffffffffh  ",
      "  iffffffffffh  ",
      "  gffffffffffe  ",
      "  dccccccccccb  ",
      " aaaaaaaaaaaaaa ",
      "                "
    ],
    [
      "                ",
      " oooooooooooooo ",
      "  d  ln   m  b  ",
      "  w  DVUTUTS w  ",
      "  w          w  ",
      "  w  AB  AB  w  ",
      "  w  QP RQP  w  ",
      "  w OML OML  w  ",
      "  w  ML!NMLK w  ",
      "  w JFEI FE  w  ",
      "  w  DC  DC  w  ",
      "  w          w  ",
      "  wB   Axxyxxw  ",
      "  du t srq  pb  ",
      " aaaaaaaaaaaaaa ",
      "                "
    ],
    [
      "                ",
      " oooooooooooooo ",
      "  d  mln     b  ",
      "  w   DV7776 w  ",
      "  w          w  ",
      "  w          w  ",
      "  w  1Y  1Y  w  ",
      "  w  54  54  w  ",
      "  w  32  32  w  ",
      "  w  10  ZY  w  ",
      "  w          w  ",
      "  w          w  ",
      "  w     xxXxxw  ",
      "  d     rW   b  ",
      " aaaaaaaaaaaaaa ",
      "                "
    ],
    [
      "                ",
      " oooooooooooooo ",
      "  d   mln    b  ",
      "  w    DV776 w  ",
      "  w          w  ",
      "  w          w  ",
      "  w          w  ",
      "  w          w  ",
      "  w          w  ",
      "  w          w  ",
      "  w          w  ",
      "  w          w  ",
      "  w     xxBxxw  ",
      "  d     r8   b  ",
      " aaaaaaaaaaaaaa ",
      "                "
    ],
    [
      "                ",
      " oooooooooooooo ",
      "  d    mln   b  ",
      "  w     DV76 w  ",
      "  w          w  ",
      "  w          w  ",
      "  w          w  ",
      "  w          w  ",
      "  w          w  ",
      "  w          w  ",
      "  w          w  ",
      "  w          w  ",
      "  w     xxxxxw  ",
      "  d     r    b  ",
      " aaaaaaaaaaaaaa ",
      "                "
    ],
    [
      "                ",
      " oooooooooooooo ",
      "  d     mln  b  ",
      "  w      DV$ w  ",
      "  w          w  ",
      "  w          w  ",
      "  w          w  ",
      "  w          w  ",
      "  w          w  ",
      "  w          w  ",
      "  w          w  ",
      "  w          w  ",
      "  wBBBBBxxxxxw  ",
      "  d##999r    b  ",
      " aaaaaaaaaaaaaa ",
      "                "
    ]
  ]
}