{
  "name": "building_office3c_floor3_90",
  "refpalette": "deceasedcraft:building_office3c/building_office3c_floor3_palette_90",
  "xsize": 16,
  "zsize": 16,
  "slices": [
    [
      "                ",
      " a            o ",
      " adgiiiiiiiikdo ",
      " acffffffffffco ",
      " acffffffffffco ",
      " acffffffffffno ",
      " acffffffffff o ",
      " acffffffffff o ",
      " acffffffffff o ",
      " acffffffffffmo ",
      " acfffffffffflo ",
      " acffffffffffco ",
      " acffffffffffco ",
      " abehhhhhhhhjbo ",
      " a            o ",
      "                "
    ],
    [
      "                ",
      " a            o ",
      " adwwwwwwwwwwdo ",
      " auB          o ",
      " a      M     o ",
      " at  DFKKOA Dlo ",
      " a   CEJJNB Sno ",
      " asA   I    R o ",
      " arx    L   Q o ",
      " aqx DFKKOA R o ",
      " a y CEJJNB Qmo ",
      " a x   I    P o ",
      " apx          o ",
      " abwwwwwwwwwwbo ",
      " a            o ",
      "                "
    ],
    [
      "                ",
      " a            o ",
      " adwwwwwwwwwwdo ",
      " a            o ",
      " a            o ",
      " a    XZ14   mo ",
      " a    VY02  Dlo ",
      " a          Sno ",
      " arx        6 o ",
      " aTx  WZ13  6 o ",
      " a U  VY02  6 o ",
      " a x        5 o ",
      " a x          o ",
      " abwwwwwwwwwwbo ",
      " a            o ",
      "                "
    ],
    [
      "                ",
      " a            o ",
      " adwwwwwwwwwwdo ",
      " a            o ",
      " a            o ",
      " a            o ",
      " a           mo ",
      " a          Dlo ",
      " arx        Sno ",
      " a7x        6 o ",
      " a B        6 o ",
      " a x        5 o ",
      " a x          o ",
      " abwwwwwwwwwwbo ",
      " a            o ",
      "                "
    ],
    [
      "                ",
      " a            o ",
      " adwwwwwwwwwwdo ",
      " a            o ",
      " a            o ",
      " a            o ",
      " a            o ",
      " a           mo ",
      " arx        Dlo ",
      " a x        Sno ",
      " a x        6 o ",
      " a x        5 o ",
      " a x          o ",
      " abwwwwwwwwwwbo ",
      " a            o ",
      "                "
    ],
    [
      "                ",
      " a            o ",
      " adwwwwwwwwwwdo ",
      " a8B          o ",
      " a8B          o ",
      " a!B          o ",
      " a8B          o ",
      " a8B          o ",
      " arx         mo ",
      " a x        Dlo ",
      " a x        Sno ",
      " a x        9 o ",
      " a x          o ",
      " abwwwwwwwwwwbo ",
      " a            o ",
      "                "
    ]
  ]
}