{
  "name": "building_office3c_floor4",
  "refpalette": "deceasedcraft:building_office3c/building_office3c_floor4_palette",
  "xsize": 16,
  "zsize": 16,
  "slices": [
    [
      "                ",
      " aaaaaaaaaaaaaa ",
      "  bccccccccccd  ",
      "  effffffffffg  ",
      "  hffffffffffi  ",
      "  hffffffffffi  ",
      "  hffffffffffi  ",
      "  hffffffffffi  ",
      "  hffffffffffi  ",
      "  hffffffffffi  ",
      "  hffffffffffi  ",
      "  hffffffffffi  ",
      "  jffffffffffk  ",
      "  bcclm   nccd  ",
      " oooooooooooooo ",
      "                "
    ],
    [
      "                ",
      " aaaaaaaaaaaaaa ",
      "  bp q!r sts d  ",
      "  uwwxww     u  ",
      "  u          u  ",
      "  u yA B B   u  ",
      "  u CCCCCCC  u  ",
      "  u CDDDDDCE u  ",
      "  u CCCCCCC  u  ",
      "  u  F F F   u  ",
      "  u          u  ",
      "  u          u  ",
      "  u IJKJKLM  u  ",
      "  b  m   nl  d  ",
      " oooooooooooooo ",
      "                "
    ],
    [
      "                ",
      " aaaaaaaaaaaaaa ",
      "  b   Nr  O  d  ",
      "  uwwPww     u  ",
      "  u          u  ",
      "  u          u  ",
      "  u  y Q     u  ",
      "  u       R  u  ",
      "  u  Q Q     u  ",
      "  u          u  ",
      "  u          u  ",
      "  u          u  ",
      "  u STTTLM   u  ",
      "  b     nlm  d  ",
      " oooooooooooooo ",
      "                "
    ],
    [
      "                ",
      " aaaaaaaaaaaaaa ",
      "  b   Ur     d  ",
      "  uwwVww     u  ",
      "  u          u  ",
      "  u          u  ",
      "  u          u  ",
      "  u          u  ",
      "  u          u  ",
      "  u          u  ",
      "  u          u  ",
      "  u          u  ",
      "  u STTLM    u  ",
      "  b    nlm   d  ",
      " oooooooooooooo ",
      "                "
    ],
    [
      "                ",
      " aaaaaaaaaaaaaa ",
      "  b    r     d  ",
      "  uwwwww     u  ",
      "  u          u  ",
      "  u          u  ",
      "  u          u  ",
      "  u          u  ",
      "  u          u  ",
      "  u          u  ",
      "  u          u  ",
      "  u          u  ",
      "  u STLM     u  ",
      "  b   nlm    d  ",
      " oooooooooooooo ",
      "                "
    ],
    [
      "                ",
      " aaaaaaaaaaaaaa ",
      "  b    rWXWWXd  ",
      "  uwwwwwVVVVVu  ",
      "  u          u  ",
      "  u          u  ",
      "  u          u  ",
      "  u          u  ",
      "  u          u  ",
      "  u          u  ",
      "  u          u  ",
      "  u          u  ",
      "  u YLM      u  ",
      "  b  nlm     d  ",
      " oooooooooooooo ",
      "                "
    ]
  ]
}