{
  "name": "building_office3c_top_270",
  "refpalette": "deceasedcraft:building_office3c/building_office3c_top_palette_270",
  "xsize": 16,
  "zsize": 16,
  "slices": [
    [
      "                ",
      " n            a ",
      " nbjhhhhhhhheba ",
      " ncffffffffffca ",
      " ncffffffffffca ",
      " nlffffffffffca ",
      " nmffffffffffca ",
      " n ffffffffffca ",
      " n ffffffffffca ",
      " n ffffffffffca ",
      " n ffffffffffca ",
      " n ffffffffffca ",
      " n ffffffffffca ",
      " ndkiiiiiiiigda ",
      " n            a ",
      "                "
    ],
    [
      "                ",
      " n            a ",
      " nbssssssssssba ",
      " n    DDDDD toa ",
      " n U  PDMDE t a ",
      " nmw  QDMDF u a ",
      " n w  DDDDD tpa ",
      " n w        tqa ",
      " n w   J J  wra ",
      " n w Syyyyyy!ra ",
      " n wOTRKKKIAwra ",
      " n w   CNL Bxra ",
      " n w    O  Cwra ",
      " ndssssssssssda ",
      " n            a ",
      "                "
    ],
    [
      "                ",
      " n            a ",
      " nbssssssssssba ",
      " n          t a ",
      " n 7        t a ",
      " n Z        YVa ",
      " n Z        tWa ",
      " n Z        tqa ",
      " n Z        ZXa ",
      " n Z   5   0ZXa ",
      " n Z  6 4321ZXa ",
      " n Z        ZXa ",
      " n Z        ZXa ",
      " ndssssssssssda ",
      " n            a ",
      "                "
    ],
    [
      "                ",
      " n            a ",
      " nbssssssssssba ",
      " n          t a ",
      " n          t a ",
      " n $        C a ",
      " n $        t8a ",
      " n $        tqa ",
      " n $        $9a ",
      " n $        $#a ",
      " n $        $9a ",
      " n $        $9a ",
      " n $        $#a ",
      " ndssssssssssda ",
      " n            a ",
      "                "
    ],
    [
      "                ",
      " n            a ",
      " nbssssssssssba ",
      " n          t a ",
      " n          t a ",
      " n          t a ",
      " n ^        t a ",
      " n          tqa ",
      " n           9a ",
      " n           9a ",
      " n ^         %a ",
      " n           9a ",
      " n            a ",
      " ndssssssssssda ",
      " n            a ",
      "                "
    ],
    [
      "                ",
      " n            a ",
      " nbssssssssssba ",
      " n&         t&a ",
      " n          t a ",
      " n ^        t a ",
      " n ^        t a ",
      " n          tqa ",
      " n ^        * a ",
      " n            a ",
      " n ^          a ",
      " n ^        * a ",
      " ny          ya ",
      " ndssssssssssda ",
      " n            a ",
      "                "
    ],
    [
      "                ",
      " n            a ",
      " n ssssssssss a ",
      " n(ssssssssss(a ",
      " n&^        *&a ",
      " n)^        *)a ",
      " n)^        *)a ",
      " n)^        *)a ",
      " n)^        *)a ",
      " n)^        *)a ",
      " n)^        *)a ",
      " ny^        *ya ",
      " n+ssssssssss+a ",
      " n ssssssssss a ",
      " n            a ",
      "                "
    ],
    [
      "                ",
      " n            a ",
      " n ---------- a ",
      " n ssssssssss a ",
      " n$|        [$a ",
      " n$| {    ] [$a ",
      " n$|        [$a ",
      " n$|        [$a ",
      " n$|        [$a ",
      " n$|        [$a ",
      " n$| }    ] [$a ",
      " n$|        [$a ",
      " n ssssssssss a ",
      " n ---------- a ",
      " n            a ",
      "                "
    ],
    [
      "                ",
      " n            a ",
      " n            a ",
      " n ---------- a ",
      " n ;;;;;;;;;; a ",
      " n ;;;;;;;;;; a ",
      " n ;;;;;;;;;; a ",
      " n ;;;;;;;;;; a ",
      " n ;;;;;;;;;; a ",
      " n ;;;;;;;;;; a ",
      " n ;;;;;;;;;; a ",
      " n ;;;;;;;;;; a ",
      " n ---------- a ",
      " n            a ",
      " n            a ",
      "                "
    ],
    [
      "                ",
      " n            a ",
      " n            a ",
      " n            a ",
      " n            a ",
      " n            a ",
      " n            a ",
      " n            a ",
      " n            a ",
      " n            a ",
      " n            a ",
      " n            a ",
      " n            a ",
      " n            a ",
      " n            a ",
      "                "
    ]
  ]
}