{
  "name": "building_office3c_floor2_90",
  "refpalette": "deceasedcraft:building_office3c/building_office3c_floor2_palette_90",
  "xsize": 16,
  "zsize": 16,
  "slices": [
    [
      "                ",
      " a            o ",
      " adgiiiiiiiikdo ",
      " acffffffffffco ",
      " acffffffffffco ",
      " acffffffffffno ",
      " acffffffffff o ",
      " acffffffffff o ",
      " acffffffffff o ",
      " acffffffffffmo ",
      " acfffffffffflo ",
      " acffffffffffco ",
      " acffffffffffco ",
      " abehhhhhhhhjbo ",
      " a            o ",
      "                "
    ],
    [
      "                ",
      " a            o ",
      " adwwwwwwwwwwdo ",
      " auB          o ",
      " a    J O     o ",
      " at  DFMMQA Dlo ",
      " a   CELLPB Vno ",
      " asA  I!    U o ",
      " arx   NOR  T o ",
      " aqx DFMMQA U o ",
      " a y CELLPB Tmo ",
      " a x   K    S o ",
      " apx          o ",
      " abwwwwwwwwwwbo ",
      " a            o ",
      "                "
    ],
    [
      "                ",
      " a            o ",
      " adwwwwwwwwwwdo ",
      " a            o ",
      " a            o ",
      " a    1351   mo ",
      " a    024Y  Dlo ",
      " a          Vno ",
      " arx        7 o ",
      " aWx  Z351  7 o ",
      " a X  Y24Y  7 o ",
      " a x        6 o ",
      " a x          o ",
      " abwwwwwwwwwwbo ",
      " a            o ",
      "                "
    ],
    [
      "                ",
      " a            o ",
      " adwwwwwwwwwwdo ",
      " a            o ",
      " a            o ",
      " a            o ",
      " a           mo ",
      " a          Dlo ",
      " arx        Vno ",
      " a8x        7 o ",
      " a B        7 o ",
      " a x        6 o ",
      " a x          o ",
      " abwwwwwwwwwwbo ",
      " a            o ",
      "                "
    ],
    [
      "                ",
      " a            o ",
      " adwwwwwwwwwwdo ",
      " a            o ",
      " a            o ",
      " a            o ",
      " a            o ",
      " a           mo ",
      " arx        Dlo ",
      " a x        Vno ",
      " a x        7 o ",
      " a x        6 o ",
      " a x          o ",
      " abwwwwwwwwwwbo ",
      " a            o ",
      "                "
    ],
    [
      "                ",
      " a            o ",
      " adwwwwwwwwwwdo ",
      " a#B          o ",
      " a#B          o ",
      " a9B          o ",
      " a9B          o ",
      " a9B          o ",
      " arx         mo ",
      " a x        Dlo ",
      " a x        Vno ",
      " a x        $ o ",
      " a x          o ",
      " abwwwwwwwwwwbo ",
      " a            o ",
      "                "
    ]
  ]
}