{
  "name": "building_office3c_ground",
  "refpalette": "deceasedcraft:building_office3c/building_office3c_ground_palette",
  "xsize": 16,
  "zsize": 16,
  "slices": [
    [
      "aaaaaaaaaaaaaaaa",
      "aaaaaaaaaaaaaaaa",
      "aaabccccccccbaaa",
      "ddeffffffffffedd",
      "ddeffffffffffedd",
      "ddeffffffffffedd",
      "ddeffffffffffedd",
      "ddeffffffffffedd",
      "ddeffffffffffedd",
      "ddeffffffffffedd",
      "ddeffffffffffedd",
      "ddeffffffffffedd",
      "ddeffffffffffedd",
      "aaabeeeee!eebaaa",
      "aaaaaaaaaaaaaaaa",
      "aaaaaaaaaaaaaaaa"
    ],
    [
      "                ",
      " gggggggggggggg ",
      "  hbiiiiiiiibj  ",
      " kl  m   nm  lk ",
      " ol pqr  pqr lo ",
      " sl  t    t  ls ",
      " ul pwr  pwr lu ",
      "  x  y    y  A  ",
      "  B          C  ",
      " DlEFFFFFI   lD ",
      " klJJJKKKKL  lk ",
      " ol      M   lo ",
      " sl      NO  ls ",
      "  hbPQRSRTU bj  ",
      " VVVVVVVVVVVVVV ",
      "                "
    ],
    [
      "                ",
      " gggggggggggggg ",
      "  hbWXXXWXXWbj  ",
      "  l  Y    Y  l  ",
      "  l  Z    0  l  ",
      "  l       1  l  ",
      " ul  2    3  lu ",
      "  4          5  ",
      "  6          7  ",
      " Dl          lD ",
      "  l89#$% ^   l  ",
      "  l          l  ",
      "  l      O   l  ",
      "  hb&*( TU) bj  ",
      " VVVVVVVVVVVVVV ",
      "                "
    ],
    [
      "                ",
      " gggggggggggggg ",
      "  hbX XXX  Xbj  ",
      "  l          l  ",
      "  l          l  ",
      "  l          l  ",
      " ul          lu ",
      " +-          M+ ",
      " +[          N+ ",
      " Dl          lD ",
      "  l          l  ",
      "  l          l  ",
      "  l     O    l  ",
      "  hb]{}TU)  bj  ",
      " VVVVVVVVVVVVVV ",
      "                "
    ],
    [
      "                ",
      " gggggggggggggg ",
      "  hb        bj  ",
      "  l          l  ",
      "  l          l  ",
      "  l          l  ",
      "  l          l  ",
      "  l          l  ",
      "  l          l  ",
      "  l          l  ",
      "  l          l  ",
      "  l          l  ",
      "  l    O     l  ",
      "  hb|;TU)   bj  ",
      " VVVVVVVVVVVVVV ",
      "                "
    ],
    [
      "                ",
      " gggggggggggggg ",
      "  hb::::::::bj  ",
      "  l ''''<<<< l  ",
      "  l          l  ",
      "  l          l  ",
      "  l          l  ",
      "  l          l  ",
      "  l          l  ",
      "  l          l  ",
      "  l          l  ",
      "  l          l  ",
      "  l   O      l  ",
      "  hb>TU)    bj  ",
      " VVVVVVVVVVVVVV ",
      "                "
    ]
  ]
}