{
  "name": "building_office3c_ground_90",
  "refpalette": "deceasedcraft:building_office3c/building_office3c_ground_palette_90",
  "xsize": 16,
  "zsize": 16,
  "slices": [
    [
      "aaaddddddddddaaa",
      "aaaddddddddddaaa",
      "aaaeeeeeeeeeeaaa",
      "aabffffffffffbaa",
      "aacffffffffffeaa",
      "aacffffffffffeaa",
      "aacffffffffff!aa",
      "aacffffffffffeaa",
      "aacffffffffffeaa",
      "aacffffffffffeaa",
      "aacffffffffffeaa",
      "aacffffffffffeaa",
      "aabffffffffffbaa",
      "aaaeeeeeeeeeeaaa",
      "aaaddddddddddaaa",
      "aaaddddddddddaaa"
    ],
    [
      "                ",
      " g kosu  Dkos V ",
      " gjllllAClllljV ",
      " gb          bV ",
      " gi r r       V ",
      " gimqtwy  L OUV ",
      " ginp p  IKMNTV ",
      " gi      FK  RV ",
      " gi      FK  SV ",
      " gi r r  FK  RV ",
      " gimqtwy FJ  QV ",
      " gi p p  FJ  PV ",
      " gb      EJ  bV ",
      " ghllllxBllllhV ",
      " g kosu  Dkos V ",
      "                "
    ],
    [
      "                ",
      " g    u  D    V ",
      " gjllll57lllljV ",
      " gb          bV ",
      " gW           V ",
      " gXY013      )V ",
      " gX       ^ OUV ",
      " gW          TV ",
      " gX       %   V ",
      " gX       $  (V ",
      " gXYZ 2   #  *V ",
      " gW       9  &V ",
      " gb       8  bV ",
      " ghllll46llllhV ",
      " g    u  D    V ",
      "                "
    ],
    [
      "                ",
      " g    u++D    V ",
      " gjllllMNlllljV ",
      " gb          bV ",
      " gX           V ",
      " g            V ",
      " g           )V ",
      " gX         OUV ",
      " gX          TV ",
      " gX          }V ",
      " g           {V ",
      " gX          ]V ",
      " gb          bV ",
      " ghllll-[llllhV ",
      " g    u++D    V ",
      "                "
    ],
    [
      "                ",
      " g            V ",
      " gjlllllllllljV ",
      " gb          bV ",
      " g            V ",
      " g            V ",
      " g            V ",
      " g           )V ",
      " g          OUV ",
      " g           TV ",
      " g           ;V ",
      " g           |V ",
      " gb          bV ",
      " ghllllllllllhV ",
      " g            V ",
      "                "
    ],
    [
      "                ",
      " g            V ",
      " gjlllllllllljV ",
      " gb          bV ",
      " g:<          V ",
      " g:<          V ",
      " g:<          V ",
      " g:<          V ",
      " g:'         )V ",
      " g:'        OUV ",
      " g:'         TV ",
      " g:'         >V ",
      " gb          bV ",
      " ghllllllllllhV ",
      " g            V ",
      "                "
    ]
  ]
}