{
  "name": "building_office3c_floor3",
  "refpalette": "deceasedcraft:building_office3c/building_office3c_floor3_palette",
  "xsize": 16,
  "zsize": 16,
  "slices": [
    [
      "                ",
      " aaaaaaaaaaaaaa ",
      "  bccccccccccd  ",
      "  effffffffffg  ",
      "  hffffffffffi  ",
      "  hffffffffffi  ",
      "  hffffffffffi  ",
      "  hffffffffffi  ",
      "  hffffffffffi  ",
      "  hffffffffffi  ",
      "  hffffffffffi  ",
      "  hffffffffffi  ",
      "  jffffffffffk  ",
      "  bcclm   nccd  ",
      " oooooooooooooo ",
      "                "
    ],
    [
      "                ",
      " aaaaaaaaaaaaaa ",
      "  bp  qrs t ud  ",
      "  wxxyxxA   Bw  ",
      "  w          w  ",
      "  w  CD  CD  w  ",
      "  w  EF  EF  w  ",
      "  w IJK IJK  w  ",
      "  w  JKL JKM w  ",
      "  w  NO  NO  w  ",
      "  w  BA  BA  w  ",
      "  w          w  ",
      "  w PQRQRSD  w  ",
      "  b  m   nl  d  ",
      " oooooooooooooo ",
      "                "
    ],
    [
      "                ",
      " aaaaaaaaaaaaaa ",
      "  b   Tr     d  ",
      "  wxxUxx     w  ",
      "  w          w  ",
      "  w          w  ",
      "  w  VW  VX  w  ",
      "  w  YZ  YZ  w  ",
      "  w  01  01  w  ",
      "  w  23  24  w  ",
      "  w          w  ",
      "  w          w  ",
      "  w 5666SD   w  ",
      "  b     nlm  d  ",
      " oooooooooooooo ",
      "                "
    ],
    [
      "                ",
      " aaaaaaaaaaaaaa ",
      "  b   7r     d  ",
      "  wxxBxx     w  ",
      "  w          w  ",
      "  w          w  ",
      "  w          w  ",
      "  w          w  ",
      "  w          w  ",
      "  w          w  ",
      "  w          w  ",
      "  w          w  ",
      "  w 566SD    w  ",
      "  b    nlm   d  ",
      " oooooooooooooo ",
      "                "
    ],
    [
      "                ",
      " aaaaaaaaaaaaaa ",
      "  b    r     d  ",
      "  wxxxxx     w  ",
      "  w          w  ",
      "  w          w  ",
      "  w          w  ",
      "  w          w  ",
      "  w          w  ",
      "  w          w  ",
      "  w          w  ",
      "  w          w  ",
      "  w 56SD     w  ",
      "  b   nlm    d  ",
      " oooooooooooooo ",
      "                "
    ],
    [
      "                ",
      " aaaaaaaaaaaaaa ",
      "  b    r88!88d  ",
      "  wxxxxxBBBBBw  ",
      "  w          w  ",
      "  w          w  ",
      "  w          w  ",
      "  w          w  ",
      "  w          w  ",
      "  w          w  ",
      "  w          w  ",
      "  w          w  ",
      "  w 9SD      w  ",
      "  b  nlm     d  ",
      " oooooooooooooo ",
      "                "
    ]
  ]
}