{
  "name": "building_office3c_floor3_270",
  "refpalette": "deceasedcraft:building_office3c/building_office3c_floor3_palette_270",
  "xsize": 16,
  "zsize": 16,
  "slices": [
    [
      "                ",
      " o            a ",
      " objhhhhhhhheba ",
      " ocffffffffffca ",
      " ocffffffffffca ",
      " olffffffffffca ",
      " omffffffffffca ",
      " o ffffffffffca ",
      " o ffffffffffca ",
      " o ffffffffffca ",
      " onffffffffffca ",
      " ocffffffffffca ",
      " ocffffffffffca ",
      " odkiiiiiiiigda ",
      " o            a ",
      "                "
    ],
    [
      "                ",
      " o            a ",
      " obwwwwwwwwwwba ",
      " o          xpa ",
      " o P    I   x a ",
      " omQ BNJJEC y a ",
      " o R AOKKFD xqa ",
      " o Q   L    xra ",
      " o R    I   Asa ",
      " onS BNJJEC   a ",
      " olD AOKKFD  ta ",
      " o     M      a ",
      " o          Bua ",
      " odwwwwwwwwwwda ",
      " o            a ",
      "                "
    ],
    [
      "                ",
      " o            a ",
      " obwwwwwwwwwwba ",
      " o          x a ",
      " o 5        x a ",
      " o 6  20YV  U a ",
      " o 6  31ZW  xTa ",
      " o 6        xra ",
      " onS          a ",
      " olD  20YV    a ",
      " om   41ZX    a ",
      " o            a ",
      " o            a ",
      " odwwwwwwwwwwda ",
      " o            a ",
      "                "
    ],
    [
      "                ",
      " o            a ",
      " obwwwwwwwwwwba ",
      " o          x a ",
      " o 5        x a ",
      " o 6        B a ",
      " o 6        x7a ",
      " onS        xra ",
      " olD          a ",
      " om           a ",
      " o            a ",
      " o            a ",
      " o            a ",
      " odwwwwwwwwwwda ",
      " o            a ",
      "                "
    ],
    [
      "                ",
      " o            a ",
      " obwwwwwwwwwwba ",
      " o          x a ",
      " o 5        x a ",
      " o 6        x a ",
      " onS        x a ",
      " olD        xra ",
      " om           a ",
      " o            a ",
      " o            a ",
      " o            a ",
      " o            a ",
      " odwwwwwwwwwwda ",
      " o            a ",
      "                "
    ],
    [
      "                ",
      " o            a ",
      " obwwwwwwwwwwba ",
      " o          x a ",
      " o 9        x a ",
      " onS        x a ",
      " olD        x a ",
      " om         xra ",
      " o          B8a ",
      " o          B8a ",
      " o          B!a ",
      " o          B8a ",
      " o          B8a ",
      " odwwwwwwwwwwda ",
      " o            a ",
      "                "
    ]
  ]
}