{
  "name": "building_office3c_floor1_90",
  "refpalette": "deceasedcraft:building_office3c/building_office3c_floor1_palette_90",
  "xsize": 16,
  "zsize": 16,
  "slices": [
    [
      "                ",
      " a            p ",
      " aehjjjjjjjjlep ",
      " acggggggggggcp ",
      " adggggggggggdp ",
      " adggggggggggop ",
      " adgggggggggg p ",
      " adgggggggggg p ",
      " adgggggggggg p ",
      " adggggggggggnp ",
      " adggggggggggmp ",
      " adggggggggggdp ",
      " acggggggggggcp ",
      " abfiiiiiiiikbp ",
      " a            p ",
      "                "
    ],
    [
      "                ",
      " a            p ",
      " aeFJJFOJOQOQep ",
      " acAAAAAAAAAAcp ",
      " axE N N N  Y p ",
      " awD M MMM  Xmp ",
      " auB L L L SWop ",
      " a C       SV p ",
      " atB       SV p ",
      " asB N N N SU p ",
      " ar  M MMM  Tnp ",
      " aq  L L L    p ",
      " acAAAAAAAARRcp ",
      " abyIKyyPKyyybp ",
      " a            p ",
      "                "
    ],
    [
      "                ",
      " a            p ",
      " ae          ep ",
      " acAAAAAAAAAAcp ",
      " a03        ^ p ",
      " aw2 5 78#  Xnp ",
      " auB        Xmp ",
      " a 1         op ",
      " a B        % p ",
      " asB        $ p ",
      " aZ  4 6 9    p ",
      " aZ           p ",
      " acAAAAAAAARRcp ",
      " ab          bp ",
      " a            p ",
      "                "
    ],
    [
      "                ",
      " a            p ",
      " ae          ep ",
      " acAAAAAAAAAAcp ",
      " a)3        X p ",
      " a(2        X p ",
      " auB        Xnp ",
      " a +        Xmp ",
      " a B         op ",
      " asB          p ",
      " a*           p ",
      " a&           p ",
      " acAAAAAAAARRcp ",
      " ab          bp ",
      " a            p ",
      "                "
    ],
    [
      "                ",
      " a            p ",
      " ae          ep ",
      " acAAAAAAAAAAcp ",
      " a[3        X p ",
      " a-2 ]    ] X p ",
      " auB        X p ",
      " a B        Xnp ",
      " a B        Xmp ",
      " asB         op ",
      " a   ]    ]   p ",
      " a            p ",
      " acAAAAAAAAARcp ",
      " ab          bp ",
      " a            p ",
      "                "
    ],
    [
      "                ",
      " a            p ",
      " ae          ep ",
      " acAAAAAAAAAAcp ",
      " a}:        X p ",
      " a}; '    ' X p ",
      " auB        X p ",
      " a B        X p ",
      " a!B        Xnp ",
      " asB        Xmp ",
      " a{+ '    '  op ",
      " a{|          p ",
      " acAAAAAAAARRcp ",
      " ab          bp ",
      " a            p ",
      "                "
    ]
  ]
}