{
  "name": "building_office3c_floor4_180",
  "refpalette": "deceasedcraft:building_office3c/building_office3c_floor4_palette_180",
  "xsize": 16,
  "zsize": 16,
  "slices": [
    [
      "                ",
      " oooooooooooooo ",
      "  dccn   mlccb  ",
      "  kffffffffffj  ",
      "  iffffffffffh  ",
      "  iffffffffffh  ",
      "  iffffffffffh  ",
      "  iffffffffffh  ",
      "  iffffffffffh  ",
      "  iffffffffffh  ",
      "  iffffffffffh  ",
      "  iffffffffffh  ",
      "  gffffffffffe  ",
      "  dccccccccccb  ",
      " aaaaaaaaaaaaaa ",
      "                "
    ],
    [
      "                ",
      " oooooooooooooo ",
      "  d  ln   m  b  ",
      "  u  MLKJKJI u  ",
      "  u          u  ",
      "  u          u  ",
      "  u   F F F  u  ",
      "  u  CCCCCCC u  ",
      "  u ECDDDDDC u  ",
      "  u  CCCCCCC u  ",
      "  u   B B Ay u  ",
      "  u          u  ",
      "  u     wwxwwu  ",
      "  d sts r!q pb  ",
      " aaaaaaaaaaaaaa ",
      "                "
    ],
    [
      "                ",
      " oooooooooooooo ",
      "  d  mln     b  ",
      "  u   MLTTTS u  ",
      "  u          u  ",
      "  u          u  ",
      "  u          u  ",
      "  u     Q Q  u  ",
      "  u  R       u  ",
      "  u     Q y  u  ",
      "  u          u  ",
      "  u          u  ",
      "  u     wwPwwu  ",
      "  d  O  rN   b  ",
      " aaaaaaaaaaaaaa ",
      "                "
    ],
    [
      "                ",
      " oooooooooooooo ",
      "  d   mln    b  ",
      "  u    MLTTS u  ",
      "  u          u  ",
      "  u          u  ",
      "  u          u  ",
      "  u          u  ",
      "  u          u  ",
      "  u          u  ",
      "  u          u  ",
      "  u          u  ",
      "  u     wwVwwu  ",
      "  d     rU   b  ",
      " aaaaaaaaaaaaaa ",
      "                "
    ],
    [
      "                ",
      " oooooooooooooo ",
      "  d    mln   b  ",
      "  u     MLTS u  ",
      "  u          u  ",
      "  u          u  ",
      "  u          u  ",
      "  u          u  ",
      "  u          u  ",
      "  u          u  ",
      "  u          u  ",
      "  u          u  ",
      "  u     wwwwwu  ",
      "  d     r    b  ",
      " aaaaaaaaaaaaaa ",
      "                "
    ],
    [
      "                ",
      " oooooooooooooo ",
      "  d     mln  b  ",
      "  u      MLY u  ",
      "  u          u  ",
      "  u          u  ",
      "  u          u  ",
      "  u          u  ",
      "  u          u  ",
      "  u          u  ",
      "  u          u  ",
      "  u          u  ",
      "  uVVVVVwwwwwu  ",
      "  dXWWXWr    b  ",
      " aaaaaaaaaaaaaa ",
      "                "
    ]
  ]
}