{
  "name": "building_office3c_top_90",
  "refpalette": "deceasedcraft:building_office3c/building_office3c_top_palette_90",
  "xsize": 16,
  "zsize": 16,
  "slices": [
    [
      "                ",
      " a            n ",
      " adgiiiiiiiikdn ",
      " acffffffffff n ",
      " acffffffffff n ",
      " acffffffffff n ",
      " acffffffffff n ",
      " acffffffffff n ",
      " acffffffffff n ",
      " acffffffffffmn ",
      " acffffffffffln ",
      " acffffffffffcn ",
      " acffffffffffcn ",
      " abehhhhhhhhjbn ",
      " a            n ",
      "                "
    ],
    [
      "                ",
      " a            n ",
      " adssssssssssdn ",
      " arwC  O    w n ",
      " arxB LNC   w n ",
      " arwAIKKKRTOw n ",
      " ar!yyyyyyS w n ",
      " arw  J J   w n ",
      " aqt        w n ",
      " apt DDDDD  w n ",
      " a u FDMDQ  wmn ",
      " a t EDMDP  U n ",
      " aot DDDDD    n ",
      " abssssssssssbn ",
      " a            n ",
      "                "
    ],
    [
      "                ",
      " a            n ",
      " adssssssssssdn ",
      " aXZ        Z n ",
      " aXZ        Z n ",
      " aXZ1234 6  Z n ",
      " aXZ0   5   Z n ",
      " aXZ        Z n ",
      " aqt        Z n ",
      " aWt        Z n ",
      " aVY        Z n ",
      " a t        7 n ",
      " a t          n ",
      " abssssssssssbn ",
      " a            n ",
      "                "
    ],
    [
      "                ",
      " a            n ",
      " adssssssssssdn ",
      " a#$        $ n ",
      " a9$        $ n ",
      " a9$        $ n ",
      " a#$        $ n ",
      " a9$        $ n ",
      " aqt        $ n ",
      " a8t        $ n ",
      " a C        $ n ",
      " a t          n ",
      " a t          n ",
      " abssssssssssbn ",
      " a            n ",
      "                "
    ],
    [
      "                ",
      " a            n ",
      " adssssssssssdn ",
      " a            n ",
      " a9           n ",
      " a%         ^ n ",
      " a9           n ",
      " a9           n ",
      " aqt          n ",
      " a t        ^ n ",
      " a t          n ",
      " a t          n ",
      " a t          n ",
      " abssssssssssbn ",
      " a            n ",
      "                "
    ],
    [
      "                ",
      " a            n ",
      " adssssssssssdn ",
      " ay          yn ",
      " a *        ^ n ",
      " a          ^ n ",
      " a            n ",
      " a *        ^ n ",
      " aqt          n ",
      " a t        ^ n ",
      " a t        ^ n ",
      " a t          n ",
      " a&t         &n ",
      " abssssssssssbn ",
      " a            n ",
      "                "
    ],
    [
      "                ",
      " a            n ",
      " a ssssssssss n ",
      " a+ssssssssss+n ",
      " ay*        ^yn ",
      " a)*        ^)n ",
      " a)*        ^)n ",
      " a)*        ^)n ",
      " a)*        ^)n ",
      " a)*        ^)n ",
      " a)*        ^)n ",
      " a&*        ^&n ",
      " a(ssssssssss(n ",
      " a ssssssssss n ",
      " a            n ",
      "                "
    ],
    [
      "                ",
      " a            n ",
      " a ---------- n ",
      " a ssssssssss n ",
      " a$[        |$n ",
      " a$[ ]    } |$n ",
      " a$[        |$n ",
      " a$[        |$n ",
      " a$[        |$n ",
      " a$[        |$n ",
      " a$[ ]    { |$n ",
      " a$[        |$n ",
      " a ssssssssss n ",
      " a ---------- n ",
      " a            n ",
      "                "
    ],
    [
      "                ",
      " a            n ",
      " a            n ",
      " a ---------- n ",
      " a ;;;;;;;;;; n ",
      " a ;;;;;;;;;; n ",
      " a ;;;;;;;;;; n ",
      " a ;;;;;;;;;; n ",
      " a ;;;;;;;;;; n ",
      " a ;;;;;;;;;; n ",
      " a ;;;;;;;;;; n ",
      " a ;;;;;;;;;; n ",
      " a ---------- n ",
      " a            n ",
      " a            n ",
      "                "
    ],
    [
      "                ",
      " a            n ",
      " a            n ",
      " a            n ",
      " a            n ",
      " a            n ",
      " a            n ",
      " a            n ",
      " a            n ",
      " a            n ",
      " a            n ",
      " a            n ",
      " a            n ",
      " a            n ",
      " a            n ",
      "                "
    ]
  ]
}