{
  "name": "building_office3c_floor4_90",
  "refpalette": "deceasedcraft:building_office3c/building_office3c_floor4_palette_90",
  "xsize": 16,
  "zsize": 16,
  "slices": [
    [
      "                ",
      " a            o ",
      " adgiiiiiiiikdo ",
      " acffffffffffco ",
      " acffffffffffco ",
      " acffffffffffno ",
      " acffffffffff o ",
      " acffffffffff o ",
      " acffffffffff o ",
      " acffffffffffmo ",
      " acfffffffffflo ",
      " acffffffffffco ",
      " acffffffffffco ",
      " abehhhhhhhhjbo ",
      " a            o ",
      "                "
    ],
    [
      "                ",
      " a            o ",
      " aduuuuuuuuuudo ",
      " a            o ",
      " as    E      o ",
      " at   CCC   Mlo ",
      " as  BCDCF  Lno ",
      " a    CDC   K o ",
      " arw BCDCF  J o ",
      " a!w  CDC   K o ",
      " aqx ACDCF  Jmo ",
      " a w yCCC   I o ",
      " apw          o ",
      " abuuuuuuuuuubo ",
      " a            o ",
      "                "
    ],
    [
      "                ",
      " a            o ",
      " aduuuuuuuuuudo ",
      " a            o ",
      " a            o ",
      " aO    R     mo ",
      " a          Mlo ",
      " a          Lno ",
      " arw  Q Q   T o ",
      " aNw        T o ",
      " a P  y Q   T o ",
      " a w        S o ",
      " a w          o ",
      " abuuuuuuuuuubo ",
      " a            o ",
      "                "
    ],
    [
      "                ",
      " a            o ",
      " aduuuuuuuuuudo ",
      " a            o ",
      " a            o ",
      " a            o ",
      " a           mo ",
      " a          Mlo ",
      " arw        Lno ",
      " aUw        T o ",
      " a V        T o ",
      " a w        S o ",
      " a w          o ",
      " abuuuuuuuuuubo ",
      " a            o ",
      "                "
    ],
    [
      "                ",
      " a            o ",
      " aduuuuuuuuuudo ",
      " a            o ",
      " a            o ",
      " a            o ",
      " a            o ",
      " a           mo ",
      " arw        Mlo ",
      " a w        Lno ",
      " a w        T o ",
      " a w        S o ",
      " a w          o ",
      " abuuuuuuuuuubo ",
      " a            o ",
      "                "
    ],
    [
      "                ",
      " a            o ",
      " aduuuuuuuuuudo ",
      " aXV          o ",
      " aWV          o ",
      " aWV          o ",
      " aXV          o ",
      " aWV          o ",
      " arw         mo ",
      " a w        Mlo ",
      " a w        Lno ",
      " a w        Y o ",
      " a w          o ",
      " abuuuuuuuuuubo ",
      " a            o ",
      "                "
    ]
  ]
}