{
  "name": "multi_alienresearch_11_base6",
  "refpalette": "deceasedcraft:multi_alienresearch_11/multi_alienresearch_11_base6_palette",
  "xsize": 16,
  "zsize": 16,
  "slices": [
    [
      " aaabbbccccccccc",
      "abdbbccccccccccc",
      "bbbccccccccccccc",
      "cccccccccccccccc",
      "cccccccccccccccc",
      "cccccccccccccccc",
      "cccccccccccccccc",
      "cccccccccccccccc",
      "cccccccccccccccc",
      "cccccccccccccccc",
      "cccccccccccccccc",
      "cccccccccccccccc",
      "cccccccccccccccc",
      "cccccccccccccccc",
      "eeeeeeeeeeeeeeee",
      "vvvvvvvvvvvvvvvv"
    ],
    [
      "     ff       gh",
      "   ff         gh",
      "fff          igj",
      "  klmln        o",
      "     p         q",
      "                ",
      "                ",
      " r r r r        ",
      "stttttttsr      ",
      "slluuulls       ",
      "s       s       ",
      "                ",
      "                ",
      "wwwxxxwwwww    y",
      "eeeeeeeeeeeeeeee",
      "vvvvvvvvvvvvvvvv"
    ],
    [
      "     AA         ",
      "   AA         B ",
      "AAA             ",
      "   CDE         F",
      "                ",
      "                ",
      "                ",
      "                ",
      "IJ JKLMJN       ",
      "  O    P        ",
      "Q       R       ",
      "                ",
      "                ",
      "SSS T SSUSS     ",
      "eeeeeeeeeeeeeeee",
      "vvvvvvvvvvvvvvvv"
    ],
    [
      "     AA         ",
      "   AA           ",
      "AAA             ",
      "                ",
      "                ",
      "                ",
      "                ",
      "                ",
      "                ",
      "                ",
      "                ",
      "                ",
      "                ",
      "VVS   SSSSS     ",
      "eeeeeeeeeeeeeeee",
      "vvvvvvvvvvvvvvvv"
    ],
    [
      "     AA         ",
      "   AA           ",
      "AAA             ",
      "                ",
      "                ",
      "                ",
      "                ",
      "                ",
      "                ",
      "                ",
      "                ",
      "                ",
      "                ",
      "!WX   XYZ01     ",
      "eeeeeeeeeeeeeeee",
      "vvvvvvvvvvvvvvvv"
    ],
    [
      "     AA         ",
      "   AA           ",
      "AAA             ",
      "                ",
      "                ",
      "                ",
      "                ",
      "                ",
      "                ",
      "                ",
      "                ",
      "                ",
      "                ",
      "                ",
      "eeeeeeeeeeeeeeee",
      "vvvvvvvvvvvvvvvv"
    ]
  ]
}