{
  "name": "multi_alienresearch_11_base8",
  "refpalette": "deceasedcraft:multi_alienresearch_11/multi_alienresearch_11_base8_palette",
  "xsize": 16,
  "zsize": 16,
  "slices": [
    [
      "abbbbbbbbbbacccc",
      "abaaaaaaaaaacccc",
      "abaccccccccccccc",
      "abaccccccccccccc",
      "addddddddddddddd",
      "accccccccccccccc",
      "accccccccccccccc",
      "accccccccccccccc",
      "accccccccccccccc",
      "accccccccccccccc",
      "accccccccccccccc",
      "accccccccccccccc",
      "accccccccccccccc",
      "accccccccccccccc",
      "addddddddddddddd",
      "vvvvvvvvvvvvvvvv"
    ],
    [
      "abbbbbbbbbbaaae ",
      "abaaaaaaaaaafagh",
      "aba!       i a  ",
      "abaghj  klma agh",
      "adddddnodddddddd",
      "apq r    stuwxx ",
      "a               ",
      "ayyy            ",
      "aAAAB    C    C ",
      "aAAAB   CDC  CDC",
      "aAAAB    C      ",
      "aEEE          C ",
      "a               ",
      "a       CDC  CDC",
      "addddddddddddddd",
      "vvvvvvvvvvvvvvvv"
    ],
    [
      "abbbbbbbbbbaaa  ",
      "abaaaaaaaaaa a  ",
      "aba        F a  ",
      "aba        aIa  ",
      "adddddJKdddddddd",
      "a        LMN OP ",
      "a               ",
      "a               ",
      "aQ Q            ",
      "a R      S    T ",
      "aQ Q            ",
      "a               ",
      "a               ",
      "a             U ",
      "addddddddddddddd",
      "vvvvvvvvvvvvvvvv"
    ],
    [
      "abbbbbbbbbbaaa  ",
      "abaaaaaaaaaa a  ",
      "aba        a a  ",
      "aba        aVa  ",
      "addddddddddddddd",
      "a        WXWXWX ",
      "a               ",
      "a               ",
      "aRRR            ",
      "aR RY           ",
      "aRRR            ",
      "a               ",
      "a               ",
      "a               ",
      "addddddddddddddd",
      "vvvvvvvvvvvvvvvv"
    ],
    [
      "abbbbbbbbbbaaa  ",
      "abaaaaaaaaaa a  ",
      "aba        a a  ",
      "aba        a a  ",
      "addddddddddddddd",
      "a        Z0 Z   ",
      "a               ",
      "a               ",
      "aRRR            ",
      "aR R            ",
      "aRRR            ",
      "a               ",
      "a               ",
      "a               ",
      "addddddddddddddd",
      "vvvvvvvvvvvvvvvv"
    ],
    [
      "abbbbbbbbbbaaa  ",
      "abaaaaaaaaaa1a  ",
      "aba        a1a  ",
      "aba        a1a  ",
      "addddddddddddddd",
      "a               ",
      "a               ",
      "a               ",
      "aRRR            ",
      "aR R            ",
      "aRRR            ",
      "a               ",
      "a               ",
      "a               ",
      "addddddddddddddd",
      "vvvvvvvvvvvvvvvv"
    ]
  ]
}