{
  "name": "multi_alienresearch_11_base7",
  "refpalette": "deceasedcraft:multi_alienresearch_11/multi_alienresearch_11_base7_palette",
  "xsize": 16,
  "zsize": 16,
  "slices": [
    [
      "abbbbbbbbbbacccc",
      "abaaaaaaaaaacccc",
      "abaccccccccccccc",
      "abaccccccccccccc",
      "addddddddddddddd",
      "aeeeeeeeeeeeeeee",
      "aeeeeeeeeeeeeeee",
      "a               ",
      "afff            ",
      "afff            ",
      "afff            ",
      "a               ",
      "a               ",
      "a               ",
      "addddddddddddddd",
      "vvvvvvvvvvvvvvvv"
    ],
    [
      "gbbbbbbbbbbaaah ",
      "bbaaaaaaaaaaiajk",
      "bba        l a  ",
      "bbajkh  mnoa ajk",
      "adddddpqdddddddd",
      "ar              ",
      "asssssssssssssss",
      "a               ",
      "a               ",
      "a               ",
      "a               ",
      "a               ",
      "a               ",
      "a               ",
      "addddddddddddddd",
      "vvvvvvvvvvvvvvvv"
    ],
    [
      "gggbbbbbbbbaaa  ",
      "bbaaaaaaaaaa a  ",
      "bba        t a  ",
      "bba        aua  ",
      "adddddwxdddddddd",
      "a               ",
      "a               ",
      "a               ",
      "a               ",
      "a               ",
      "a               ",
      "a               ",
      "a               ",
      "a               ",
      "addddddddddddddd",
      "vvvvvvvvvvvvvvvv"
    ],
    [
      " gggbbbbbbbaaa  ",
      "gbaaaaaaaaaaya  ",
      "bba        a a  ",
      "bba        aAa  ",
      "addddddddddddddd",
      "a               ",
      "a               ",
      "a               ",
      "a               ",
      "a               ",
      "a               ",
      "a               ",
      "a               ",
      "a               ",
      "addddddddddddddd",
      "vvvvvvvvvvvvvvvv"
    ],
    [
      "  gggbbbbbbaaa  ",
      "ggaaaaaaaaaa a  ",
      "bba        a a  ",
      "bba        a a  ",
      "addddddddddddddd",
      "a               ",
      "a               ",
      "a               ",
      "a               ",
      "a               ",
      "a               ",
      "a               ",
      "a               ",
      "a               ",
      "addddddddddddddd",
      "vvvvvvvvvvvvvvvv"
    ],
    [
      "   BBbbbbbbaaa  ",
      "BBBaaaaaaaaaCa  ",
      "bba        aCa  ",
      "bba        aCa  ",
      "addddddddddddddd",
      "a               ",
      "a               ",
      "a               ",
      "a               ",
      "a               ",
      "a               ",
      "a               ",
      "a               ",
      "a               ",
      "addddddddddddddd",
      "vvvvvvvvvvvvvvvv"
    ]
  ]
}