{
  "name": "multi_alienresearch_11_top",
  "refpalette": "deceasedcraft:multi_alienresearch_11/multi_alienresearch_11_top_palette",
  "xsize": 16,
  "zsize": 16,
  "slices": [
    [
      "                ",
      "                ",
      "                ",
      "                ",
      "                ",
      "                ",
      "                ",
      "                ",
      "                ",
      "  a a      b    ",
      "cdc dddddddddddd",
      "                ",
      "                ",
      "                ",
      "                ",
      "                "
    ],
    [
      "                ",
      "                ",
      "               e",
      "                ",
      "                ",
      "                ",
      "                ",
      "                ",
      "                ",
      "a  a       b    ",
      "cdfddddddddddddd",
      "                ",
      "                ",
      "                ",
      "                ",
      "                "
    ],
    [
      "                ",
      "                ",
      "   ggg       hbb",
      "                ",
      "                ",
      "                ",
      "                ",
      "                ",
      "                ",
      "a          b hbb",
      "cddddddd!ddddddd",
      "                ",
      "                ",
      "                ",
      "                ",
      "                "
    ],
    [
      "           h  ij",
      "           h  kl",
      "   g g    hbbbij",
      "           h  ij",
      "           h  kk",
      "           h  ij",
      "           h  ij",
      "           h  kk",
      "           h  ij",
      "a       a hbbbij",
      " dddddddcddddddd",
      "                ",
      "                ",
      "                ",
      "                ",
      "                "
    ],
    [
      "           ijmn ",
      "           ijk  ",
      "bh g g hbbbijmn ",
      "           ijmn ",
      "           ijk  ",
      "           ijmn ",
      "           ijmn ",
      "           ijk  ",
      "           ijmn ",
      "bh     hbbbinnn ",
      "fdddddddddddopo ",
      "                ",
      "                ",
      "                ",
      "                ",
      "                "
    ],
    [
      "i       ijmn    ",
      "k       kkmn    ",
      "ibbbbbbbijmn    ",
      "i       ijmn    ",
      "k       kkm     ",
      "i       ijmn    ",
      "i       ijmn    ",
      "k       kkmn    ",
      "i       ijmn    ",
      "ibbbbbbbijmn    ",
      "ddddddddddpo    ",
      "                ",
      "                ",
      "                ",
      "                ",
      "                "
    ],
    [
      "nqjjjjjmn       ",
      " kkkkkkk        ",
      " qjjjjjmn       ",
      "nqjjjjjmn       ",
      " kkkkllk        ",
      "nqjjjjjnn       ",
      "nnjjjjjmn       ",
      " lkkkkkk        ",
      "nqjjjjjmn       ",
      "nqjjjjjmn       ",
      "ordddddpo       ",
      "                ",
      "                ",
      "                ",
      "                ",
      "                "
    ],
    [
      "   nnn          ",
      "                ",
      "   nn           ",
      "    n           ",
      "                ",
      "   nnn          ",
      "     n          ",
      "                ",
      "   nn           ",
      "    nn          ",
      "   ooo          ",
      "                ",
      "                ",
      "                ",
      "                ",
      "                "
    ]
  ]
}