{
  "name": "multi_alienresearch_11_base5",
  "refpalette": "deceasedcraft:multi_alienresearch_11/multi_alienresearch_11_base5_palette",
  "xsize": 16,
  "zsize": 16,
  "slices": [
    [
      "     aa         ",
      "   aa           ",
      "aaa             ",
      "                ",
      "                ",
      "                ",
      "                ",
      "                ",
      "                ",
      "                ",
      "                ",
      "                ",
      "                ",
      "                ",
      "bbbbbbbbbbbbbbbb",
      "vvvvvvvvvvvvvvvv"
    ],
    [
      "     aa         ",
      "   aa           ",
      "aaa             ",
      "                ",
      "                ",
      "                ",
      "                ",
      "                ",
      "                ",
      "                ",
      "                ",
      "                ",
      "                ",
      "                ",
      "bbbbbbbbbbbbbbbb",
      "vvvvvvvvvvvvvvvv"
    ],
    [
      "     aa         ",
      "   aa           ",
      "aaa             ",
      "                ",
      "                ",
      "                ",
      "                ",
      "                ",
      "                ",
      "                ",
      "                ",
      "                ",
      "                ",
      "                ",
      "bbbbbbbbbbbbbbbb",
      "vvvvvvvvvvvvvvvv"
    ],
    [
      "     aa         ",
      "   aa           ",
      "aaa             ",
      "                ",
      "                ",
      "                ",
      "                ",
      "                ",
      "                ",
      "                ",
      "                ",
      "                ",
      "                ",
      "                ",
      "bbbbbbbbbbbbbbbb",
      "vvvvvvvvvvvvvvvv"
    ],
    [
      "     aa         ",
      "   aa           ",
      "aaa             ",
      "                ",
      "                ",
      "                ",
      "                ",
      "                ",
      "                ",
      "                ",
      "                ",
      "                ",
      "                ",
      "                ",
      "bbbbbbbbbbbbbbbb",
      "vvvvvvvvvvvvvvvv"
    ],
    [
      "     cc       d ",
      "   cc    d    d ",
      "ccc      d    d ",
      "    d    d    dd",
      "                ",
      "                ",
      "                ",
      "    d    d    d ",
      "    d    d    d ",
      "    d    d    d ",
      "    d    d    d ",
      "    d    d    d ",
      "                ",
      "                ",
      "bbbbbbbbbbbbbbbb",
      "vvvvvvvvvvvvvvvv"
    ]
  ]
}