{
  "name": "multi_alienresearch_11_ground",
  "refpalette": "deceasedcraft:multi_alienresearch_11/multi_alienresearch_11_ground_palette",
  "xsize": 16,
  "zsize": 16,
  "slices": [
    [
      "aaaabaaacaaaaaaa",
      "aaacbaaaaaaaaaaa",
      "caacdccaaaaaaaca",
      "aaaabaaaacacaaaa",
      "aaacecaaaaaaaaaa",
      "acabddccaaaaaaaa",
      "aaaaccacaacaaaaa",
      "aaaaaacaaaacaaaa",
      "accaaaaaaaaaaaaa",
      "aaazcacacaafaaaa",
      "gggggggggggggggg",
      "hvvvhvvvvhvvvvvv",
      "vhhhhhhvhhhivhhh",
      "iiziihiihiiizhii",
      "zzizzizzzzzzizzz",
      "zzzzzzzizzzzzzzz"
    ],
    [
      "                ",
      "                ",
      "                ",
      "                ",
      "                ",
      "                ",
      "                ",
      "                ",
      "              jk",
      "lllm l lnn o k  ",
      "pppppppppppppppp",
      "                ",
      "                ",
      "qqqqqqqqqqqqqqqq",
      "    m    m m    ",
      "     m       mm "
    ],
    [
      "                ",
      "                ",
      "                ",
      "                ",
      "                ",
      "                ",
      "                ",
      "                ",
      "                ",
      "        n  o    ",
      "rrrrrrrrrrrrsrrr",
      "                ",
      "                ",
      "qqqqqqqqqqqqqqqq",
      "                ",
      "                "
    ],
    [
      "                ",
      "                ",
      "                ",
      "                ",
      "                ",
      "                ",
      "                ",
      "                ",
      "                ",
      "           onn  ",
      "rrrrrrrrrrrrtrrr",
      "                ",
      "                ",
      "qqqqqqqqqqqqqqqq",
      "                ",
      "                "
    ],
    [
      "                ",
      "                ",
      "                ",
      "                ",
      "                ",
      "                ",
      "                ",
      "                ",
      "                ",
      "   n       on   ",
      "rrrrrrrrrrrrtrrr",
      "                ",
      "                ",
      "uuuuuuuuuuuuuuuu",
      "                ",
      "                "
    ],
    [
      "                ",
      "                ",
      "                ",
      "                ",
      "                ",
      "                ",
      "                ",
      "                ",
      "                ",
      "  nn       on   ",
      "rrtwrrrrrrrrrrrr",
      "                ",
      "                ",
      "                ",
      "                ",
      "                "
    ]
  ]
}