{
  "name": "multi_communitycenter_8_ground",
  "refpalette": "deceasedcraft:multi_communitycenter_8/multi_communitycenter_8_ground_palette",
  "xsize": 16,
  "zsize": 16,
  "slices": [
    [
      "aaaaaabbbbbbbbcd",
      "aaaaaabbbbbbbbcd",
      "eeeeeabbbbbbbbcd",
      "faaaaabbbbbbbbcd",
      "faaaaabbbbbbbbcd",
      "aaaaaabbbbbbbbcd",
      "aaaaaabbbbbbbbcd",
      "bbbbbbbbbbbbbbcd",
      "  ghhbdddccccccd",
      "  g  bdddccccccd",
      "  i  bdddccccccd",
      "     bdddccccccd",
      "     bdddccccccd",
      "bbbbbbdddddddddd",
      "dddddddddddddddd",
      "dddddddddddddddd"
    ],
    [
      "  j kl   mnnnoi ",
      "ppqrrl  q    st ",
      "uuuwxl  y ABCst ",
      "DE   l  q  B st ",
      "DE   l   mABCoi ",
      "F    I  q  B ot ",
      "     J  qKABCot ",
      "uuu  loLoooooot ",
      "  g  l   iM NMi ",
      "  g  l   tMMM t ",
      "  i  l   tN NMt ",
      "     l   tMNMMt ",
      "     l   itttti ",
      "llllll          ",
      "                ",
      "                "
    ],
    [
      "  O  l   mPPPo  ",
      "  qrrl  q    s  ",
      "uQQ  l  R  S s  ",
      " DE  l  q    s  ",
      " DE  l   m S o  ",
      "TF   U  qV W o  ",
      "     X  qV   o  ",
      "uQQ  loYoooooo  ",
      "  g  l    Z 0Z  ",
      "  g  l    ZZZ   ",
      "  i  l    0 0Z  ",
      "     l    Z0ZZ  ",
      "     1          ",
      "1ll111          ",
      "                ",
      "                "
    ],
    [
      "  q22l   mnnno  ",
      "  q33l  q    4  ",
      "uQQ  l  q    4  ",
      "  DE l  q    4  ",
      "  DE l   m   o  ",
      " TF  l  qV   o  ",
      "     l  qV   o  ",
      "uQQ  loooooooo  ",
      "  g  l          ",
      "  g  l          ",
      "  i  l          ",
      "     l          ",
      "     1          ",
      "1ll111          ",
      "                ",
      "                "
    ],
    [
      "    Kl  5mnnno  ",
      "     l  q    s  ",
      "uQQQQl  q    s  ",
      "   DEl  q    s  ",
      "   DEl   m   o  ",
      "  TF l  q    o  ",
      "     l  q    o  ",
      "uQQQQloooooooo  ",
      "  g  l          ",
      "  g  l          ",
      "  i  l          ",
      "     l          ",
      "     l          ",
      "llllll          ",
      "                ",
      "                "
    ],
    [
      "66666lbbbbbbb7  ",
      "66666lbbbbbbb7  ",
      "uuuuulbbbbbbb7  ",
      "    Dfbbbbbbb7  ",
      "    Dfbbbbbbbo  ",
      "   TFlbbbbbbb7  ",
      "     lbbbbbbb7  ",
      "uuuuul777o7777  ",
      "66666l          ",
      "66666l          ",
      "66666l          ",
      "66666l          ",
      "66666l          ",
      "llllll          ",
      "                ",
      "                "
    ]
  ]
}