{
  "name": "multi_communitycenter_8_base1",
  "refpalette": "deceasedcraft:multi_communitycenter_8/multi_communitycenter_8_base1_palette",
  "xsize": 16,
  "zsize": 16,
  "slices": [
    [
      "HHHHHHHHHHHHHHHv",
      "HHHHHHHHHHHHHHHv",
      "HHHHHHHHHHHHHHHv",
      "HHHHHHHHHHHHHHHv",
      "HHHHHHHHHHHHHHHv",
      "HHHHHHHHHHHHHHHv",
      "HHHHHHHHHHHHHHHv",
      "aaaaHHHHHHHHHHHv",
      "bbbaccccHHHHHHHv",
      "bbbaccccHHHHHHHv",
      "aaaaccccHHHHHHHv",
      "HHHHHHccHHHHHHHv",
      "HHHHHHccHHHHHHHv",
      "HHHHHHHHHHHHHHHv",
      "HHHHHHHHHHHHHHHv",
      "vvvvvvvvvvvvvvvv"
    ],
    [
      "   d    d    dev",
      "fgf      gfgf ev",
      "              ev",
      "              ev",
      "              ev",
      "              ev",
      "         hihi ev",
      "jkldmmnmd    dev",
      "oopeqr  e     ev",
      "sspeqt  egfgf!ev",
      "aaueee  eeeeeeev",
      "aaaaaewxeeeeeeev",
      "aaaaaeyAeeeeeeev",
      "eeeeeeeeeeeeeeev",
      "eeeeeeeeeeeeeeev",
      "vvvvvvvvvvvvvvvv"
    ],
    [
      "   d    d    dev",
      "              ev",
      "              ev",
      "              ev",
      "              ev",
      "              ev",
      "              ev",
      "BCldmmDmd    dev",
      "  peqE  e     ev",
      "  peqF  e     ev",
      "ssueee  eeeeeeev",
      "aaaaaeIJeeeeeeev",
      "aaaaae!Aeeeeeeev",
      "eeeeeeeeeeeeeeev",
      "eeeeeeeeeeeeeeev",
      "vvvvvvvvvvvvvvvv"
    ],
    [
      "   d    d    dev",
      "              ev",
      "              ev",
      "              ev",
      "              ev",
      "              ev",
      "              ev",
      "llldmmmmd    dev",
      "  pe    e     ev",
      "  pe    e     ev",
      "  ueee  eeeeeeev",
      "  Kaae  eeeeeeev",
      "  Kaae Leeeeeeev",
      "eeeeeeeeeeeeeeev",
      "eeeeeeeeeeeeeeev",
      "vvvvvvvvvvvvvvvv"
    ],
    [
      "MMMdMMMMdMMMMdev",
      "   d    d    dev",
      "   d    d    dev",
      "   d    d    dev",
      "   d    d    dev",
      "   d    d    dev",
      "   d    d    dev",
      "dddddddddMMMMdev",
      "  pdL  Ld    dev",
      "  pdN  Nd    dev",
      "  uOOe Leeeeeeev",
      "     e Leeeeeeev",
      "     eLLeeeeeeev",
      "eeeeeeeeeeeeeeev",
      "eeeeeeeeeeeeeeev",
      "vvvvvvvvvvvvvvvv"
    ],
    [
      "eeeeeeeeeeeeeeev",
      "eeeeeeeeeeeeeeev",
      "eeeeeeeeeeeeeeev",
      "eeeeeeeeeeeeeeev",
      "eeeeeeeeeeeeeeev",
      "eeeeeeeeeeeeeeev",
      "eeeeeeeeeeeeeeev",
      "eeeeeeeeeeeeeeev",
      "  paaeeeeeeeeeev",
      "  pOOeeeeeeeeeev",
      "  u  eeeeeeeeeev",
      "     eeeeeeeeeev",
      "     eeeeeeeeeev",
      "eeeeeeeeeeeeeeev",
      "eeeeeeeeeeeeeeev",
      "vvvvvvvvvvvvvvvv"
    ]
  ]
}