{
  "name": "multi_communitycenter_8_floor1",
  "refpalette": "deceasedcraft:multi_communitycenter_8/multi_communitycenter_8_floor1_palette",
  "xsize": 16,
  "zsize": 16,
  "slices": [
    [
      "aaaaabc    d e  ",
      "aaaaab   fgdhe  ",
      "iiiiib   jkdhe  ",
      "l          d e  ",
      "l          d e  ",
      "l   mbdddddd e  ",
      "l    bh    hhe  ",
      "iiiiibeeeeeeee  ",
      "aaaaab          ",
      "aaaaab          ",
      "aaaaab          ",
      "aaaaab          ",
      "aaaanb          ",
      "bbbbbb          ",
      "                ",
      "                "
    ],
    [
      " o              ",
      "o  o        h   ",
      "ppppp       h   ",
      "                ",
      "                ",
      "                ",
      "h    hh    hh   ",
      "pppppq          ",
      "orsotq          ",
      "     q          ",
      "     q          ",
      "    oq          ",
      "uuuuuq          ",
      "qqqqqq          ",
      "                ",
      "                "
    ],
    [
      "                ",
      "            h   ",
      "            h   ",
      "                ",
      "                ",
      "                ",
      "h    hh    hh   ",
      "                ",
      "                ",
      "                ",
      "                ",
      "                ",
      "                ",
      "                ",
      "                ",
      "                "
    ],
    [
      "                ",
      "            w   ",
      "            w   ",
      "                ",
      "                ",
      "                ",
      "w    ww    ww   ",
      "                ",
      "                ",
      "                ",
      "                ",
      "                ",
      "                ",
      "                ",
      "                ",
      "                "
    ],
    [
      "xxxxxxxxxxxxiyy ",
      "xxxxxxxxxxxxiyy ",
      "xxxxxxxxxxxxiyy ",
      "xxxxxxxxxxxxiyy ",
      "xxxxxxxxxxxxiyy ",
      "xxxxxxxxxxxxiyy ",
      "iiiiiiiiiiiiiyy ",
      "yyyyyyyyyyyyyyy ",
      "yyyyyyyyyyyyyyy ",
      "                ",
      "                ",
      "                ",
      "                ",
      "                ",
      "                ",
      "                "
    ],
    [
      "                ",
      "                ",
      "                ",
      "                ",
      "                ",
      "                ",
      "     ~          ",
      "                ",
      "                ",
      "                ",
      "                ",
      "                ",
      "                ",
      "                ",
      "                ",
      "                "
    ]
  ]
}