{
  "name": "multi_policestation_1_floor1",
  "refpalette": "deceasedcraft:multi_policestation_1/multi_policestation_1_floor1_palette",
  "xsize": 16,
  "zsize": 16,
  "slices": [
    [
      " aabbbbbbbbbbb  ",
      " aaaaaaaaaaaaaa ",
      " acccccccccccda ",
      " aeeeeeeeeeefda ",
      " aeeeeeeeeeeeda ",
      " aeeeeeeeeeeeda ",
      " aeeeeeeeeeeeda ",
      " aeeeeeeeeeeega ",
      " aeeeeeeeeeeeda ",
      " aeeeeeeeeeeeda ",
      " aeeeeeeeeeeeda ",
      " aeedddddgdddda ",
      " aaaaaaaaaaaaaa ",
      "                ",
      "                ",
      "                "
    ],
    [
      "                ",
      "                ",
      "  bbbbbbbbbbbb  ",
      "  b         hb  ",
      "  b      ii  b  ",
      "  b      jjddb  ",
      "  b      kk  b  ",
      "  b      ii  b  ",
      "  b      jjddb  ",
      "  b      kk  b  ",
      "  b          b  ",
      "  bbbbbbbbbbbb  ",
      "                ",
      "                ",
      "                ",
      "                "
    ],
    [
      "                ",
      "                ",
      "                ",
      "                ",
      "         ii     ",
      "         jj     ",
      "         kk     ",
      "         ii     ",
      "         jj     ",
      "         kk     ",
      "                ",
      "                ",
      "                ",
      "                ",
      "                ",
      "                "
    ],
    [
      "                ",
      "                ",
      "                ",
      "                ",
      "                ",
      "                ",
      "                ",
      "                ",
      "                ",
      "                ",
      "                ",
      "                ",
      "                ",
      "                ",
      "                ",
      "                "
    ],
    [
      "                ",
      "                ",
      "                ",
      "                ",
      "                ",
      "                ",
      "                ",
      "                ",
      "                ",
      "                ",
      "                ",
      "                ",
      "                ",
      "                ",
      "                ",
      "                "
    ],
    [
      "                ",
      "                ",
      "                ",
      "                ",
      "                ",
      "                ",
      "                ",
      "                ",
      "                ",
      "                ",
      "                ",
      "                ",
      "                ",
      "                ",
      "                ",
      "                "
    ]
  ]
}