{
  "name": "multi_policestation_1_ground",
  "refpalette": "deceasedcraft:multi_policestation_1/multi_policestation_1_ground_palette",
  "xsize": 16,
  "zsize": 16,
  "slices": [
    [
      "abbbbbbbbbbbbbcd",
      "abbbbbbbbbbbbbcd",
      "acccccbbbbbbbbcd",
      "dceeefggggggggcd",
      "aceeefggggggggcd",
      "aceeefggggggggcd",
      "aceeefggggggggcd",
      "aceeefggggggggcd",
      "aceeefggggggggcd",
      "aceeefggggggggcd",
      "dceeefggggggggcd",
      "dceehfij      cd",
      "acccccccckcckccd",
      "aadddddddddddddd",
      "addddddddddddddd",
      "addddddddddddddd"
    ],
    [
      "      l  mno pq ",
      "  rrrrls     pc ",
      " ccccclbtbbbbbc ",
      " cuuuuluuuuuuuc ",
      " cuuuuluuuuuuuc ",
      " cuuuuluuuuuuuc ",
      " cuuuuuuuuuuuuc ",
      " ccccuuuuuuuuuc ",
      " cwwwcuuuuuuuuc ",
      " cwwwwuuuuuuuuc ",
      " cwwwcuuuuuuuuc ",
      " cwwxcy       c ",
      " ccAccAccAccAcc ",
      "                ",
      "                ",
      "                "
    ],
    [
      "      l  BCB  D ",
      "      l  E F  I ",
      " IJKLJlb bbbbbI ",
      " I    l M   N I ",
      " I    l  OP   I ",
      " I    l QQQQQ I ",
      " IRRR    S S  I ",
      " IIII        TI ",
      " IUV I       WI ",
      " I   X       YI ",
      " IZ  I 0000000I ",
      " I12xI        I ",
      " II3II3II3II3II ",
      "                ",
      "                ",
      "                "
    ],
    [
      "      4   5   D ",
      "      l       I ",
      " IJ67Jlb bbbbbI ",
      " I    l 8   N I ",
      " I    9       I ",
      " I    l  #$%^ I ",
      " I  R         I ",
      " IIII        &I ",
      " I  *I        I ",
      " I   (        I ",
      " I  )I        I ",
      " I+2xI        I ",
      " II3II3II3II3II ",
      "                ",
      "                ",
      "                "
    ],
    [
      "      l------lD ",
      "      l------lI ",
      " IJJJJlbbbbbbbI ",
      " I    l [   N I ",
      " 3    l       3 ",
      " 3    l       3 ",
      " 3  R         3 ",
      " ]III         { ",
      " 3 } I        3 ",
      " 3 | ;        3 ",
      " 3   I        3 ",
      " I:'xI        I ",
      " II3II3II3II3II ",
      "                ",
      "                ",
      "                "
    ],
    [
      "              D ",
      "              I ",
      " Ibbbbbbbbbbb<I ",
      " I        > N I ",
      " I            I ",
      " I            I ",
      " I  R         I ",
      " IIII,        I ",
      " IgggI        I ",
      " IgggI        I ",
      " IgggI        I ",
      " IggxI        I ",
      " IIIIIIIIIIIIII ",
      "                ",
      "                ",
      "                "
    ]
  ]
}