{
  "name": "multi_policestation_1_base1",
  "refpalette": "deceasedcraft:multi_policestation_1/multi_policestation_1_base1_palette",
  "xsize": 16,
  "zsize": 16,
  "slices": [
    [
      "vabbbbbbbbbbbbav",
      "vabbbbbbbbbbbbav",
      "vaabaaaaaaaabaav",
      "vabbbbbbbbbbbbav",
      "vabbbbbbbbbbbbav",
      "vabbbbbbbbbbbbav",
      "vabbbbbbbbbbbbav",
      "vabbbbbbbbbbbbav",
      "vabbbbbbbbbbbbav",
      "vabbbbbbbbbbbbav",
      "vabbbbbbbbbbbbav",
      "vabbbbbbbbbbbcav",
      "vaabaaaaaaaa!aav",
      "vadddaeeeeeeeeev",
      "vadddaeeeeeeeeev",
      "vvvvvvvvvvvvvvvv"
    ],
    [
      "va            av",
      "va            av",
      "vaafaghghghaiaav",
      "va  jkkkkkk  lav",
      "va  mk        av",
      "va  nk   o    av",
      "va pnk  qqq   av",
      "va  nk  rrr   av",
      "va  nk   s    av",
      "va tnk        av",
      "va  uk      w av",
      "va  mkxxxcccy av",
      "vaaAaaaaaaaaBaav",
      "vaC Daeeeeeeeeev",
      "vaC Eaeeeeeeeeev",
      "vvvvvvvvvvvvvvvv"
    ],
    [
      "va            av",
      "va            av",
      "vaaFaIIIIIIaJaav",
      "va  K@L MNOP Qav",
      "va   @        av",
      "va  R@        av",
      "va  S@    T   av",
      "vaU V@   WX   av",
      "va  Y@        av",
      "va  Z@        av",
      "va   @     ww av",
      "va   @   ccy  av",
      "vaa0aaaaaaaaBaav",
      "vaC 1aeeeeeeeeev",
      "vaC 2aeeeeeeeeev",
      "vvvvvvvvvvvvvvvv"
    ],
    [
      "va            av",
      "va3           av",
      "vaa4aaaaaaaa4aav",
      "va   @    O  Qav",
      "va   @        av",
      "va   @        av",
      "va   @        av",
      "va   @        av",
      "va   @        av",
      "va   @        av",
      "va   @    ww  av",
      "va   @555cy   av",
      "vaa6aaaaa7aaBaav",
      "va8  aeeeeeeeeev",
      "va8  aeeeeeeeeev",
      "vvvvvvvvvvvvvvvv"
    ],
    [
      "va3           av",
      "va 3         3av",
      "vaaaaaaaaaaaaaav",
      "va   @    O   av",
      "va   @        av",
      "va   @        av",
      "va   @        av",
      "va   @        av",
      "va   @        av",
      "va   @        av",
      "va   @   ww   av",
      "va   @cccy    av",
      "vaaaaaaaaBaaBaav",
      "va   aeeeeeeeeev",
      "va   aeeeeeeeeev",
      "vvvvvvvvvvvvvvvv"
    ],
    [
      "va999999999999av",
      "va999999999999av",
      "vaaaaaaaaaaaaaav",
      "va   @   #O   av",
      "va   @        av",
      "va $ @        av",
      "va $ @  $$$   av",
      "va $ @  $$$   av",
      "va $ @        av",
      "va $ @        av",
      "va   @% ww    av",
      "va   @ccy     av",
      "vaaaaaaaaBaaBaav",
      "va999aeeeeeeeeev",
      "va999aeeeeeeeeev",
      "vvvvvvvvvvvvvvvv"
    ]
  ]
}