{
  "name": "multi_sunkenmonumentpark_7_ground",
  "refpalette": "deceasedcraft:multi_sunkenmonumentpark_7/multi_sunkenmonumentpark_7_ground_palette",
  "xsize": 16,
  "zsize": 16,
  "slices": [
    [
      "                ",
      "       a        ",
      "a a             ",
      "      a         ",
      "          bb    ",
      "          cbbb  ",
      "d         eeec  ",
      "     d     eee  ",
      "           eee  ",
      "   f    fg eee  ",
      " g   h     eeeii",
      "jjjjjjjjjjjekkll",
      "mmmmmmmmmmmekknn",
      "mmmmmmmmmmeekknn",
      "eeeeeeeeeeeekknn",
      "eeeeeeeeeeeekknn"
    ],
    [
      "        bbbbbbbb",
      "       a eeebbbb",
      "a a      eeeee  ",
      "      a  eeeee  ",
      "          eeee  ",
      "          ekkk  ",
      "a         ekkk  ",
      "     a     ekk  ",
      "           eoo  ",
      "   f     d eoo  ",
      " d   p     qoo  ",
      "           q    ",
      "    g  g   q    ",
      " gf ff          ",
      "         f      ",
      "                "
    ],
    [
      "        ekkkkkkk",
      "       r ekkkkee",
      "a r      eoooo  ",
      "         eoooo  ",
      "          qooo  ",
      "          q     ",
      "a         s     ",
      "     a     q    ",
      "           q    ",
      "         a q    ",
      " a   d          ",
      "                ",
      "    d  d        ",
      " d              ",
      "                ",
      "                "
    ],
    [
      "        s       ",
      "         q     t",
      "r        q    uu",
      "         s      ",
      "                ",
      "                ",
      "r               ",
      "     a          ",
      "                ",
      "         a      ",
      " a   a          ",
      "                ",
      "    a  a        ",
      " a              ",
      "                ",
      "                "
    ],
    [
      "                ",
      "                ",
      "                ",
      "                ",
      "                ",
      "                ",
      "                ",
      "                ",
      "                ",
      "         r      ",
      " r   a          ",
      "                ",
      "    a  a        ",
      " a              ",
      "                ",
      "                "
    ],
    [
      "                ",
      "                ",
      "                ",
      "                ",
      "                ",
      "                ",
      "                ",
      "                ",
      "                ",
      "                ",
      "     r          ",
      "                ",
      "    r  r        ",
      " r              ",
      "                ",
      "                "
    ]
  ]
}