{
  "name": "multi_sunkenmonumentpark_7_base1",
  "refpalette": "deceasedcraft:multi_sunkenmonumentpark_7/multi_sunkenmonumentpark_7_base1_palette",
  "xsize": 16,
  "zsize": 16,
  "slices": [
    [
      "aaaaaaaaaaaaaaaa",
      "aaaaaaaaaaaaaaaa",
      "aaaaaaaaaaaaaaaa",
      "aaaaaaaaaaaaaaaa",
      "aaaaaaaaaaaaaaaa",
      "aaaaaaaaaaaaaaaa",
      "aaaaaaaaaaaaaaaa",
      "aaaaaaaaaaaaaaaa",
      "aaaaaaaaaaaaaaaa",
      "aaaaaaaaaaaaaaaa",
      "aaaaaaaaaaaaaaaa",
      "aaaaaaaaaaaaaaaa",
      "aaaaaaaaaaaaaaaa",
      "aaaaaaaaaaaaaaaa",
      "aaaaaaaaaaaaaaaa",
      "vvvvvvvvvvvvvvvv"
    ],
    [
      "aaaaaaaaaaaaaaaa",
      "aaaaaaaaaaaaaaaa",
      "aaaaaaaaaaaaaaaa",
      "aaaaaaaaaaaaaaaa",
      "aaaaaaaaaaaaaaaa",
      "aaaaaaaaaaaaaaaa",
      "aaaaaaaaaaaaaaaa",
      "aaaaaaaaaaaaaaaa",
      "aaaaaaaaaaaaaaaa",
      "aaaaaaaaaaaaaaaa",
      "aaaaaaaaaaaaaaaa",
      "aaaaaaaaaaaaaaaa",
      "aaaaaaaaaaaaaaaa",
      "aaaaaaaaaaaaaaaa",
      "aaaaaaaaaaaaaaaa",
      "vvvvvvvvvvvvvvvv"
    ],
    [
      "aaabbbbbbbbbbbcc",
      "aaaabbbbbbbbbbcc",
      "aaaaaaabbbbbbbcc",
      "aaaaaaaaaaaaaaaa",
      "aaaaaaaaaaaaaaaa",
      "aaaaaaaaaaaaaaaa",
      "aaaaaaaaaaaaaaaa",
      "aaaaaaaaaaaaaaaa",
      "aaaaaaaaaaaaaaaa",
      "aaaaaaaaaaaaaaaa",
      "aaaaaaaaaaaaaaaa",
      "aaaaaaaaaaaaaaaa",
      "aaaaaaaaaaaaaaaa",
      "aaaaaaaaaaaaaaaa",
      "aaaaaaaaaaaaaaaa",
      "vvvvvvvvvvvvvvvv"
    ],
    [
      "bbbd  e ee      ",
      "bbbbdddf      gg",
      "bbbbbbbdddddddhh",
      "bbbbbbbbbbbbbbcc",
      "bbbbbbbbbbbbbbcc",
      "aabbbbbbbbbbbbcc",
      "aaaaaaaaaaaaaaaa",
      "aaaaaaaaaaaaaaaa",
      "aaaaaaaaaaaaaaaa",
      "aaaaaaaaaaaaaaaa",
      "aaaaaaaaaaaiiiii",
      "aaaaaaaaaaaiiiii",
      "aaaaaaaaaaaiiiii",
      "aaaaaaaaaaaiiiii",
      "aaaaaaaaaaaiiiii",
      "vvvvvvvvvvvvvvvv"
    ],
    [
      "e               ",
      "       j        ",
      "k k             ",
      "   e  k ee      ",
      "dd            gg",
      "bbddddddddddddhh",
      "bbbbbbbbbbbbbbcc",
      "bbbbbbbbbbbbbbcc",
      "bbbbbbbbbbbbbbcc",
      "aaaaaaaaaaaiiiii",
      "aaaaaaaaaaaiiiii",
      "aaaaaaaaaaaiiiii",
      "aaaaaaaaaaaiiiii",
      "aaaaaaaaaaaiiiii",
      "aaaaaaaaaaaiiiii",
      "vvvvvvvvvvvvvvvv"
    ],
    [
      "                ",
      "       l        ",
      "l l             ",
      "      l         ",
      "                ",
      "                ",
      "ke      e       ",
      "     k     mn gg",
      "dddddddddddiiihh",
      "bbbbbbbbbbbiiicc",
      "bbbbbbbbbbbiiicc",
      "bbbbbbbbbbbiiicc",
      "aaaaaaaaaaaiiiii",
      "aaaaaaaaaaaiiiii",
      "aaaaaaaaaaaiiiii",
      "vvvvvvvvvvvvvvvv"
    ]
  ]
}