{
  "name": "multi_courtyardofficetower_12_ground",
  "refpalette": "deceasedcraft:multi_courtyardofficetower_12/multi_courtyardofficetower_12_ground_palette",
  "xsize": 16,
  "zsize": 16,
  "slices": [
    [
      "aaaaaaaaaaaaaaaa",
      "aaaaaaaaaaaaaaaa",
      "aaaaaaaaaaaaaaaa",
      "aaaaaaaaaaaaaaaa",
      "aaaaaaaaaaaaaaaa",
      "aaaaaaaaaaaaaaaa",
      "aaaaaaaaaaaaaaaa",
      "aaaaaaaaaaaaaaaa",
      "aaaaaaaaaaaaaaaa",
      "aaaaaaaaaaaaaaaa",
      "aaaaaaaaaaaaaaaa",
      "aaaaaaaaaaaaaaaa",
      "aaaaaaaaaaaaaaaa",
      "aaaaaaaaaaaaaaaa",
      "aaaaaaaaaaaaaaaa",
      "aaaaaaaaaaaaaaaa"
    ],
    [
      "          b     ",
      "b      c      b ",
      "    b   b    b  ",
      "         b c b  ",
      "   c   b        ",
      "  bb      b     ",
      "          bb c  ",
      "        b     b ",
      " b c    c       ",
      "b     b         ",
      "       b b      ",
      "    b    b  bc  ",
      "  c bb       b  ",
      "       cb       ",
      "       b        ",
      "    b     b     "
    ],
    [
      "                ",
      "       d        ",
      "                ",
      "           d    ",
      "   d            ",
      "                ",
      "             d  ",
      "                ",
      "   d    d       ",
      "b               ",
      "                ",
      "             d  ",
      "  d b           ",
      "       d        ",
      "                ",
      "                "
    ],
    [
      "                ",
      "       b        ",
      "                ",
      "           b    ",
      "   b            ",
      "                ",
      "             b  ",
      "                ",
      "   b    b       ",
      "                ",
      "                ",
      "             b  ",
      "  b             ",
      "       b        ",
      "                ",
      "                "
    ],
    [
      "                ",
      "       b        ",
      "                ",
      "           b    ",
      "   b            ",
      "                ",
      "             b  ",
      "                ",
      "   b    b       ",
      "                ",
      "                ",
      "             b  ",
      "  b             ",
      "       b        ",
      "                ",
      "                "
    ],
    [
      "                ",
      "       b        ",
      "                ",
      "           b    ",
      "   b            ",
      "                ",
      "             b  ",
      "                ",
      "   b    b       ",
      "                ",
      "                ",
      "             b  ",
      "  b             ",
      "       b        ",
      "                ",
      "                "
    ]
  ]
}