{
  "name": "multi_courtyardofficetower_12_base1",
  "refpalette": "deceasedcraft:multi_courtyardofficetower_12/multi_courtyardofficetower_12_base1_palette",
  "xsize": 16,
  "zsize": 16,
  "slices": [
    [
      "vvvvvvvvvvvvvvvv",
      "vvvvaaaaaaaaaaav",
      "vvvvvaaaaaaaaaav",
      "vvvvvvaaaaaaaaav",
      "vvvvvvaaaaaaaaav",
      "vvvvvvaaaaaaaaav",
      "vvvvvvaaaaaaaaav",
      "vvvvvvaaaaaaaaav",
      "vvvvvvaaaaaaaaav",
      "vvvvvvaaaaaaaaav",
      "vvvvvvaaaaaaaaav",
      "vvvvvvvaaaaaaaav",
      "vvvvvvvaaaaaaaav",
      "vvvvvvvaaaaaaaav",
      "vvvvvvvaaaaaaaav",
      "vvvvvvvaaaaaaaav"
    ],
    [
      "vvvvvvvvvvvvvvvv",
      "bbbvaaaaaaaaaaav",
      "HHbbvaaaaaaaaaav",
      "HHHbbvaaaaaaaaav",
      "HHHHbvaaaaaaaaav",
      "HHHHbvaaaaaaaaav",
      "HHHHbvaaaaaaaaav",
      "HHHHbvaaaaaaaaav",
      "HHHHbvaaaaaaaaav",
      "bHHHbvaaaaaaaaav",
      "bHHHbvaaaaaaaaav",
      "bHHHbbvaaaaaaaav",
      "bHHHHbvaaaaaaaav",
      "bHHHHbvaaaaaaaav",
      "bHHHHbvaaaaaaaav",
      "bbHHHbvaaaaaaaav"
    ],
    [
      "vvvvvvvvvvvvvvvv",
      "   vaaaaaaaaaaav",
      "    vaaaaaaaaaav",
      "     vaaaaaaaaav",
      "     vaaaaaaaaav",
      "     vaaaaaaaaav",
      "     vaaaaaaaaav",
      "     vaaaaaaaaav",
      "     vaaaaaaaaav",
      "     vaaaaaaaaav",
      "     vaaaaaaaaav",
      "      vaaaaaaaav",
      "      vaaaaaaaav",
      "      vaaaaaaaav",
      "      vaaaaaaaav",
      "      vaaaaaaaav"
    ],
    [
      "vvvvvvvvvvvvvvvv",
      "   vaaaaaaaaaaav",
      "    vaaaaaaaaaav",
      "     vaaaaaaaaav",
      "     vaaaaaaaaav",
      "     vaaaaaaaaav",
      "     vaaaaaaaaav",
      "     vaaaaaaaaav",
      "     vaaaaaaaaav",
      "     vaaaaaaaaav",
      "     vaaaaaaaaav",
      "      vaaaaaaaav",
      "      vaaaaaaaav",
      "      vaaaaaaaav",
      "      vaaaaaaaav",
      "      vaaaaaaaav"
    ],
    [
      "vvvvvvvvvvvvvvvv",
      "   vaaaaaaaaaaav",
      "    vaaaaaaaaaav",
      "     vaaaaaaaaav",
      "     vaaaaaaaaav",
      "     vaaaaaaaaav",
      "     vaaaaaaaaav",
      "     vaaaaaaaaav",
      "     vaaaaaaaaav",
      "     vaaaaaaaaav",
      "     vaaaaaaaaav",
      "      vaaaaaaaav",
      "      vaaaaaaaav",
      "      vaaaaaaaav",
      "      vaaaaaaaav",
      "      vaaaaaaaav"
    ],
    [
      "vvvvvvvvvvvvvvvv",
      "cccvaaaaaaaaaaav",
      "ccccvaaaaaaaaaav",
      "cccccvaaaaaaaaav",
      "cccccvaaaaaaaaav",
      "cccccvaaaaaaaaav",
      "cccccvaaaaaaaaav",
      "cccccvaaaaaaaaav",
      "cccccvaaaaaaaaav",
      "cccccvaaaaaaaaav",
      "cccccvaaaaaaaaav",
      "ccccccvaaaaaaaav",
      "ccccccvaaaaaaaav",
      "ccccccvaaaaaaaav",
      "ccccccvaaaaaaaav",
      "ccccccvaaaaaaaav"
    ]
  ]
}