{
  "name": "multi_timbertower_0_ground",
  "refpalette": "deceasedcraft:multi_timbertower_0/multi_timbertower_0_ground_palette",
  "xsize": 16,
  "zsize": 16,
  "slices": [
    [
      "HHHabaaaabaaaaba",
      "HHHaabbababbabbb",
      "HHHaaabaaaaaabaa",
      "HHHvvvvvvvvvvvvv",
      "HHHvvvvvvvvvvvcv",
      "HHHvvvvvvvvvcvvv",
      "HHHvvvdvvvvvvdvv",
      "HHHvvvvvvvvvvvvv",
      "HHHvvvvvvvvvvvvv",
      "HHHvvvvvvvvvvvvv",
      "HHHvvvvvvvvvvvvv",
      "HHHvvvvvvvvvvvvv",
      "HHHvvvvvvvvvvvvv",
      "HHHvvvdvvvvvvdvv",
      "HHHvvvvvvvvvvv  ",
      "HHHvvvvvvvvvvv  "
    ],
    [
      "                ",
      "                ",
      "   e f fffffe ff",
      "   ggghgggggghgg",
      "   g!i       j k",
      "   gi        i j",
      "  lhi dmmmmmmdmm",
      "   g  noooooonpq",
      "   g  norssron  ",
      "   g  nt  u  nw ",
      "   g  nx     myA",
      "   g  n      B  ",
      "   g  n   CCCmiD",
      "  lh  dyEyyyydFF",
      "   g  n      I  ",
      "   g  J      I  "
    ],
    [
      "                ",
      "                ",
      "                ",
      "   ggghgggggghgg",
      "   gi           ",
      "   g            ",
      "   h  dmmmmmmdmm",
      "   g  nKLKMKKn  ",
      "   g  nN OP  n  ",
      "   g  n      n  ",
      "   g  n      myQ",
      "   g  n      R  ",
      "   g  n    S m  ",
      "   h  dyTyyyydFF",
      "   g  n      IUU",
      "   g  V      IUW"
    ],
    [
      "                ",
      "                ",
      "                ",
      "   ggghgggggghgg",
      "   gi i         ",
      "   g         i  ",
      "   h  dmmmmmmdmm",
      "   g  nMMLKMLni ",
      "   g  n      n  ",
      "   g  n      nX ",
      "   g  n      myy",
      "   g  n      m  ",
      "   g  n     Ym  ",
      "   h  dyyyyyydFF",
      "   g  n      IUU",
      "   g  n      IUU"
    ],
    [
      "                ",
      "                ",
      "                ",
      "   ggghgggggghgg",
      "   g  i     iZ  ",
      "   g  i     iii ",
      "   h  dmmmmmmdmm",
      "   g  nKKMKKKm!i",
      "   g  n      m  ",
      "   g  n      m  ",
      "   g  n      m00",
      "   g  n      m  ",
      "   g  n      mi ",
      "   h  d000000dFF",
      "   g  0      0  ",
      "   g  0      0  "
    ],
    [
      "                ",
      "                ",
      "                ",
      "   ggghgggggghgg",
      "   g11d111111d11",
      "   g11d111111d11",
      "  1hdddddddddddd",
      "  1011d111111dmm",
      "  1011d111111dmm",
      "  1011d111111dmm",
      "  1011d111111dmm",
      "  1011d111111d11",
      "  1011d111111d11",
      "  1hdddddddddddd",
      "   g11d111111d  ",
      "   g11d111111d  "
    ]
  ]
}