{
  "name": "multi_timbertower_0_base2",
  "refpalette": "deceasedcraft:multi_timbertower_0/multi_timbertower_0_base2_palette",
  "xsize": 16,
  "zsize": 16,
  "slices": [
    [
      "vvvvvvvvvvvvvvvv",
      "vaaaaaaaaaaaaaaa",
      "vaaaaaaaaaaaaaaa",
      "vaavvvvvvvvvvvvv",
      "vaavvvvvvvvvvvvv",
      "vaavvHHHHHHHHHHH",
      "vaavvHbHHHHHHbHH",
      "vaavvHHHHHHHHHHH",
      "vaavvHHHHHHHHHHH",
      "vaavvHHHHHHHHHHH",
      "vaavvHHHHHHHHHHH",
      "vaavvHHHHHHHHHHH",
      "vaavvHHHHHHHHHHH",
      "vaavvHbHHHHHHbvv",
      "vaavvHHHHHHHHvvv",
      "vaavvHHHHHHHHvvv"
    ],
    [
      "vvvvvvvvvvvvvvvv",
      "vaaaaaaaaaaaaaaa",
      "vaaaaaaaaaaaaaaa",
      "vaavvvvvvvvvvvvv",
      "vaavcccccccccccc",
      "vaavc   defef ef",
      "vaavc b dg   b  ",
      "vaavc   dhihijhi",
      "vaavckkk        ",
      "vaavce f        ",
      "vaavch i        ",
      "vaavce f        ",
      "vaavch i     l  ",
      "vaavc bm     bnn",
      "vaavce f     o  ",
      "vaavch i     o  "
    ],
    [
      "vvvvvvvvvvvvvvvv",
      "vaaaaaaaaaaaaaaa",
      "vaaaaaaaaaaaaaaa",
      "vaavvvvvvvvvvvvv",
      "vaav            ",
      "vaav            ",
      "vaav  b      b  ",
      "vaav            ",
      "vaav            ",
      "vaav            ",
      "vaav            ",
      "vaav            ",
      "vaav            ",
      "vaav  b      bnn",
      "vaav         opp",
      "vaav         opq"
    ],
    [
      "vvvvvvvvvvvvvvvv",
      "vaaaaaaaaaaaaaaa",
      "vaaaaaaaaaaaaaaa",
      "vaavvvvvvvvvvvvv",
      "vaav            ",
      "vaav            ",
      "vaav  b      b  ",
      "vaav            ",
      "vaav            ",
      "vaav            ",
      "vaav            ",
      "vaav            ",
      "vaav            ",
      "vaav  b      bnn",
      "vaav         opp",
      "vaav         opp"
    ],
    [
      "vvvvvvvvvvvvvvvv",
      "vaaaaaaaaaaaaaaa",
      "vaaaaaaaaaaaaaaa",
      "vaavvvvvvvvvvvvv",
      "vaav            ",
      "vaav            ",
      "vaav  b      b  ",
      "vaav            ",
      "vaav            ",
      "vaav            ",
      "vaav            ",
      "vaav            ",
      "vaav            ",
      "vaav  b      bnn",
      "vaav         r  ",
      "vaav         r  "
    ],
    [
      "vvvvvvvvvvvvvvvv",
      "vaaaaaaaaaaaaaaa",
      "vaaaaaaaaaaaaaaa",
      "vaavvvvvvvvvvvvv",
      "vaavvvvvvvvvvvvv",
      "vaavvsssssssssss",
      "vaavvsbbbbbbbbbb",
      "vaavvsbssssssbss",
      "vaavvsbssssssbss",
      "vaavvsbssssssbss",
      "vaavvsbssssssbss",
      "vaavvsbssssssbss",
      "vaavvsbssssssbss",
      "vaavvsbbbbbbbbbb",
      "vaavvsbssssssb  ",
      "vaavvsbssssssb  "
    ]
  ]
}