{
  "name": "multi_timbertower_0_floor1",
  "refpalette": "deceasedcraft:multi_timbertower_0/multi_timbertower_0_floor1_palette",
  "xsize": 16,
  "zsize": 16,
  "slices": [
    [
      "                ",
      "                ",
      "                ",
      "   aaabaaaaaabaa",
      "   acdeeeeeeeeee",
      "   acdeeeeeeeeef",
      "   bcdeefeeeefee",
      "   acdeeeefeeegf",
      "   acdeeefgfggee",
      "   acdefeegggefe",
      "   acdeegeffegee",
      "   acdefgfgffgef",
      "   acdeegggghhhh",
      "   bcdeeffgghihh",
      "   acdeeeggghh  ",
      "   acdeeefgghh  "
    ],
    [
      "                ",
      "                ",
      "                ",
      "   aaabaaaaaabaa",
      "   ajkl      l  ",
      "   ajmn         ",
      "   bjop         ",
      "   ajmp         ",
      "   ajmn         ",
      "   ajmp         ",
      "   ajkp         ",
      "   ajmn         ",
      "   ajmp    q    ",
      "   bjkn    r iss",
      "   ajmn    t u  ",
      "   ajkp    w u  "
    ],
    [
      "                ",
      "                ",
      "                ",
      "   aaabaaaaaabaa",
      "   axy          ",
      "   ajA          ",
      "   bj           ",
      "   axA          ",
      "   ajA          ",
      "   ajA          ",
      "   ajy          ",
      "   ajA          ",
      "   axA          ",
      "   bxy       iss",
      "   ajA       uBB",
      "   ajy     C uBD"
    ],
    [
      "                ",
      "                ",
      "                ",
      "   aaabaaaaaEF  ",
      "   ax           ",
      "   aj           ",
      "   bj           ",
      "   a            ",
      "   aj           ",
      "   aj           ",
      "   aj           ",
      "   aj           ",
      "   aj           ",
      "   bx        iss",
      "   aj        uBB",
      "   aj        uBB"
    ],
    [
      "                ",
      "                ",
      "                ",
      "   aaabaEE      ",
      "   aj           ",
      "   aj           ",
      "   b            ",
      "   a            ",
      "   ax           ",
      "   aj           ",
      "   a            ",
      "   a            ",
      "   a            ",
      "   bx        iss",
      "   a         I  ",
      "   a         I  "
    ],
    [
      "                ",
      "                ",
      "                ",
      "   EEE          ",
      "   E            ",
      "   E            ",
      "   F            ",
      "   E            ",
      "   E            ",
      "   E            ",
      "   E         J  ",
      "   E        KLMM",
      "   E       N O  ",
      "   F      JLOiii",
      "   E       P i  ",
      "   E       P i  "
    ]
  ]
}