{
  "name": "multi_farmhouse1_1_floor1",
  "refpalette": "deceasedcraft:multi_farmhouse1_1/multi_farmhouse1_1_floor1_palette",
  "xsize": 16,
  "zsize": 16,
  "slices": [
    [
      "aaaaaaaaaaaaaaaa",
      "aaaaaaaaaaaaaaab",
      "aaaaaaaaaaaaaabb",
      "aaaaaaaaaaaaaabb",
      "aaaaaaaaaaaaaabb",
      "aaaaaaaaaaaaaabb",
      "aaaaaaaaaaaaaabb",
      "aaaaaaaaaaaaaabb",
      "aaaaaaaaaaaaaabb",
      "aaaaaaaaaaaaaabb",
      "aaaaaaaaaaaaaaab",
      "aaaaaaaaaaaaaaab",
      "aaaaaaaaaaaaaaab",
      "aaaaaaaaaaaaaaaa",
      "aaaaaaaaaaaaaaaa",
      "aaaaaaaaaaaaaaaa"
    ],
    [
      "cdeeeeeeeeeeeeee",
      "feedeeeeedeeeeea",
      "edeedeeeeeeeeeaa",
      "cdedeeeeeeeeeeaa",
      "ceeeeeeeeedeeeaa",
      "cdeedededgeeeeaa",
      "feeeeeeeeeeeeeaa",
      "ceedeeeeeedeeeaa",
      "eddeedeeeeeeeeaa",
      "dfeeeeeeeeeeeeaa",
      "ceeddeeeeeeeeeea",
      "ceeeedeeeegeeeea",
      "dhdeeeeeeeeeeeea",
      "cdegdeedeeeeeeed",
      "cdeeeeeeeeeeeeed",
      "ceedeeeeeeeeeeee"
    ],
    [
      "ddiiiiiiiiiiiiii",
      "diidiiiiidiiiiid",
      "idiidiiiiiiiiidd",
      "ddidiiiiiiiiiidd",
      "diiiiiiiiidiiidd",
      "ddiidididgiiiidd",
      "diiiiiiiiiiiiidd",
      "diidiiiiiidiiidd",
      "iddiidiiiiiiiidd",
      "ddiiiiiiiiiiiidd",
      "diiddiiiiiiiiiid",
      "diiiidiiiidiiiid",
      "dddiiiiiiiiiiiid",
      "ddijdiidiiiiiiid",
      "ddiiiiiiiiiiiiid",
      "diidiiiiiiiiiiii"
    ],
    [
      "dddddddddddddddd",
      "dddddddddddddddd",
      "dddddddddddddddd",
      "dddddddddddddddd",
      "dddddddddddddddd",
      "dddddddddkdddddd",
      "dddddddddddddddd",
      "dddddddddddddddd",
      "dddddddddddddddd",
      "dddddddddddddddd",
      "dddddddddddddddd",
      "dddddddddddddddd",
      "dddddddddddddddd",
      "dddddddddddddddd",
      "dddddddddddddddd",
      "dddddddddddddddd"
    ],
    [
      "dddddddddddddddd",
      "dddddddddddddddd",
      "dddddddddddddddd",
      "dddddddddddddddd",
      "dddddddddddddddd",
      "dddddddddddddddd",
      "dddddddddddddddd",
      "dddddddddddddddd",
      "dddddddddddddddd",
      "dddddddddddddddd",
      "dddddddddddddddd",
      "dddddddddddddddd",
      "dddddddddddddddd",
      "dddddddddddddddd",
      "dddddddddddddddd",
      "dddddddddddddddd"
    ],
    [
      "dddddddddddddddd",
      "dddddddddddddddd",
      "dddddddddddddddd",
      "dddddddddddddddd",
      "dddddddddddddddd",
      "dddddddddddddddd",
      "dddddddddddddddd",
      "dddddddddddddddd",
      "dddddddddddddddd",
      "dddddddddddddddd",
      "dddddddddddddddd",
      "dddddddddddddddd",
      "dddddddddddddddd",
      "dddddddddddddddd",
      "dddddddddddddddd",
      "dddddddddddddddd"
    ]
  ]
}