{
  "name": "multi_verticalschool_19_floor10",
  "refpalette": "deceasedcraft:multi_verticalschool_19/multi_verticalschool_19_floor10_palette",
  "xsize": 16,
  "zsize": 16,
  "slices": [
    [
      " ab             ",
      "aab             ",
      "bb              ",
      "                ",
      "                ",
      "                ",
      "                ",
      "                ",
      "                ",
      "                ",
      "                ",
      "                ",
      "                ",
      "                ",
      "                ",
      "                "
    ],
    [
      "                ",
      "                ",
      "                ",
      "                ",
      "                ",
      "                ",
      "                ",
      "                ",
      "                ",
      "                ",
      "                ",
      "                ",
      "                ",
      "                ",
      "                ",
      "                "
    ],
    [
      "cccccccccccdc e ",
      "cccccccccccdc e ",
      "cccccccccccdc e ",
      "cccccccccccdc e ",
      "cccccccccccdc e ",
      "ccccccccccdcc e ",
      "ddddddddddcc e  ",
      "ccccccccccc  e  ",
      "           ee   ",
      "eeeeeeeeeee     ",
      "                ",
      "                ",
      "                ",
      "                ",
      "                ",
      "                "
    ],
    [
      "fffggggggffffhi ",
      "fffggggggffffhi ",
      "fffggggggffffhi ",
      "fffggggggffffhi ",
      "fffffffffffffhi ",
      "fffffffffffffhi ",
      "ffffffffffffhi  ",
      "fffffffffffhhi  ",
      "hhhhhhhhhhhii   ",
      "iiiiiiiiiii     ",
      "                ",
      "                ",
      "                ",
      "                ",
      "                ",
      "                "
    ],
    [
      "    jjjj    khb ",
      "    jjjj    lhb ",
      "    jjjj    mhb ",
      "             hb ",
      "             hb ",
      "             hb ",
      "            hb  ",
      "    noop   hhb  ",
      "hhhhhhhhhhhbb   ",
      "bbbbbbbbbbb     ",
      "                ",
      "                ",
      "                ",
      "                ",
      "                ",
      "                "
    ],
    [
      "      q      r  ",
      "    s ts     r  ",
      "      u      r  ",
      "             r  ",
      "             r  ",
      "             r  ",
      "            r   ",
      "           rr   ",
      "rrrrrrrrrrr     ",
      "                ",
      "                ",
      "                ",
      "                ",
      "                ",
      "                ",
      "                "
    ]
  ]
}