{
  "name": "multi_verticalschool_19_base1",
  "refpalette": "deceasedcraft:multi_verticalschool_19/multi_verticalschool_19_base1_palette",
  "xsize": 16,
  "zsize": 16,
  "slices": [
    [
      "           abcdd",
      "           ae fg",
      "           ah  i",
      "           a  fg",
      "           abddd",
      "            j   ",
      "            k   ",
      "           abcdd",
      "           al fg",
      "           ah  i",
      "           a  fg",
      "           abddd",
      "            j   ",
      "                ",
      "mmmmmmmmmmmmmmmm",
      "vvvvvvvvvvvvvvvv"
    ],
    [
      "           abnop",
      "           a    ",
      "           a    ",
      "           a    ",
      "           abppp",
      "            q   ",
      "            k   ",
      "           abnop",
      "           a    ",
      "           a    ",
      "           a    ",
      "           abppp",
      "            q   ",
      "                ",
      "mmmmmmmmmmmmmmmm",
      "vvvvvvvvvvvvvvvv"
    ],
    [
      "            rsss",
      "            tuuu",
      "            tu w",
      "            tuuu",
      "            rsss",
      "                ",
      "                ",
      "            rsss",
      "            tuuu",
      "            tu w",
      "            tuuu",
      "            rsss",
      "                ",
      "                ",
      "mmmmmmmmmmmmmmmm",
      "vvvvvvvvvvvvvvvv"
    ],
    [
      "                ",
      "                ",
      "              x ",
      "                ",
      "                ",
      "                ",
      "                ",
      "                ",
      "                ",
      "              x ",
      "                ",
      "                ",
      "                ",
      "                ",
      "mmmmmmmmmmmmmmmm",
      "vvvvvvvvvvvvvvvv"
    ],
    [
      "                ",
      "                ",
      "                ",
      "                ",
      "                ",
      "                ",
      "                ",
      "                ",
      "                ",
      "                ",
      "                ",
      "                ",
      "                ",
      "                ",
      "mmmmmmmmmmmmmmmm",
      "vvvvvvvvvvvvvvvv"
    ],
    [
      "yyyyyyyyyyyyyyyy",
      "yyyyyyyyyyyyyyyy",
      "yyyyyAAyyyyyyyAA",
      "yyyyyyyyyyyyyyyy",
      "yyyyyyyyyyyyyyyy",
      "yyyyyyyyyyyyyyyy",
      "yyyyyyyyyyyyyyyy",
      "yyyyyyyyyyyyyyyy",
      "yyyyyyyyyyyyyyyy",
      "yyyyyAAyyyyyyyAA",
      "yyyyyyyyyyyyyyyy",
      "yyyyyyyyyyyyyyyy",
      "yyyyyyyyyyyyyyyy",
      "yyyyyyyyyyyyyyyy",
      "BBBBBBBBBBBBBBBB",
      "vvvvvvvvvvvvvvvv"
    ]
  ]
}