{
  "name": "multi_verticalschool_19_floor11",
  "refpalette": "deceasedcraft:multi_verticalschool_19/multi_verticalschool_19_floor11_palette",
  "xsize": 16,
  "zsize": 16,
  "slices": [
    [
      "      a      b  ",
      "     c       b  ",
      "     d       b  ",
      "             b  ",
      "             b  ",
      "             b  ",
      "            b   ",
      "           bb   ",
      "bbbbbbbbbbb     ",
      "                ",
      "                ",
      "                ",
      "                ",
      "                ",
      "                ",
      "                "
    ],
    [
      "      e      b  ",
      "      f      b  ",
      "     a       b  ",
      "             b  ",
      "             b  ",
      "             b  ",
      "            b   ",
      "           bb   ",
      "bbbbbbbbbbb     ",
      "                ",
      "                ",
      "                ",
      "                ",
      "                ",
      "                ",
      "                "
    ],
    [
      "             b  ",
      "     f       b  ",
      "     e       b  ",
      "             b  ",
      "             b  ",
      "             b  ",
      "            b   ",
      "           bb   ",
      "bbbbbbbbbbb     ",
      "                ",
      "                ",
      "                ",
      "                ",
      "                ",
      "                ",
      "                "
    ],
    [
      "             bg ",
      "    hiij     bg ",
      "             bg ",
      "             bg ",
      "             bg ",
      "             bg ",
      "            bg  ",
      "           bbg  ",
      "bbbbbbbbbbbgg   ",
      "ggggggggggg     ",
      "                ",
      "                ",
      "                ",
      "                ",
      "                ",
      "                "
    ],
    [
      "kkkkllllkkkkmno ",
      "kkkklkklkkkkmno ",
      "kkkkllllkkkkmno ",
      "kkkkkkkkkkkkmno ",
      "kkkkkkkkkkkkmno ",
      "kkkkkkkkkkkkmno ",
      "kkkkkkkkkkkmno  ",
      "mmmmmmmmmmmnno  ",
      "nnnnnnnnnnnoo   ",
      "ooooooooooo     ",
      "                ",
      "                ",
      "                ",
      "                ",
      "                ",
      "                "
    ],
    [
      "pppqqqqqpppprns ",
      "pqqqqqqqpppprns ",
      "qqqqqqqppppprns ",
      "qqqqqppppppprns ",
      "qqqqppppppprrns ",
      "qpppppppppprnns ",
      "ppppppppprrrns  ",
      "rrrrrrrrrrnnns  ",
      "nnnnnnnnnnnss   ",
      "sssssssssss     ",
      "                ",
      "                ",
      "                ",
      "                ",
      "                ",
      "                "
    ]
  ]
}