{
  "name": "multi_convenientstore_1_top",
  "refpalette": "deceasedcraft:multi_convenientstore_1/multi_convenientstore_1_top_palette",
  "xsize": 16,
  "zsize": 16,
  "slices": [
    [
      "      ab        ",
      "      ab        ",
      "      ab        ",
      "      ab        ",
      "      abcccccccc",
      "      abdddddddd",
      "      abdddddddd",
      "      abdddddddd",
      "      abdddddddd",
      "      abeddddedd",
      "    vvvfgggggggg",
      "    vvvv        ",
      "                ",
      "                ",
      "                ",
      "                "
    ],
    [
      "      hb        ",
      "      hb        ",
      "      hb        ",
      "      hb        ",
      "      hbiiiiiiii",
      "      hbjklmnjkl",
      "      hb o  p   ",
      "      hb  q     ",
      "      hb   r   q",
      "      hbstuuwstu",
      "    vvvfgggggggg",
      "    vvvv        ",
      "                ",
      "                ",
      "                ",
      "                "
    ],
    [
      "     xxb        ",
      "     xxb        ",
      "     xxb        ",
      "     xxb        ",
      "     xxb        ",
      "     xxb y    A ",
      "     xxb        ",
      "     xxb        ",
      "     xxb        ",
      "     xxbBCDE BFI",
      "    vvvfggJJggJJ",
      "    vvvv        ",
      "                ",
      "                ",
      "                ",
      "                "
    ],
    [
      "      gb        ",
      "      gb        ",
      "      gb        ",
      "      gb        ",
      "      gb        ",
      "      gb        ",
      "      gb        ",
      "      gb        ",
      "      gb        ",
      "      gb        ",
      "    vvvfggddggdd",
      "    vvvv        ",
      "                ",
      "                ",
      "                ",
      "                "
    ],
    [
      "      gfKKKKKKKK",
      "      gfKKKKKKKK",
      "      gfLKKKKKKK",
      "      gfKKKKKKKK",
      "      gfKKKKKKKK",
      "      gfKKKKKKKK",
      "      gfKKKKKKKK",
      "      gfKKKKKKKK",
      "      gfKKKKKKKK",
      "      gfLKKKKKKK",
      "    vvvfgggggggg",
      "    vvvv        ",
      "                ",
      "                ",
      "                ",
      "                "
    ],
    [
      "      M         ",
      "      M         ",
      "      M N       ",
      "      M         ",
      "      M         ",
      "      M         ",
      "      M         ",
      "      M         ",
      "      M O       ",
      "      MPQR      ",
      "    vvvvMMMMMMMM",
      "    vvvv        ",
      "                ",
      "                ",
      "                ",
      "                "
    ],
    [
      "                ",
      "                ",
      "                ",
      "                ",
      "                ",
      "                ",
      "                ",
      "                ",
      "                ",
      "                ",
      "    SSSS        ",
      "    SSSS        ",
      "                ",
      "                ",
      "                ",
      "                "
    ]
  ]
}