{
  "name": "multi_convenientstore_1_floor1",
  "refpalette": "deceasedcraft:multi_convenientstore_1/multi_convenientstore_1_floor1_palette",
  "xsize": 16,
  "zsize": 16,
  "slices": [
    [
      "       abbbbbbbb",
      "       ab       ",
      "       ab       ",
      "       ab       ",
      "       ab       ",
      "       abccccccc",
      "       abddddddd",
      "       abddddddd",
      "       abddddddd",
      "       abddddddd",
      "       abddddddd",
      "       abddddddd",
      "       abeeeeeee",
      "     vvvv       ",
      "                ",
      "                "
    ],
    [
      "       fbbbbbbbb",
      "       fb       ",
      "       fb       ",
      "       fb       ",
      "       fb       ",
      "       fbggggggg",
      "       fbhi jhi ",
      "       fbk      ",
      "       fb       ",
      "       fb       ",
      "       fb       ",
      "       fblmnolmn",
      "       fbeeeeeee",
      "     vvvv       ",
      "                ",
      "                "
    ],
    [
      "      ppbbbbbbbb",
      "      ppb       ",
      "      ppb       ",
      "      ppb       ",
      "      ppb       ",
      "      ppb       ",
      "      ppb       ",
      "      ppb       ",
      "      ppb       ",
      "      ppb       ",
      "      ppb       ",
      "      ppbqr  qr ",
      "      ppbeessees",
      "     vvvv       ",
      "                ",
      "                "
    ],
    [
      "       ebbbbbbbb",
      "       eb       ",
      "       eb       ",
      "       eb       ",
      "       eb       ",
      "       eb       ",
      "       eb       ",
      "       eb       ",
      "       eb       ",
      "       eb       ",
      "       eb       ",
      "       eb       ",
      "       eeeeeeeee",
      "     vvvv       ",
      "                ",
      "                "
    ],
    [
      "       etttttttt",
      "       etttttttt",
      "       etttttttt",
      "       etttttttt",
      "       etttttttt",
      "       etttttttt",
      "       etttttttt",
      "       etttttttt",
      "       etttttttt",
      "       etttttttt",
      "       etttttttt",
      "       etttttttt",
      "       eeeeeeeee",
      "     vvvv       ",
      "                ",
      "                "
    ],
    [
      "                ",
      "                ",
      "                ",
      "                ",
      "                ",
      "                ",
      "                ",
      "                ",
      "                ",
      "                ",
      "                ",
      "                ",
      "                ",
      "     vvvv       ",
      "                ",
      "                "
    ]
  ]
}