{
  "name": "multi_convenientstore_1_ground",
  "refpalette": "deceasedcraft:multi_convenientstore_1/multi_convenientstore_1_ground_palette",
  "xsize": 16,
  "zsize": 16,
  "slices": [
    [
      "abHHbccccccccccc",
      "abHHbccccccccccc",
      "abHHbccccccccccc",
      "abHHbccccccccccc",
      "abHHbccccccccccc",
      "abHHbccccccccccc",
      "abHHbccccccccccc",
      "abHHbccccccccccc",
      "abHHbccccccccccc",
      "abHHbccccccccccc",
      "abHHvvvvcccccccc",
      "abHHvvvvbbbbbbbb",
      "abHHHHHHHHHHHHHH",
      "abbHHHHHHHHHHHHH",
      "abbbbbbbbbbbbbbb",
      "accccccccccccccc"
    ],
    [
      "  d  eccffffffff",
      "  g  eccffffffff",
      "     eccffffffff",
      "h    eccffffffff",
      "     eccffffffff",
      "     eccffffffff",
      "     eccffffffff",
      "h    eccffffffff",
      "  i  eccffffffff",
      "     eccffjfffff",
      "    vvvvcccccccc",
      "h   vvvvbbbbbbbb",
      "     kkkHHHHHHHH",
      "     kkkHHHHHHHH",
      "     lllbbbbbbbb",
      " eeemmmmmmmmmmmm"
    ],
    [
      "          no p  ",
      "       bqqqqqq  ",
      "       b r    o ",
      "s      b   t u t",
      "       bwxxwxy  ",
      "       bAAAAAy B",
      "       bCDDDDy  ",
      "s      b  EF I  ",
      "       bJ   K   ",
      "       bLM MNOOO",
      "    vvvPQQQQQQQQ",
      "s   vvvvRSSSR R ",
      "         TTU    ",
      "                ",
      "                ",
      "       eeeeeeeee"
    ],
    [
      "       V        ",
      "       bWnXY    ",
      "       b        ",
      "Z      V        ",
      "       bx0xx1y  ",
      "       bAAAAAy  ",
      "       bDFDDD2  ",
      "Z               ",
      "       b        ",
      "       b     3  ",
      "    vvvPQQQQQQQQ",
      "Z   vvvv SSSR   ",
      "         TTT    ",
      "                ",
      "                ",
      "                "
    ],
    [
      "       V        ",
      "       b        ",
      "       b        ",
      "4      V        ",
      "       bxxx5x2  ",
      "       b66666y  ",
      "       bDDD7Dy  ",
      "Z      V        ",
      "       b        ",
      "       b        ",
      "    vvvPQQQQQQQQ",
      "Z   vvvv  PR    ",
      "                ",
      "                ",
      "                ",
      "                "
    ],
    [
      "       V        ",
      "       b        ",
      "       b        ",
      "       b        ",
      "       b88888888",
      "       b88888888",
      "       b88888888",
      "Z      b        ",
      "       b        ",
      "       bPP9PP9PP",
      "    vvvPQQPQQPQQ",
      "4   vvvv  PPPPPP",
      "                ",
      "                ",
      "                ",
      "                "
    ]
  ]
}