{
  "name": "multi_laboratory_6_base7",
  "refpalette": "deceasedcraft:multi_laboratory_6/multi_laboratory_6_base7_palette",
  "xsize": 16,
  "zsize": 16,
  "slices": [
    [
      "aaaaaaaaaaaaaabc",
      "aaaaaaaaaaaaaaca",
      "aaaaaaaaaaaaaaaa",
      "aaaaaaaaaaaaaaaa",
      "aaaaaaaaaaaaaaaa",
      "aaaaaaaaaaaaaaaa",
      "aaaaaaaaaaaaaaaa",
      "aaaaaddddddaaaaa",
      "aaadddaaaadddaaa",
      "adddaaaaaaaaddda",
      "ddaaaaacaaaaaadd",
      "daaaaaaaacaaaaad",
      "daaaaabaaaaaaaad",
      "aaaaeeeeeeeeaaaa",
      "aaaaeffffffeaaaa",
      "aaaaeffffffeaaaa"
    ],
    [
      "aaaaaaaaaaaaaagh",
      "aaaaaaaaaaaaaaic",
      "aaaaaaaaaaaaaajc",
      "aaaaaaaaaaaaaaka",
      "aaaaaaaaaaaaaa a",
      "aaaaaaaaaaaaaaaa",
      "aaaaaaaaaaaaaaaa",
      "aaaaaaaaaaaaaaaa",
      "aaaaalmmmmlabaaa",
      "aaaaamm   mbaaaa",
      "alaaa       bcla",
      "aaaa    h   bnaa",
      "aaa          baa",
      "bh            bo",
      "aa p          ob",
      "aa           qbb"
    ],
    [
      "aaaaaaaaaaaaaaa ",
      "aaaaaaaaaaaaaaah",
      "aaaaaaaaaaaaaaac",
      "aaaaaaaaaaaaaaaa",
      "aaaaaaaaaaaaaaaa",
      "aaaaaaaaaaaaaaaa",
      "aaaaaaaaaaaaaaaa",
      "aaaaaaaaaaaaaaaa",
      "aaaaalm  mlaaaaa",
      "aaaa        aaaa",
      "alaa         qla",
      "a!o           ba",
      "aa           qba",
      "a             ro",
      "sts            o",
      "a              o"
    ],
    [
      "aaaaaaaaaaaaaaau",
      "aaaaaaaaaaaaaaau",
      "aaaaaaaaaaaaaaaa",
      "aaaaaaaaaaaaaaaa",
      "aaaaaaaaaaaaaaaa",
      "aaaaaaaaaaaaaaaa",
      "aaaaaaaaaaaaaaaa",
      "aaaaaaaaaaaaaaaa",
      "aaaaal    laaaaa",
      "aaaa        aaaa",
      "ala           la",
      "  q           ba",
      "               a",
      "              q ",
      " w             x",
      "                "
    ],
    [
      "aaaaaaaaaaaaaaaa",
      "aaaaaaaaaaaaaaaa",
      "aaaaaaaaaaaaaaaa",
      "aaaaaaaaaaaaaaaa",
      "aaaaaaaaaaaaaaaa",
      "aaaaaaaaaaaaaaaa",
      "aaaaaaaaaaaaaaaa",
      "aaaaabaaaaaaaaaa",
      "aaaaal    laaaaa",
      "aaaa        aaaa",
      " l            la",
      "               a",
      "               a",
      "                ",
      "               r",
      "                "
    ],
    [
      "aaaaaaaaaaaaaaaa",
      "aaaaaaaaaaaaaaaa",
      "aaaaaaaaaaaaaaaa",
      "aaaaaaaaaaaaaaaa",
      "aaaaaaaaaaaaaaaa",
      "aaaaaaaaaaaaaaaa",
      "aaaaaaaaaaaaaaaa",
      "aaaaaaaaaaaaaaaa",
      "aaaaal    laaaaa",
      "aaaa        aaaa",
      " l            la",
      "               a",
      "               a",
      "                ",
      "               q",
      "                "
    ]
  ]
}