{
  "name": "multi_laboratory_6_base3",
  "refpalette": "deceasedcraft:multi_laboratory_6/multi_laboratory_6_base3_palette",
  "xsize": 16,
  "zsize": 16,
  "slices": [
    [
      "aaaaaaaaaaaaaaaa",
      "aaaaaaaaaaaaaaaa",
      "aaaaaaaaaaaaaaaa",
      "aaaaaaaaaaaaaaaa",
      "aaaaaaaaaaaaaaaa",
      "aaaaaaaaaaaaaaaa",
      "aaaaaaaaaaaaaaaa",
      "aaaaabbbbbbaaaaa",
      "aaabbc    cbbaaa",
      "abbb        bbba",
      "bc            cb",
      "b              b",
      "b         d    b",
      "                ",
      " d              ",
      "                "
    ],
    [
      "  ef   ef   ef  ",
      "      g         ",
      "       hi j     ",
      "        k  l    ",
      "   hmnnnnnno p  ",
      "qrs mtu wxyo   q",
      "ABq   CjD     nE",
      "FI JcKKKKKKcL MN",
      " q KKc    cKK q ",
      " KKK        KKK ",
      "Kc            cK",
      "K              K",
      "K         d    K",
      "                ",
      " d              ",
      "                "
    ],
    [
      "  OP   OP   OP  ",
      "                ",
      "                ",
      "                ",
      "     Q RSTl     ",
      "                ",
      "               U",
      "    VKKKKKKV    ",
      "   KKc    cKK   ",
      " KKK        KKK ",
      "Kc            cK",
      "K              K",
      "K         d    K",
      "                ",
      " d              ",
      "                "
    ],
    [
      "                ",
      "                ",
      "                ",
      "                ",
      "                ",
      "                ",
      "                ",
      "    WKKKKKKW    ",
      "   KKc    cKK   ",
      " KKK        KKK ",
      "Kc            cK",
      "K              K",
      "K         d    K",
      "                ",
      " d              ",
      "                "
    ],
    [
      "                ",
      "                ",
      "                ",
      "                ",
      "                ",
      "                ",
      "                ",
      "     KKKKKK     ",
      "   KKc    cKK   ",
      " KKK        KKK ",
      "Kc            cK",
      "K              K",
      "K         X    K",
      "                ",
      " d              ",
      "                "
    ],
    [
      "YYYYYYYYYYYYYYYY",
      "YYYYYYYYYYYYYYYY",
      "YYYYYYYYYYYYYYYY",
      "YYYYYYYYYYYYYYYY",
      "YYYYYYYYYYZYYYYY",
      "YYYYYYYYYYYYYYYY",
      "YYYYYYYYYYYYYYYY",
      "YYYYYKKKKKKYYYYY",
      "YYYKKc    cKKYYY",
      "YKKK        KKKY",
      "Kc            cK",
      "K              K",
      "K         d    K",
      "                ",
      " d              ",
      "                "
    ]
  ]
}