{
  "name": "multi_laboratory_6_base2",
  "refpalette": "deceasedcraft:multi_laboratory_6/multi_laboratory_6_base2_palette",
  "xsize": 16,
  "zsize": 16,
  "slices": [
    [
      "aaaaaaaaaaaaaaaa",
      "aaaaaaaaaaaaaaaa",
      "aaaaaaaaaaaaaaaa",
      "aaaaaaaaaaaaaaaa",
      "aaaaaaaaaaaaaaaa",
      "aaaaaaaaaaaaaaaa",
      "aaaaaaaaaaaaaaaa",
      "aaaaabbbbbbaaaaa",
      "aaabbc    cbbaaa",
      "abbb        bbba",
      "bc            cb",
      "b              b",
      "b         d    b",
      "                ",
      " d              ",
      "                "
    ],
    [
      "  ef   ef   ef  ",
      "                ",
      "                ",
      "                ",
      "g   hiiiiiij    ",
      "    hk l  mj   g",
      "nog          gnn",
      "pq rcssssssct pp",
      " g ssc    css  g",
      " sss        sss ",
      "sc            cs",
      "s              s",
      "s         d    s",
      "                ",
      " d              ",
      "                "
    ],
    [
      "  uw   uw   uw  ",
      "                ",
      "                ",
      "                ",
      "     xyAB       ",
      "                ",
      "C             D ",
      " E  FssssssF   I",
      "   ssc    css   ",
      " sss        sss ",
      "sc            cs",
      "s              s",
      "s         J    s",
      "                ",
      " d              ",
      "                "
    ],
    [
      "                ",
      "                ",
      "                ",
      "                ",
      "                ",
      "                ",
      "                ",
      "    KssssssK    ",
      "   ssc    css   ",
      " sss        sss ",
      "sc            cs",
      "s              s",
      "s         d    s",
      "                ",
      " d              ",
      "                "
    ],
    [
      "                ",
      "                ",
      "                ",
      "                ",
      "                ",
      "                ",
      "                ",
      "     ssssss     ",
      "   ssc    css   ",
      " sss        sss ",
      "sc            cs",
      "s              s",
      "s         L    s",
      "                ",
      " d              ",
      "                "
    ],
    [
      "MMMMMMMMMMMMMMMM",
      "MNMMMNMMMMNMMMNM",
      "MNMMMNMMMMNMMMOM",
      "MNMMMNMMMMNMMMNM",
      "M!MMMNMMMMNMMMNM",
      "MMMMMMMMMMMMMMMM",
      "MMMMMMMMMMMMMMMM",
      "MMMMMssssssMMMMM",
      "MMMssc    cssMMM",
      "Msss        sssM",
      "sc            cs",
      "s              s",
      "s         d    s",
      "                ",
      " d              ",
      "                "
    ]
  ]
}