{
  "name": "multi_laboratory_6_base6",
  "refpalette": "deceasedcraft:multi_laboratory_6/multi_laboratory_6_base6_palette",
  "xsize": 16,
  "zsize": 16,
  "slices": [
    [
      "aaaaaaaaaaaaaaaa",
      "aaaaaaaaaaaaaaaa",
      "aaaaaaaaaaaaaaaa",
      "aaaaaaaaaaaaaaaa",
      "aaaaaaaaaaaaaaaa",
      "aaaaaaaaaaaaaaaa",
      "aaaaaaaaaaaaaaaa",
      "aaaaabbbbbbaaaaa",
      "aaabbc    cbbaaa",
      "abbb        bbba",
      "bc            cb",
      "b              b",
      "b              b",
      "                ",
      "                ",
      "                "
    ],
    [
      "  d e  df g df  ",
      "   e            ",
      "                ",
      "                ",
      "h              h",
      "iij          kii",
      "                ",
      "     llllll     ",
      "   llc    cll   ",
      " lll        lll ",
      "lc            cl",
      "l              l",
      "l              l",
      "                ",
      "                ",
      "                "
    ],
    [
      "  m    mn   mn  ",
      "                ",
      "                ",
      "                ",
      "                ",
      "o            p o",
      "                ",
      "     llllll     ",
      "   llc    cll   ",
      " lll        lll ",
      "lc        q   cl",
      "l         r    l",
      "l         s    l",
      "          t     ",
      "          t     ",
      "          u     "
    ],
    [
      "                ",
      "                ",
      "                ",
      "                ",
      "                ",
      "                ",
      "                ",
      "     llllll     ",
      "   llc    cll   ",
      " lll        lll ",
      "lc            cl",
      "l              l",
      "l         w    l",
      "                ",
      "                ",
      "                "
    ],
    [
      "                ",
      "                ",
      "                ",
      "                ",
      "                ",
      "                ",
      "                ",
      "     llllll     ",
      "   llc    cll   ",
      " lll        lll ",
      "lc            cl",
      "l              l",
      "l         x    l",
      "                ",
      "                ",
      "                "
    ],
    [
      "                ",
      "                ",
      "                ",
      "                ",
      "                ",
      "                ",
      "                ",
      "     llllll     ",
      "   llc    cll   ",
      " lll        lll ",
      "lc            cl",
      "l              l",
      "l         x    l",
      "                ",
      "                ",
      "                "
    ]
  ]
}