{
  "name": "multi_laboratory_6_base1",
  "refpalette": "deceasedcraft:multi_laboratory_6/multi_laboratory_6_base1_palette",
  "xsize": 16,
  "zsize": 16,
  "slices": [
    [
      "aaaaaaaaaaaaaaaa",
      "aaaaaaaaaaaaaaaa",
      "aaaaaaaaaaaaaaaa",
      "aaaaaaaaaaaaaaaa",
      "aaaaaaaaaaaaaaaa",
      "aaaaaaaaaaaaaaaa",
      "aaaaaaaaaaaaaaaa",
      "aaaaabbbbbbaaaaa",
      "aaabbc    dbbaaa",
      "abbb e    e bbba",
      "bf   e    e   fb",
      "b    e    e    b",
      "b    e    g    b",
      "     e    e     ",
      "egeeeeeeeeeeeeee",
      "     e    e     "
    ],
    [
      "  hi j hi   hi  ",
      "                ",
      "                ",
      "                ",
      "                ",
      "k               ",
      "lm           klm",
      "no pfqqqqqqfr no",
      " k qqf    fqq   ",
      " qqq        qqq ",
      "qf            fq",
      "q              q",
      "q         s    q",
      "                ",
      "                ",
      "                "
    ],
    [
      "  tu   tu   tu  ",
      "                ",
      "                ",
      "                ",
      "                ",
      "                ",
      "w               ",
      "    xqqqqqqx   y",
      "   qqf    fqq   ",
      " qqq        qqq ",
      "qf            fq",
      "q              q",
      "q              q",
      "                ",
      "                ",
      "                "
    ],
    [
      "                ",
      "                ",
      "                ",
      "                ",
      "                ",
      "                ",
      "                ",
      "    AqqqqqqA    ",
      "   qqf    fqq   ",
      " qqq        qqq ",
      "qf            fq",
      "q              q",
      "q              q",
      "                ",
      "                ",
      "                "
    ],
    [
      "                ",
      "                ",
      "                ",
      "                ",
      "                ",
      "                ",
      "                ",
      "     qqqqqq     ",
      "   qqf    fqq   ",
      " qqq        qqq ",
      "qf            fq",
      "q              q",
      "q              q",
      "                ",
      "                ",
      "                "
    ],
    [
      "BBBBBBBBBBBBBBBB",
      "BBBBBBBBBBBBBBBB",
      "BBBBBBBBBBBBBBBB",
      "BBBBBBBBBBBBBBBB",
      "BBBBBBBBBBBBBBBB",
      "BBBBBBBBBBBBBBBB",
      "BBBBBBBBBBBBBBBB",
      "BBBBBCCCCCCBBBBB",
      "BBBCCD    DCCBBB",
      "BCCC        CCCB",
      "CD            DC",
      "C              C",
      "C              C",
      "                ",
      "                ",
      "                "
    ]
  ]
}