{
  "name": "multi_laboratory_6_ground",
  "refpalette": "deceasedcraft:multi_laboratory_6/multi_laboratory_6_ground_palette",
  "xsize": 16,
  "zsize": 16,
  "slices": [
    [
      "aaaaaaaaaaaaaaaa",
      "aaaaaaaaaaaaaaaa",
      "aaaaaaaaaaaaaaaa",
      "aaaaaaaaaaaaaaaa",
      "aaaaaaaaaaaaaaaa",
      "aaaaaaaaaaaaaaaa",
      "aaaaaaaaaaaaaaaa",
      "aaaaabbbbbbaaaaa",
      "aaabbb@@@@bbbaaa",
      "abbb@@@@@@@@bbba",
      "bb@@@@@@@@@@@@bb",
      "b@@@@@@@@@@@@@@b",
      "b@@@@@@@@@@@@@@b",
      "@@@@@@@@@@@@@@@@",
      "@@@@@@@@@@@@@@@@",
      "@@@@@@@@@@@@@@@@"
    ],
    [
      "  cd e cd e cd  ",
      "                ",
      "                ",
      "                ",
      "                ",
      "                ",
      "                ",
      "     ffffff     ",
      "   fff    fff   ",
      " fff        fff ",
      "ff            ff",
      "f              f",
      "f              f",
      "                ",
      "                ",
      "                "
    ],
    [
      "  gh   gh   gh  ",
      "                ",
      "                ",
      "                ",
      "                ",
      "                ",
      "                ",
      "                ",
      "                ",
      "                ",
      "                ",
      "                ",
      "                ",
      "                ",
      "                ",
      "                "
    ],
    [
      "                ",
      "                ",
      "                ",
      "                ",
      "                ",
      "                ",
      "                ",
      "                ",
      "                ",
      "                ",
      "                ",
      "                ",
      "                ",
      "                ",
      "                ",
      "                "
    ],
    [
      "                ",
      "                ",
      "                ",
      "                ",
      "                ",
      "                ",
      "                ",
      "                ",
      "                ",
      "                ",
      "                ",
      "                ",
      "                ",
      "                ",
      "                ",
      "                "
    ],
    [
      "iiiiiiiiiiiiiiii",
      "iiiiiiiiiiiiiiii",
      "iiiiiiiiiiiiiiii",
      "iiiiiiiiiiiiiiii",
      "iiiii      iiiii",
      "ii            ii",
      "i              i",
      "                ",
      "                ",
      "                ",
      "                ",
      "                ",
      "                ",
      "                ",
      "                ",
      "                "
    ]
  ]
}