{
  "name": "multi_laboratory_6_base4",
  "refpalette": "deceasedcraft:multi_laboratory_6/multi_laboratory_6_base4_palette",
  "xsize": 16,
  "zsize": 16,
  "slices": [
    [
      "aaaaaaaaaaaaaaaa",
      "aaaaaaaaaaaaaaaa",
      "aaaaaaaaaaaaaaaa",
      "aaaaaaaaaaaaaaaa",
      "aaaaaaaaaaaaaaaa",
      "aaaaaaaa!aaaaaaa",
      "aaaaaaaaaaaaaaaa",
      "aaaaabbbbbbaaaaa",
      "aaabbc    cbbaaa",
      "abbb        bbba",
      "bc            cb",
      "b              b",
      "b         d    b",
      "                ",
      " d              ",
      "                "
    ],
    [
      "  ef   ef   ef g",
      "                ",
      "                ",
      " h              ",
      " h  ijjjjjjk    ",
      "l   imn   ok  l ",
      "pq            rq",
      "st ucwwwwwwcx yA",
      " l wwc    cww   ",
      " www        www ",
      "wc            cw",
      "w              w",
      "w         d    w",
      "                ",
      " B              ",
      "                "
    ],
    [
      "  CD   CD   CD  ",
      "                ",
      "                ",
      "                ",
      "     EFIJKL     ",
      "                ",
      "M             N ",
      "    OwwwwwwO   M",
      "   wwc    cww   ",
      " www        www ",
      "wc            cw",
      "w              w",
      "w         d    w",
      "                ",
      " d              ",
      "                "
    ],
    [
      "                ",
      "                ",
      "                ",
      "                ",
      "                ",
      "                ",
      "                ",
      "    PwwwwwwP    ",
      "   wwc    cww   ",
      " www        www ",
      "wc            cw",
      "w              w",
      "w         d    w",
      "                ",
      " d              ",
      "                "
    ],
    [
      "                ",
      "                ",
      "                ",
      "                ",
      "                ",
      "                ",
      "                ",
      "     wwwwww     ",
      "   wwc    cww   ",
      " www        www ",
      "wc            cw",
      "w              w",
      "w         d    w",
      "                ",
      " d              ",
      "                "
    ],
    [
      "QQQQQQQQQQQQQQQQ",
      "QRQQQRQQQQRQQQRQ",
      "QRQQQRQQQQRQQQRQ",
      "QSQQQRQQQQRQQQRQ",
      "QSQQQRQQQQRQQQRQ",
      "QQQQQQQQQQQQQQQQ",
      "QQQQQQQQQQQQQQQQ",
      "QQQQQwwwwwwQQQQQ",
      "QQQwwc    cwwQQQ",
      "Qwww        wwwQ",
      "wc            cw",
      "w              w",
      "w         d    w",
      "                ",
      " d              ",
      "                "
    ]
  ]
}