{
  "name": "multi_laboratory_6_top",
  "refpalette": "deceasedcraft:multi_laboratory_6/multi_laboratory_6_top_palette",
  "xsize": 16,
  "zsize": 16,
  "slices": [
    [
      "aaaaaaaaaaaaaaaa",
      "aaaaaaaaaaaaaaaa",
      "aaaaaaaaaaaaaaaa",
      "aaaaaaaaaaaaaaaa",
      "aaaaaaaaaaaaaaaa",
      "aaaaaa    aaaaaa",
      "aaa          aaa",
      "aa            aa",
      "a              a",
      "                ",
      "                ",
      "                ",
      "                ",
      "                ",
      "                ",
      "                "
    ],
    [
      "  bc d bc   bc d",
      "                ",
      "                ",
      "                ",
      "      eeee      ",
      "   eeef  geee   ",
      "  ef        ge  ",
      " ef          ge ",
      "g              f",
      "h              h",
      "                ",
      "                ",
      "                ",
      "                ",
      "                ",
      "                "
    ],
    [
      "  ij   ij   ij  ",
      "                ",
      "                ",
      "                ",
      "                ",
      "                ",
      "                ",
      "                ",
      "                ",
      "                ",
      "                ",
      "                ",
      "                ",
      "                ",
      "                ",
      "                "
    ]
  ]
}