{
  "name": "multi_campsite1_0_floor1",
  "refpalette": "deceasedcraft:multi_campsite1_0/multi_campsite1_0_floor1_palette",
  "xsize": 16,
  "zsize": 16,
  "slices": [
    [
      "aabbbbbaaaabbbbb",
      "bbbbbbbbbbaaabbb",
      "bcddcbbbbbaaabbb",
      "bcddcbbbbbaaaabb",
      "bcddcbbbbbbaabbb",
      "bbddbbbbbbabbbbb",
      "bbbddbbbbbbbbbbb",
      "bbdbdbdbbbcccbbb",
      "bdbdddbddddddbbb",
      "abbbdddbdddddbbb",
      "abbddbddbbcccbbb",
      "bbdbddbbbbbbbbba",
      "bbddddbbbbbbbbba",
      "bddddddbbbbbbbaa",
      "bbddddbdbbbbbbbb",
      "bdddbddbbdbbbbbb"
    ],
    [
      "aaaaaaaaaaaaaaaa",
      "aaaaaeaaaaaaaafa",
      "aghhgaafaaaaaaae",
      "agijgaaaaaaaaaaa",
      "agiigaaaaaaaaaaa",
      "aaklaaaaaaaaaaaa",
      "aaaaaaaaaaaaaaaa",
      "aaaaaaaaaammmaaa",
      "aanaaaaaaoppqaea",
      "aaaaaaaaarppqaaa",
      "aaaaaaaaaammmaaa",
      "aaaaaaaaaaaaaafa",
      "aaasaaaaanaaaaaa",
      "aaatuaaaaaaaaaaa",
      "aaavaaaaaaaaeaaa",
      "aaaaaaaaaaaaafaa"
    ],
    [
      "aaaaaaaaaaaaaaaa",
      "aaaaaaaaaaaaaawa",
      "axhhyaawaaaaaaaa",
      "axaayaaaaaaaaaaa",
      "axaayaaaaaaaaaaa",
      "aazAaaaaaaaaaaaa",
      "aaaaaaaaaaaaaaaa",
      "aaaaaaaaaaBBBaaa",
      "aaaaaaaaaCaaqaaa",
      "aaaaaaaaaDaaqaaa",
      "aaaaaaaaaaEEEaaa",
      "aaaaaaaaaaaaaawa",
      "aaaaaaaaaaaaaaaa",
      "aaaaaaaaaaaaaaaa",
      "aaaaaaaaaaaaaaaa",
      "aaaaaaaaaaaaawaa"
    ],
    [
      "aaaaaaaaaaaaaaaa",
      "aaaaaaaaaaaaaaaa",
      "aaxyaaaaaaaaaaaa",
      "aaxyaaaaaaaaaaaa",
      "aaxyaaaaaaaaaaaa",
      "aaaaaaaaaaaaaaaa",
      "aaaaaaaaaaaaaaaa",
      "aaaaaaaaaaaaaaaa",
      "aaaaaaaaaaBBBaaa",
      "aaaaaaaaaaEEEaaa",
      "aaaaaaaaaaaaaaaa",
      "aaaaaaaaaaaaaaaa",
      "aaaaaaaaaaaaaaaa",
      "aaaaaaaaaaaaaaaa",
      "aaaaaaaaaaaaaaaa",
      "aaaaaaaaaaaaaaaa"
    ],
    [
      "aaaaaaaaaaaaaaaa",
      "aaaaaaaaaaaaaaaa",
      "aaaaaaaaaaaaaaaa",
      "aaaaaaaaaaaaaaaa",
      "aaaaaaaaaaaaaaaa",
      "aaaaaaaaaaaaaaaa",
      "aaaaaaaaaaaaaaaa",
      "aaaaaaaaaaaaaaaa",
      "aaaaaaaaaaaaaaaa",
      "aaaaaaaaaaaaaaaa",
      "aaaaaaaaaaaaaaaa",
      "aaaaaaaaaaaaaaaa",
      "aaaaaaaaaaaaaaaa",
      "aaaaaaaaaaaaaaaa",
      "aaaaaaaaaaaaaaaa",
      "aaaaaaaaaaaaaaaa"
    ],
    [
      "aaaaaaaaaaaaaaaa",
      "aaaaaaaaaaaaaaaa",
      "aaaaaaaaaaaaaaaa",
      "aaaaaaaaaaaaaaaa",
      "aaaaaaaaaaaaaaaa",
      "aaaaaaaaaaaaaaaa",
      "aaaaaaaaaaaaaaaa",
      "aaaaaaaaaaaaaaaa",
      "aaaaaaaaaaaaaaaa",
      "aaaaaaaaaaaaaaaa",
      "aaaaaaaaaaaaaaaa",
      "aaaaaaaaaaaaaaaa",
      "aaaaaaaaaaaaaaaa",
      "aaaaaaaaaaaaaaaa",
      "aaaaaaaaaaaaaaaa",
      "aaaaaaaaaaaaaaaa"
    ]
  ]
}