{
  "name": "multi_terraceplaza_7_floor3",
  "refpalette": "deceasedcraft:multi_terraceplaza_7/multi_terraceplaza_7_floor3_palette",
  "xsize": 16,
  "zsize": 16,
  "slices": [
    [
      "aaaaaaaaaaabaaba",
      "cdcccdccdcddccdc",
      "                ",
      "                ",
      "                ",
      "      e        f",
      "g   h   ij    kf",
      "ffffffffffffffff",
      "                ",
      "     l          ",
      "                ",
      "                ",
      "                ",
      "                ",
      "   mfffff       ",
      "  n fop         "
    ],
    [
      "aaaaaaaaaaabaaba",
      "cdcccdccdcddccdc",
      "                ",
      "                ",
      "                ",
      "      e        f",
      "  qq     rststsf",
      "ffffffffffffffff",
      "                ",
      "                ",
      "                ",
      "                ",
      "                ",
      "     u u        ",
      "    fffff       ",
      "  w f x         "
    ],
    [
      "aaaaaaaaaaaaaaaa",
      "cdcccdccdcddccdc",
      "                ",
      "                ",
      "                ",
      "      e        f",
      "               f",
      "ffffffffffffffff",
      "                ",
      "                ",
      "                ",
      "                ",
      "                ",
      "      y         ",
      "    fffff       ",
      "AB  f x         "
    ],
    [
      "aaaaaaaaaaaaaaaa",
      "cdcccdccdcddccdc",
      "                ",
      "                ",
      "                ",
      "      e        C",
      "               C",
      "CCCCCCCCCCCCCCCC",
      "                ",
      "                ",
      "                ",
      "                ",
      "                ",
      "      D         ",
      "    fffff       ",
      "    f x         "
    ],
    [
      "aaaaEEEEEaEEEEEa",
      "cdcccdccdcddccdc",
      "                ",
      "                ",
      "                ",
      "      e         ",
      "                ",
      "                ",
      "                ",
      "                ",
      "                ",
      "                ",
      "                ",
      "                ",
      "    fffff       ",
      "    f x         "
    ],
    [
      "aaaaaaEEaaaaEEaa",
      "cdcccdccdcddccdc",
      "                ",
      "                ",
      "                ",
      "      e         ",
      "      F         ",
      "                ",
      "                ",
      "                ",
      "                ",
      "                ",
      "                ",
      "                ",
      "    fffff       ",
      "    f!x         "
    ]
  ]
}