{
  "name": "multi_terraceplaza_7_base1",
  "refpalette": "deceasedcraft:multi_terraceplaza_7/multi_terraceplaza_7_base1_palette",
  "xsize": 16,
  "zsize": 16,
  "slices": [
    [
      "vvvvvvvvvvvvvvvv",
      "aaaaaaaaaaaaaaaa",
      "bbbbbbbbbbbbbbbb",
      "bbbbbbbbbbbbbbbb",
      "HHHHHHHHHHHHHHHH",
      "HHHHHHcHHHHHHHHH",
      "HHHHHHHHHHHHHHHH",
      "HHHHHHHHHHHHHHHH",
      "HHHHHHHHHHHHHHHH",
      "HHHHHHHHHHHHHHHH",
      "HHHHHHHHHHHHHHHH",
      "HHHHHHHHHHHHHHHH",
      "HHHHHHHHHHHHHHHH",
      "HHHHHHHHHHHHHHHH",
      "HHHHHHHHHHHHHHHH",
      "HHHHHHHHHHHHHHHH"
    ],
    [
      "vvvvvvvvvvvvvvvv",
      "aaaaaaaaaaaaaaaa",
      "                ",
      "                ",
      "dededefdedededeg",
      "      c        g",
      "      f     h  g",
      "ijijij ijijijijg",
      "               g",
      "               g",
      "               g",
      "               g",
      "dedede dedededeg",
      "      f        g",
      "      f   k    g",
      "ijijijfijijijijg"
    ],
    [
      "vvvvvvvvvvvvvvvv",
      "aaaaaaaaaaaaaaaa",
      "                ",
      "                ",
      "                ",
      "      c         ",
      "                ",
      "                ",
      "                ",
      "                ",
      "                ",
      "                ",
      "                ",
      "                ",
      "                ",
      "                "
    ],
    [
      "vvvvvvvvvvvvvvvv",
      "aaaaaaaaaaaaaaaa",
      "                ",
      "                ",
      "                ",
      "      c         ",
      "                ",
      "                ",
      "                ",
      "                ",
      "                ",
      "                ",
      "                ",
      "                ",
      "                ",
      "                "
    ],
    [
      "vvvvvvvvvvvvvvvv",
      "aaaaaaaaaaaaaaaa",
      "llllllmlllllllll",
      "nnnnnnnnnnnnnnnn",
      "nnnnnnnnnnnnnnnn",
      "nnnnnncnnnnnnnnn",
      "                ",
      "                ",
      "         o    o ",
      "                ",
      "                ",
      "                ",
      "                ",
      "   o     o      ",
      "                ",
      "                "
    ],
    [
      "vvvvvvvvvvvvvvvv",
      "aaaaaaaaaaaaaaaa",
      "ppppppqppppppppp",
      "rrrrrrqrrrrrrrrr",
      "rrr rrqrr rrrr!r",
      "qqqqqqcqqqqqqqqq",
      "pppppppppppppppp",
      "pppppppppppppppp",
      "pppspppppsppppsp",
      "pppppppppppppppp",
      "pppppppppppppppp",
      "pppppppppppppppp",
      "pppppppppppppppp",
      "pppspppppsppppsp",
      "pppppppppppppppp",
      "pppppppppppppppp"
    ]
  ]
}