{
  "name": "multi_terraceplaza_7_ground",
  "refpalette": "deceasedcraft:multi_terraceplaza_7/multi_terraceplaza_7_ground_palette",
  "xsize": 16,
  "zsize": 16,
  "slices": [
    [
      "aaaaaaaaaaaaaaaa",
      "aaaaaaaaaaaaaaaa",
      "bbbbbbbbbbbbbbbb",
      "cccccccccccccccc",
      "cccdcccccdccccec",
      "ccccccfccccccccc",
      "bbbbbbbbbbbbbbbb",
      "gggggggggggggggg",
      "HHHHHHHHHHHHHHHH",
      "HHHHHHHHHHHHHHHH",
      "HHHHHHHHHHHHHHHH",
      "HHHHHHHHHHHHHHHH",
      "HHHHHHHHHHHHHHHH",
      "gggggggggggggggg",
      "ghhhhhhhhhhhhhaa",
      "hhhhhhhhhhhhhhha"
    ],
    [
      "                ",
      "                ",
      "                ",
      "                ",
      "   i     i    i ",
      "      f         ",
      "                ",
      "                ",
      "                ",
      "                ",
      "j    j    j    j",
      "                ",
      "                ",
      "                ",
      " kkkkkkkkkkkkk  ",
      "kkll llll ll kk "
    ],
    [
      "                ",
      "                ",
      "                ",
      "                ",
      "                ",
      "      f         ",
      "                ",
      "                ",
      "                ",
      "                ",
      "                ",
      "                ",
      "                ",
      "                ",
      "                ",
      "  mm mmmm mm    "
    ],
    [
      "                ",
      "                ",
      "                ",
      "                ",
      "                ",
      "      f         ",
      "                ",
      "                ",
      "                ",
      "                ",
      "                ",
      "                ",
      "                ",
      "                ",
      "                ",
      "                "
    ],
    [
      "                ",
      "                ",
      "                ",
      "                ",
      "                ",
      "      f         ",
      "                ",
      "                ",
      "                ",
      "                ",
      "                ",
      "                ",
      "                ",
      "                ",
      "                ",
      "                "
    ],
    [
      "                ",
      "                ",
      "                ",
      "                ",
      "                ",
      "      f         ",
      "                ",
      "                ",
      "                ",
      "                ",
      "                ",
      "                ",
      "                ",
      "                ",
      "                ",
      "                "
    ]
  ]
}