{
  "name": "multi_terraceplaza_7part2_floor3",
  "refpalette": "deceasedcraft:multi_terraceplaza_7/multi_terraceplaza_7part2_floor3_palette",
  "xsize": 16,
  "zsize": 16,
  "slices": [
    [
      "aaaaaaaaaaabaaba",
      "                ",
      "                ",
      "                ",
      "                ",
      "               c",
      "               c",
      "cccccccccccccccc",
      "                ",
      "                ",
      "                ",
      "                ",
      "                ",
      "                ",
      "    ccccc       ",
      "    c           "
    ],
    [
      "aaaaaaaaaaabaaba",
      "                ",
      "                ",
      "                ",
      "                ",
      "               c",
      "               c",
      "cccccccccccccccc",
      "                ",
      "                ",
      "                ",
      "                ",
      "                ",
      "                ",
      "    ccccc       ",
      "    c           "
    ],
    [
      "aaaaaaaaaaaaaaaa",
      "                ",
      "                ",
      "                ",
      "                ",
      "               c",
      "               c",
      "cccccccccccccccc",
      "                ",
      "                ",
      "                ",
      "                ",
      "                ",
      "      d         ",
      "    ccccc       ",
      "    c           "
    ],
    [
      "aaaaaaaaaaaaaaaa",
      "                ",
      "                ",
      "                ",
      "                ",
      "               e",
      "               e",
      "eeeeeeeeeeeeeeee",
      "                ",
      "                ",
      "                ",
      "                ",
      "                ",
      "                ",
      "    ccccc       ",
      "    c           "
    ],
    [
      "aaaafffffafffffa",
      "                ",
      "                ",
      "                ",
      "                ",
      "                ",
      "                ",
      "                ",
      "                ",
      "                ",
      "                ",
      "                ",
      "                ",
      "                ",
      "    ccccc       ",
      "    c           "
    ],
    [
      "aaaaaaffaaaaffaa",
      "                ",
      "                ",
      "                ",
      "                ",
      "                ",
      "                ",
      "                ",
      "                ",
      "                ",
      "                ",
      "                ",
      "                ",
      "                ",
      "    ccccc       ",
      "    c           "
    ]
  ]
}