{
  "name": "multi_terraceplaza_7_floor5",
  "refpalette": "deceasedcraft:multi_terraceplaza_7/multi_terraceplaza_7_floor5_palette",
  "xsize": 16,
  "zsize": 16,
  "slices": [
    [
      "aaaaaaaaaaaaaaaa",
      "bcbbbcbbcbccbbcb",
      "                ",
      "                ",
      "                ",
      "      d         ",
      "                ",
      "                ",
      "                ",
      "                ",
      "                ",
      "                ",
      "                ",
      "                ",
      "                ",
      "                "
    ],
    [
      "aaaaaaaaaaaaaaaa",
      "bcbbbcbbcbccbbcb",
      "eeeeeeeeeeeeeeee",
      "eeeeeeeeeeeeeeee",
      "ffffffffffffffff",
      "ggggggdggggggggg",
      "hhhhhhhhhhhhhhhh",
      "                ",
      "                ",
      "hhhhhhhhhhhhhhhh",
      "hhhhhhhhhhhhhhhh",
      "hhhhhhhhhhhhhhhh",
      "hhhhhhhhhhhhhhhh",
      "                ",
      "                ",
      "hhhhhhhhhhhhhhhh"
    ],
    [
      "aaaaaaaaaaaaaaaa",
      "bcbbbcbbcbccbbcb",
      "                ",
      "                ",
      "iiiiiiiiiiiiiiii",
      "iiiiiiiiiiiiiiii",
      "iiiiiiiiiiiiiiii",
      "@@@@@@@@@@@@@@@@",
      "@@@@@@@@@@@@@@@@",
      "iiiiiiiiiiiiiiii",
      "iiiiiiiiiiiiiiii",
      "iiiiiiiiiiiiiiii",
      "iiiiiiiiiiiiiiii",
      "@@@@@@@@@@@@@@@@",
      "@@@@@@@@@@@@@@@@",
      "iiiiiiiiiiiiiiii"
    ],
    [
      "aaaaaaaaaaaaaaaa",
      "bcbbbcbbcbccbbcb",
      "                ",
      "                ",
      "                ",
      "                ",
      "                ",
      "                ",
      "                ",
      "                ",
      "                ",
      "                ",
      "                ",
      "                ",
      "                ",
      "                "
    ],
    [
      "                ",
      "                ",
      "                ",
      "                ",
      "                ",
      "                ",
      "                ",
      "                ",
      "                ",
      "                ",
      "                ",
      "                ",
      "                ",
      "                ",
      "                ",
      "                "
    ],
    [
      "                ",
      "                ",
      "                ",
      "                ",
      "                ",
      "                ",
      "                ",
      "                ",
      "                ",
      "                ",
      "                ",
      "                ",
      "                ",
      "                ",
      "                ",
      "                "
    ]
  ]
}