{
  "name": "multi_terraceplaza_7_floor4",
  "refpalette": "deceasedcraft:multi_terraceplaza_7/multi_terraceplaza_7_floor4_palette",
  "xsize": 16,
  "zsize": 16,
  "slices": [
    [
      "aaaabbbbaaaabbab",
      "cdcccdccdcddccdc",
      "                ",
      "                ",
      "                ",
      "      e         ",
      "                ",
      "                ",
      "                ",
      "                ",
      "                ",
      "                ",
      "                ",
      "ffffffffffffffff",
      "ffffffffffffffff",
      "fffffgggffffffff"
    ],
    [
      "aaaaabbaaaabbaab",
      "cdcccdccdcddccdc",
      "                ",
      "                ",
      "                ",
      "      e         ",
      "                ",
      "                ",
      "                ",
      "                ",
      "                ",
      "                ",
      "                ",
      "hhhhhhhhhhhhhhhh",
      "                ",
      "                "
    ],
    [
      "aabbbbbabbbbbaaa",
      "cdcccdccdcddccdc",
      "                ",
      "                ",
      "                ",
      "      e         ",
      "                ",
      "                ",
      "                ",
      "                ",
      "                ",
      "                ",
      "                ",
      "                ",
      "                ",
      "                "
    ],
    [
      "aaaaaaaaaaaaaaaa",
      "cdcccdccdcddccdc",
      "                ",
      "                ",
      "                ",
      "      e         ",
      "                ",
      "                ",
      "                ",
      "                ",
      "                ",
      "                ",
      "                ",
      "                ",
      "                ",
      "                "
    ],
    [
      "aaaaaaaaaaaaaaaa",
      "cdcccdccdcddccdc",
      "                ",
      "                ",
      "                ",
      "      e         ",
      "                ",
      "                ",
      "                ",
      "                ",
      "                ",
      "                ",
      "                ",
      "                ",
      "                ",
      "                "
    ],
    [
      "aaaaaaaaaaaaaaaa",
      "cdcccdccdcddccdc",
      "                ",
      "                ",
      "                ",
      "      e         ",
      "                ",
      "                ",
      "                ",
      "                ",
      "                ",
      "                ",
      "                ",
      "                ",
      "                ",
      "                "
    ]
  ]
}