{
  "name": "multi_terraceplaza_7_base2",
  "refpalette": "deceasedcraft:multi_terraceplaza_7/multi_terraceplaza_7_base2_palette",
  "xsize": 16,
  "zsize": 16,
  "slices": [
    [
      "vvvvvvvvvvvvvvvv",
      "aaaaaaaaaaaaaaaa",
      "bbbbbbbbbbbbbbbb",
      "bbbbbbbbbbbbbbbb",
      "HHHHHHHHHHHHHHHH",
      "HHHHHHcHHHHHHHHH",
      "HHHHHHHHHHHHHHHH",
      "HHHHHHHHHHHHHHHH",
      "HHHHHHHHHHHHHHHH",
      "HHHHHHHHHHHHHHHH",
      "HHHHHHHHHHHHHHHH",
      "HHHHHHHHHHHHHHHH",
      "HHHHHHHHHHHHHHHH",
      "HHHHHHHHHHHHHHHH",
      "HHHHHHHHHHHHHHHH",
      "HHHHHHHHHHHHHHHH"
    ],
    [
      "vvvvvvvvvvvvvvvv",
      "aaaaaaaaaaaaaaaa",
      "                ",
      "                ",
      "dededefdedededeg",
      "      c        g",
      " h    f        g",
      "ijijij ijijijijg",
      "               g",
      "               g",
      "               g",
      "               g",
      "dedede dedededeg",
      "      f        g",
      "   k  f   l    g",
      "ijijijfijijijijg"
    ],
    [
      "vvvvvvvvvvvvvvvv",
      "aaaaaaaaaaaaaaaa",
      "                ",
      "                ",
      "                ",
      "      c         ",
      "                ",
      "                ",
      "                ",
      "                ",
      "                ",
      "                ",
      "                ",
      "                ",
      "                ",
      "                "
    ],
    [
      "vvvvvvvvvvvvvvvv",
      "aaaaaaaaaaaaaaaa",
      "                ",
      "                ",
      "                ",
      "      c         ",
      "                ",
      "                ",
      "                ",
      "                ",
      "                ",
      "                ",
      "                ",
      "                ",
      "                ",
      "                "
    ],
    [
      "vvvvvvvvvvvvvvvv",
      "aaaaaaaaaaaaaaaa",
      "mmmmmmmmmmmmmmmm",
      "nnnnnnnnnnnnnnnn",
      "nnnnnnnnnnnnnnnn",
      "nnnnnncnnnnnnnnn",
      "                ",
      "                ",
      "   o            ",
      "                ",
      "                ",
      "                ",
      "                ",
      "                ",
      "                ",
      "                "
    ],
    [
      "vvvvvvvvvvvvvvvv",
      "aaaaaaaaaaaaaaaa",
      "pppppppppppppppp",
      "pppppppppppppppp",
      "pppppppppppppppp",
      "qqqqqqcqqqqqqqqq",
      "pppppppppppppppp",
      "pppppppppppppppp",
      "ppprppppprpppprp",
      "pppppppppppppppp",
      "pppppppppppppppp",
      "pppppppppppppppp",
      "pppppppppppppppp",
      "ppprppppprpppprp",
      "pppppppppppppppp",
      "pppppppppppppppp"
    ]
  ]
}