{
  "name": "multi_terraceplaza_7_floor2",
  "refpalette": "deceasedcraft:multi_terraceplaza_7/multi_terraceplaza_7_floor2_palette",
  "xsize": 16,
  "zsize": 16,
  "slices": [
    [
      "                ",
      "                ",
      "                ",
      "                ",
      "                ",
      "      a         ",
      "                ",
      "                ",
      "                ",
      "                ",
      "                ",
      "                ",
      "                ",
      "                ",
      "                ",
      "                "
    ],
    [
      "                ",
      "                ",
      "                ",
      "                ",
      "                ",
      "bbbbbbabbbbbbbbb",
      "     cdc        ",
      "     cdc        ",
      "     cdc        ",
      "     cdc        ",
      "     cdc        ",
      "     cdc        ",
      "     cdc        ",
      "     cdc        ",
      "     cdc        ",
      "     cdc        "
    ],
    [
      "                ",
      "eeeeeeeeeeeeeeee",
      "                ",
      "                ",
      "      f         ",
      "ggggggaggggggggg",
      "hhhhhcichhhhhhhh",
      "jjjjklilkjjjjjjk",
      "mmmmklilkmmmmmmk",
      "mmmmklilkmmmmmmk",
      "mmmmklilkmmmmmmk",
      "mmmmklilkmmmmmmk",
      "mmmmklilkmmmmmmk",
      "mmmmklilkmmmmmmk",
      "nnnnklilknnnnnnk",
      "ooooocicoooooooo"
    ],
    [
      "pppppppppppppppp",
      "qrqqqrqqrqrrqqrq",
      "sssssstsssssssss",
      "sssssstsssssssss",
      "ccccccuccccccccc",
      "wwwwwwawwwwwwwww",
      "xxxxxxwxxxxxxxxx",
      "xxxxxxwxxxxxxxxx",
      "xxxxxxwxxxxxxxxx",
      "xxxxxxwxxxxxxxxx",
      "xxxxxxwxxxxxxxxx",
      "xxxxxxwxxxxxxxxx",
      "xxxxxxwxxxxxxxxx",
      "xxxxxxwxxxxxxxxx",
      "xxxxxxwxxxxxxxxx",
      "xxxxxxwxxxxxxxxx"
    ],
    [
      "pppppppppppppppp",
      "qrqqqrqqrqrrqqrq",
      "yyyyyyyyyyyyyyyy",
      "yyyyyyyyyyyyyyyy",
      "yyyyyyyyyyyyyyyy",
      "yyyyyyayyyyyyyyy",
      "yyyyyyyyyyyyyyyy",
      "yyyyyyyyyyyyyyyy",
      "yyyyyyyyyyyyyyyy",
      "yyyyyyyyyyyyyyyy",
      "yyyyyyyyyyyyyyyy",
      "yyyyyyyyyyyyyyyy",
      "yyyyyyyyyyyyyyyy",
      "yyyyyyyyyyyyyyyy",
      "AAAAyyyyyyyyyyyy",
      "AAAAyyyyyyyyyyyy"
    ],
    [
      "ppppppppppBBpBBp",
      "qrqqqrqqrqrrqqrq",
      "                ",
      "                ",
      "                ",
      "      a        C",
      "DEFFEI!JKLMMNOOC",
      "CCCCCCCCCCCCCCCC",
      "PPP QRS  T  UVU ",
      "WXY  Z  012 U3U ",
      "444 QRS  5      ",
      "                ",
      "                ",
      "                ",
      "   6CCCCC       ",
      " 78 C9#         "
    ]
  ]
}