{
  "xsize": 16,
  "zsize": 16,
  "refpalette": "lce2:black_building",
  "slices": [
    [
      "################",
      "#              #",
      "#              #",
      "#              #",
      "#  o        o  #",
      "#              #",
      "#              #",
      "#              #",
      "#              #",
      "#              #",
      "#              #",
      "#  o        o  #",
      "#              #",
      "#              #",
      "#              #",
      "################"
    ],
    [
      "################",
      "#              #",
      "#              #",
      "#              #",
      "#  o        o  #",
      "#              #",
      "#              #",
      "#              #",
      "#              #",
      "#              #",
      "#              #",
      "#  o        o  #",
      "#              #",
      "#              #",
      "#              #",
      "################"
    ],
    [
      "################",
      "#              #",
      "#              #",
      "#              #",
      "#  o        o  #",
      "#              #",
      "#              #",
      "#              #",
      "#              #",
      "#              #",
      "#              #",
      "#  o        o  #",
      "#              #",
      "#              #",
      "#              #",
      "################"
    ],
    [
      "################",
      "#              #",
      "#              #",
      "#              #",
      "#  o        o  #",
      "#              #",
      "#              #",
      "#              #",
      "#              #",
      "#              #",
      "#              #",
      "#  o        o  #",
      "#              #",
      "#              #",
      "#              #",
      "################"
    ],
    [
      "################",
      "################",
      "################",
      "################",
      "################",
      "################",
      "################",
      "################",
      "################",
      "################",
      "################",
      "################",
      "################",
      "################",
      "################",
      "################"
    ]
  ]
}