{
  "name": "multi_workshop_0_floor3",
  "refpalette": "deceasedcraft:multi_workshop_0/multi_workshop_0_floor3_palette",
  "xsize": 16,
  "zsize": 16,
  "slices": [
    [
      "                ",
      "                ",
      "                ",
      "                ",
      "                ",
      "    aabaaabaaab ",
      "   cc deeef fda ",
      "  cc  de e g da ",
      " ac   de e   da ",
      " ah   deeef fda ",
      " adddddddddddda ",
      " adddddddddddda ",
      " adddddddddddda ",
      " adddddddddddda ",
      " adddddddddddda ",
      " adddddddddddda "
    ],
    [
      "                ",
      "                ",
      "                ",
      "                ",
      "                ",
      "    aabaaabaaab ",
      "   iij    k k a ",
      "  ii j        i ",
      " ai  j       li ",
      " ah  j    k k i ",
      " a mmm l    n i ",
      " ao           i ",
      " ap           i ",
      " aq       r   i ",
      " aq           i ",
      " ap r s       i "
    ],
    [
      "                ",
      "                ",
      "                ",
      "                ",
      "                ",
      "    aabaaabaaab ",
      "   ii t   uuuwa ",
      "  ii      u u i ",
      " ai       u u i ",
      " ah       uuu i ",
      " b        xy  i ",
      " i            i ",
      " i            i ",
      " i            i ",
      " i            i ",
      " iA           i "
    ],
    [
      "                ",
      "                ",
      "                ",
      "                ",
      "                ",
      "    aabaaabaaab ",
      "   ii    BCDCEa ",
      "  ii      FIJ i ",
      " ai       FKJ i ",
      " ah      BCLCEi ",
      " a            i ",
      " a            i ",
      " a            i ",
      " a            i ",
      " a            i ",
      " a            i "
    ],
    [
      "                ",
      "                ",
      "                ",
      "                ",
      "                ",
      "    aabaaabaaab ",
      "   ii      M  a ",
      "  ii      N N O ",
      " ai       N N O ",
      " ah        N  O ",
      " a            O ",
      " a            O ",
      " a            O ",
      " a            O ",
      " a            O ",
      " a            O "
    ],
    [
      "                ",
      "                ",
      "                ",
      "                ",
      "                ",
      "    aabaaabaaab ",
      "   ii  PPPPPPPa ",
      "  ii   PPPPPPPa ",
      " ai    PPPPPPPa ",
      " ah    PPPPPPPa ",
      " a     PPPPPPPa ",
      " aPPPPPPPPPPPPa ",
      " aPPPPPPPPPPPPa ",
      " aPPPPPPPPPPPPa ",
      " aPPPPPPPPPPPPa ",
      " aPPPPPPPPPPPPa "
    ]
  ]
}