{
  "name": "multi_workshop_0_base1",
  "refpalette": "deceasedcraft:multi_workshop_0/multi_workshop_0_base1_palette",
  "xsize": 16,
  "zsize": 16,
  "slices": [
    [
      "vvvvvvvvvvvvvvvv",
      "vaaaaaaaaaaaaaav",
      "va            av",
      "va            av",
      "va            av",
      "va            av",
      "va            av",
      "va            av",
      "va            av",
      "va            av",
      "va            av",
      "va            av",
      "vabbbbbbbbbbbbav",
      "va            av",
      "va            av",
      "va            av"
    ],
    [
      "vvvvvvvvvvvvvvvv",
      "vaaaaaaaaaaaaaav",
      "va            av",
      "va            av",
      "va            av",
      "va            av",
      "va            av",
      "va            av",
      "va            av",
      "va            av",
      "va            av",
      "va            av",
      "vaccccccccccccav",
      "va            av",
      "va            av",
      "va            av"
    ],
    [
      "vvvvvvvvvvvvvvvv",
      "vaaaaaaaaaaaaaav",
      "va            av",
      "va            av",
      "va            av",
      "va            av",
      "va            av",
      "va            av",
      "va            av",
      "va            av",
      "va            av",
      "va            av",
      "vabbbbbbbbbbbbav",
      "va            av",
      "va            av",
      "va            av"
    ],
    [
      "vvvvvvvvvvvvvvvv",
      "vaaaaaaaaaaaaaav",
      "va            av",
      "va            av",
      "va            av",
      "va            av",
      "va            av",
      "va            av",
      "va            av",
      "va            av",
      "va            av",
      "va            av",
      "vabbbbbbbbbbbbav",
      "va            av",
      "va            av",
      "va            av"
    ],
    [
      "vvvvvvvvvvvvvvvv",
      "vaaaaaaaaaaaaaav",
      "va            av",
      "va dddddddddd av",
      "va d        d av",
      "va d        d av",
      "va d        d av",
      "va d        d av",
      "va d        d av",
      "va d        d av",
      "va dddddddddd av",
      "va            av",
      "vaaaaaaaaaaaaaav",
      "vaeeeeeeeeeeeeav",
      "vaeffeeffeeffeav",
      "vaeggeeffeeffeav"
    ],
    [
      "vvvvvvvvvvvvvvvv",
      "vaaaaaaaaaaaaaav",
      "vahhhhhhhhhhhhav",
      "vahiiiiiiiiiihav",
      "vahiiiiiiiiiihav",
      "vahiiiiiiiiiihav",
      "vahiiiiiiiiiihav",
      "vahiiiiiiiiiihav",
      "vahiiiiiiiiiihav",
      "vahiiiiiiiiiihav",
      "vahiiiiiiiiiihav",
      "vahhhhhhhhhhhhav",
      "vaaaaaaaaaaaaaav",
      "vaeeeeeeeeeeeeav",
      "vaeeeeeeeeeeeeav",
      "vaeeeeeeeeeeeeav"
    ]
  ]
}