{
  "name": "multi_workshop_0_base2",
  "refpalette": "deceasedcraft:multi_workshop_0/multi_workshop_0_base2_palette",
  "xsize": 16,
  "zsize": 16,
  "slices": [
    [
      "vvvvvvvvvvvvvvvv",
      "vaaaaaaaaaaaaaav",
      "vaaaaaaaaaaaaaav",
      "vaaaaaaaaaaaaaav",
      "vaaaaaaaaaaaaaav",
      "vaaaaaaaaaaaaaav",
      "vaaaaaaaaaaaaaav",
      "vaaaaaaaaaaaaaav",
      "vaaaaaaaaaaaaaav",
      "vaaaaaaaaaaaaaav",
      "vaaaaaaaaaaaaaav",
      "vaaaaaaaaaaaaaav",
      "vaaaaaaaaaaaaaav",
      "vaaaaaaaaaaaaaav",
      "vaaaaaaaaaaaaaav",
      "vaaaaaaaaaaaaaav"
    ],
    [
      "vvvvvvvvvvvvvvvv",
      "vaaaaaaaaaaaaaav",
      "vaaaaaaaaaaaaaav",
      "vaaaaaaaaaaaaaav",
      "vaaaaaaaaaaaaaav",
      "vaaaaaaaaaaaaaav",
      "vaaaaaaaaaaaaaav",
      "vaaaaaaaaaaaaaav",
      "vaaaaaaaaaaaaaav",
      "vaaaaaaaaaaaaaav",
      "vaaaaaaaaaaaaaav",
      "vaaaaaaaaaaaaaav",
      "vaaaaaaaaaaaaaav",
      "vaaaaaaaaaaaaaav",
      "vaaaaaaaaaaaaaav",
      "vaaaaaaaaaaaaaav"
    ],
    [
      "vvvvvvvvvvvvvvvv",
      "vbbbbbbbbbbbbbbv",
      "vbccccccccccccbv",
      "vbcddddddddddcbv",
      "vbcddddddddddcbv",
      "vbcddddddddddcbv",
      "vbcddddddddddcbv",
      "vbcddddddddddcbv",
      "vbcddddddddddcbv",
      "vbcddddddddddcbv",
      "vbcddddddddddcbv",
      "vbccccccccccccbv",
      "vbbbbbbbbbbbbbbv",
      "vbeeeeeefffffebv",
      "vbeeeeeefffffebv",
      "vbeeeeeefffffebv"
    ],
    [
      "vvvvvvvvvvvvvvvv",
      "vbbbbbbbbbbbbbbv",
      "vb            bv",
      "vb            bv",
      "vb  ghi  jkl  bv",
      "vb mn!nopnqnr bv",
      "vb  sts  kuk  bv",
      "vb  sws  kxk  bv",
      "vb mnhnopnynr bv",
      "vb  ABA  k=k  bv",
      "vb       CDC  bv",
      "vb            bv",
      "vbEFEEEEEEEEEEbv",
      "vb            bv",
      "vb       III Jbv",
      "vb       III Kbv"
    ],
    [
      "vvvvvvvvvvvvvvvv",
      "vbbbbbbbbbbbbbbv",
      "vb            bv",
      "vb            bv",
      "vb  LMN  OPO  bv",
      "vb  QRQ  STS  bv",
      "vb  Q Q  T T  bv",
      "vb   U   TTT  bv",
      "vb  VWV  XYX  bv",
      "vb       XZX  bv",
      "vb            bv",
      "vb            bv",
      "vbE0EEEEEEEEEEbv",
      "vb            bv",
      "vb            bv",
      "vb            bv"
    ],
    [
      "vvvvvvvvvvvvvvvv",
      "vbbbbbbbbbbbbbbv",
      "vb            bv",
      "vb            bv",
      "vb       YYY  bv",
      "vb        Z   bv",
      "vb       XYX  bv",
      "vb       XZX  bv",
      "vb            bv",
      "vb            bv",
      "vb            bv",
      "vb            bv",
      "vbEEEEEEEEEEEEbv",
      "vb            bv",
      "vb            bv",
      "vb            bv"
    ]
  ]
}