{
  "name": "multi_workshop_0_floor1",
  "refpalette": "deceasedcraft:multi_workshop_0/multi_workshop_0_floor1_palette",
  "xsize": 16,
  "zsize": 16,
  "slices": [
    [
      "                ",
      "                ",
      "                ",
      "                ",
      "                ",
      "    aabaaabaaab ",
      "   cc defegggda ",
      "  cc  dh hg gda ",
      " ac   di ig gda ",
      " aj   de egggda ",
      " adddddddddddda ",
      " adddddddddddda ",
      " adddddddddddda ",
      " adddddddddddda ",
      " adddddddddddda ",
      " adddddddddddda "
    ],
    [
      "                ",
      "                ",
      "                ",
      "                ",
      "                ",
      "    aabaaabaaab ",
      "   kkl m m   na ",
      "  kk l        k ",
      " ak  l        k ",
      " aj  l m m    k ",
      " a ooo p   p  k ",
      " aq      r   pk ",
      " as           k ",
      " at          uk ",
      " at           k ",
      " as  w        k "
    ],
    [
      "                ",
      "                ",
      "                ",
      "                ",
      "                ",
      "    aabaaabaaab ",
      "   kk xyyy   Aa ",
      "  kk   y y    k ",
      " ak    y y    k ",
      " aj    yyy    k ",
      " b            k ",
      " k            k ",
      " kB           k ",
      " k            k ",
      " k            k ",
      " k            k "
    ],
    [
      "                ",
      "                ",
      "                ",
      "                ",
      "                ",
      "    aabaaabaaab ",
      "   kk         a ",
      "  kk          k ",
      " ak           k ",
      " aj           k ",
      " a            k ",
      " a            k ",
      " a            k ",
      " a            k ",
      " a            k ",
      " a            k "
    ],
    [
      "                ",
      "                ",
      "                ",
      "                ",
      "                ",
      "    aabaaabaaab ",
      "   kk         a ",
      "  kk          C ",
      " ak           C ",
      " aj           C ",
      " a            C ",
      " a            C ",
      " a            C ",
      " a            C ",
      " a            C ",
      " a            C "
    ],
    [
      "                ",
      "                ",
      "                ",
      "                ",
      "                ",
      "    aabaaabaaab ",
      "   kk  DDDDDDDa ",
      "  kk   DDDDDDDa ",
      " ak    DDDDDDDa ",
      " aj    DDDDDDDa ",
      " a     DDDDDDDa ",
      " aDDDDDDDDDDDDa ",
      " aDDDDDDDDDDDDa ",
      " aDDDDDDDDDDDDa ",
      " aDDDDDDDDDDDDa ",
      " aDDDDDDDDDDDDa "
    ]
  ]
}