{
  "name": "multi_workshop_0_floor2",
  "refpalette": "deceasedcraft:multi_workshop_0/multi_workshop_0_floor2_palette",
  "xsize": 16,
  "zsize": 16,
  "slices": [
    [
      "                ",
      "                ",
      "                ",
      "                ",
      "                ",
      "    aabaaabaaab ",
      "   cc deeefffda ",
      "  cc  de efgfda ",
      " ac   de ef fda ",
      " ah   deeefffda ",
      " adddddddddddda ",
      " adddddddddddda ",
      " adddddddddddda ",
      " adddddddddddda ",
      " adddddddddddda ",
      " adddddddddddda "
    ],
    [
      "                ",
      "                ",
      "                ",
      "                ",
      "                ",
      "    aabaaabaaab ",
      "   iijkl!lm  na ",
      "  ii j opo    i ",
      " ai  j opo    i ",
      " ah  jqrolm   i ",
      " a sss       ti ",
      " au    w      i ",
      " ax           i ",
      " ay           i ",
      " ay AB        i ",
      " axC D    w   i "
    ],
    [
      "                ",
      "                ",
      "                ",
      "                ",
      "                ",
      "    aabaaabaaab ",
      "   ii EFIF   Ea ",
      "  ii   J K    i ",
      " ai           i ",
      " ah    KFJ    i ",
      " b      L     i ",
      " i            i ",
      " iM           i ",
      " i            i ",
      " i            i ",
      " iN           i "
    ],
    [
      "                ",
      "                ",
      "                ",
      "                ",
      "                ",
      "    aabaaabaaab ",
      "   ii  O O    a ",
      "  ii   P P    i ",
      " ai    P P    i ",
      " ah    PPP    i ",
      " a            i ",
      " a            i ",
      " a            i ",
      " a            i ",
      " a            i ",
      " a            i "
    ],
    [
      "                ",
      "                ",
      "                ",
      "                ",
      "                ",
      "    aabaaabaaab ",
      "   ii         a ",
      "  ii          Q ",
      " ai           Q ",
      " ah           Q ",
      " a            Q ",
      " a            Q ",
      " a            Q ",
      " a            Q ",
      " a            Q ",
      " a            Q "
    ],
    [
      "                ",
      "                ",
      "                ",
      "                ",
      "                ",
      "    aabaaabaaab ",
      "   ii  RRRRRRRa ",
      "  ii   RRRRRRRa ",
      " ai    RRRRRRRa ",
      " ah    RRRRRRRa ",
      " a     RRRRRRRa ",
      " aRRRRRRRRRRRRa ",
      " aRRRRRRRRRRRRa ",
      " aRRRRRRRRRRRRa ",
      " aRRRRRRRRRRRRa ",
      " aRRRRRRRRRRRRa "
    ]
  ]
}