{
  "name": "multi_workshop_0_ground",
  "refpalette": "deceasedcraft:multi_workshop_0/multi_workshop_0_ground_palette",
  "xsize": 16,
  "zsize": 16,
  "slices": [
    [
      "aaaaaaaaaaaaaaaa",
      "aaaabaaabaaabaaa",
      "aaaaaaaaaaaaaaaa",
      "aaaaaaaaaaaaaaaa",
      "aaaaaaaaaaaaaaaa",
      "aaaaccdcccdcccdd",
      "aaaeeeeeeeeeeecd",
      "aaeefffffffffe=d",
      "aceffgggfgggfe=d",
      "aceffgggfgggfe=d",
      "aceffgggfg!gfe=d",
      "aceffgggfgggfe=d",
      "aheffffffffffe=d",
      "aceffffffffffe=d",
      "aceffffffffffe=d",
      "aceffffffffffe=d"
    ],
    [
      "                ",
      "  iijiiijiiijii ",
      " kkkk kkk k kk  ",
      "                ",
      "                ",
      "    ccdcccdcccdl",
      "   mm no  p   cl",
      "  mm          ml",
      " cm  q r q r  ml",
      " cs           ml",
      " c            ml",
      " c   t u t u  ml",
      " c            ml",
      " c            ml",
      " c            ml",
      " c            ml"
    ],
    [
      "                ",
      "    w   w   w   ",
      "                ",
      "                ",
      "                ",
      "    ccdcccdcccd ",
      "   mm x   y   c ",
      "  mm          m ",
      " cm           m ",
      " cs           m ",
      " d            m ",
      " m            m ",
      " m            m ",
      " m            m ",
      " m            m ",
      " m            m "
    ],
    [
      "                ",
      "    i   i   i   ",
      "                ",
      "                ",
      "                ",
      "    ccdcccdcccd ",
      "   mm         c ",
      "  mm          m ",
      " cm           m ",
      " cs           m ",
      " c            m ",
      " c            m ",
      " c            m ",
      " c            m ",
      " c            m ",
      " c            m "
    ],
    [
      "                ",
      "    i   i   i   ",
      "                ",
      "                ",
      "                ",
      "    ccdcccdcccd ",
      "   mm         c ",
      "  mm          l ",
      " cm           l ",
      " cs           l ",
      " c            l ",
      " c            l ",
      " c            l ",
      " c            l ",
      " c            l ",
      " c            l "
    ],
    [
      "                ",
      "    A   A   A   ",
      "                ",
      "                ",
      "                ",
      "    ccdcccdcccd ",
      "   mm  BBBBBBBc ",
      "  mm   BBBBBBBc ",
      " cm    BBBBBBBc ",
      " cs    BBBBBBBc ",
      " c     BBBBBBBc ",
      " cBBBBBBBBBBBBc ",
      " cBBBBBBBBBBBBc ",
      " cBBBBBBBBBBBBc ",
      " cBBBBBBBBBBBBc ",
      " cBBBBBBBBBBBBc "
    ]
  ]
}