{
  "name": "multi_workshop_0_top",
  "refpalette": "deceasedcraft:multi_workshop_0/multi_workshop_0_top_palette",
  "xsize": 16,
  "zsize": 16,
  "slices": [
    [
      "                ",
      "                ",
      "                ",
      "                ",
      "                ",
      "    aabaaabaaab ",
      "   cc dddddddda ",
      "  cc  dddddddda ",
      " ac   dddddddda ",
      " ae   dddddddda ",
      " adddddddddddda ",
      " adddddddddddda ",
      " adddddddddddda ",
      " adddddddddddda ",
      " adddddddddddda ",
      " adddddddddddda "
    ],
    [
      "                ",
      "                ",
      "                ",
      "                ",
      "                ",
      "    aabaaabaaab ",
      "   ffg  h  h  a ",
      "  ff g ijkljmnf ",
      " af  g mmmokpqf ",
      " ae  g ijkrjmsf ",
      " a ttt  u  u  f ",
      " a         w xf ",
      " a    y    w Af ",
      " a    BC     Af ",
      " a    DEF  IJKf ",
      " a   LME      f "
    ],
    [
      "                ",
      "                ",
      "                ",
      "                ",
      "                ",
      "    aabaaabaaab ",
      "   ff         a ",
      "  ff        NOf ",
      " af     NOPQkmf ",
      " a          NOf ",
      " b            f ",
      " f            f ",
      " f            f ",
      " f    R       f ",
      " f            f ",
      " f    S       f "
    ],
    [
      "                ",
      "                ",
      "                ",
      "                ",
      "                ",
      "    aabaaabaaab ",
      "   ff         a ",
      "  ff          f ",
      " af       N   f ",
      " a            f ",
      " a            f ",
      " a            f ",
      " a            f ",
      " a            f ",
      " a            f ",
      " a            f "
    ],
    [
      "                ",
      "                ",
      "                ",
      "                ",
      "                ",
      "    aabaaabaaab ",
      "   ff         a ",
      "  ff          T ",
      " af           T ",
      " a            T ",
      " a            T ",
      " a            T ",
      " a            T ",
      " a            T ",
      " a            T ",
      " a            T "
    ],
    [
      "                ",
      "                ",
      "                ",
      "                ",
      "                ",
      "    aabaaabaaab ",
      "   ff         a ",
      "  ff          a ",
      " af           a ",
      " a            a ",
      " a            a ",
      " a            a ",
      " a            a ",
      " a            a ",
      " a            a ",
      " a            a "
    ],
    [
      "                ",
      "                ",
      "                ",
      "                ",
      "                ",
      "    aabaaabaaab ",
      "   ff b   b   b ",
      "  ff  b   b   b ",
      " af   b   b   b ",
      " a    b   b   b ",
      " a    b   b   b ",
      " a    b   b   b ",
      " a    b   b   b ",
      " a    b   b   b ",
      " a    b   b   b ",
      " a    b   b   b "
    ],
    [
      "                ",
      "                ",
      "                ",
      "                ",
      "                ",
      "    aaaaaaaaaaa ",
      "   UUUVUUUVUUUa ",
      "  UUUUVUUUVUUUa ",
      " aUUUUVUUUVUUUa ",
      " aUUUUVUUUVUUUa ",
      " aUUUUVUUUVUUUa ",
      " aUUUUVUUUVUUUa ",
      " aUUUUVUUUVUUUa ",
      " aUUUUVUUUVUUUa ",
      " aUUUUVUUUVUUUa ",
      " aUUUUVUUUVUUUa "
    ],
    [
      "                ",
      "                ",
      "                ",
      "                ",
      "                ",
      "    aaaaaaaaaaa ",
      "              a ",
      "              a ",
      " a            a ",
      " a            a ",
      " a            a ",
      " a            a ",
      " a            a ",
      " a            a ",
      " a            a ",
      " a            a "
    ]
  ]
}