{
  "name": "multi_hospital_1_base4",
  "refpalette": "deceasedcraft:multi_hospital_1/multi_hospital_1_base4_palette",
  "xsize": 16,
  "zsize": 16,
  "slices": [
    [
      "va     bcdcecb  ",
      "va     fbbbbbf  ",
      "va              ",
      "va              ",
      "va              ",
      "va              ",
      "va              ",
      "vaaa            ",
      "vggbbbbbbbbbbbbb",
      "vg hi           ",
      "vgjhk           ",
      "vgjhlmnopmmmqmnr",
      "vgjggggggggggggg",
      "vgjjgggggggggggg",
      "vggggggggggggggg",
      "vvvvvvvvvvvvvvvv"
    ],
    [
      "va     bddcesb  ",
      "va     fbbbbbf  ",
      "va              ",
      "va              ",
      "va              ",
      "va              ",
      "va              ",
      "vaaa            ",
      "vggbbbbbbbbbbbbb",
      "vg h            ",
      "vg hk           ",
      "vg h     tt    t",
      "vgugwwxywwwxyyww",
      "vgjjjjjjjjjjjjjj",
      "vggggggggggggggg",
      "vvvvvvvvvvvvvvvv"
    ],
    [
      "va     bdccssb  ",
      "va     fbbbbbf  ",
      "va              ",
      "va              ",
      "va              ",
      "va              ",
      "va              ",
      "vaaa            ",
      "vggbbbbbbbbbbbbb",
      "vgAh            ",
      "vgAhkBBBBBBBBBBB",
      "vgjhCCCCCCCCCCCC",
      "vgjgDDDDDDDDDDDD",
      "vg              ",
      "vggggggggggggggg",
      "vvvvvvvvvvvvvvvv"
    ],
    [
      "va     bdccscb  ",
      "va     fbbbbbf  ",
      "va              ",
      "va              ",
      "va              ",
      "va              ",
      "va              ",
      "vaaa            ",
      "vggbbbbbbbbbbbbb",
      "vgAh            ",
      "vgAhk           ",
      "vgjhmmEmnqmmmlmm",
      "vgjggggggggggggg",
      "vgjjgggggggggggg",
      "vggggggggggggggg",
      "vvvvvvvvvvvvvvvv"
    ],
    [
      "va     bdccscb  ",
      "va     fbbbbbf  ",
      "va              ",
      "va              ",
      "va              ",
      "va              ",
      "va              ",
      "vaaa            ",
      "vggbbbbbbbbbbbbb",
      "vgAh            ",
      "vgAhk           ",
      "vgjht  t t tt   ",
      "vgFgwyxwxwwwwxwy",
      "vg Ijjjjjjjjjjjj",
      "vggggggggggggggg",
      "vvvvvvvvvvvvvvvv"
    ],
    [
      "va     bccsJcb  ",
      "va     fbbbbbf  ",
      "va              ",
      "va              ",
      "va              ",
      "va              ",
      "va              ",
      "vaaa            ",
      "vggbbbbbbbbbbbbb",
      "vgAh            ",
      "vgAhkBBBBBBBBBBB",
      "vg hCCCCCCCCCCCC",
      "vgjgDDDDDDDDDDDD",
      "vgjj            ",
      "vggggggggggggggg",
      "vvvvvvvvvvvvvvvv"
    ]
  ]
}