{
  "name": "multi_hospital_1_base2",
  "refpalette": "deceasedcraft:multi_hospital_1/multi_hospital_1_base2_palette",
  "xsize": 16,
  "zsize": 16,
  "slices": [
    [
      "va     bccddcb  ",
      "va     ebbbbbe  ",
      "va              ",
      "va              ",
      "vafg            ",
      "vahhhhhhhhhhhhhh",
      "vahhhhhhhhhhhhhh",
      "vaaaaaaaaaaaaaaa",
      "viibbbbbbbbbbbbb",
      "vijkkkkkkkkkkkkk",
      "vijkkkkkkkkkkkkk",
      "vilkkkkkkkkkkkkk",
      "viliiiiiiiiiiiii",
      "villiiiiiiiiiiii",
      "viiiiiiiiiiiiiii",
      "vvvvvvvvvvvvvvvv"
    ],
    [
      "va     bccmdcb  ",
      "va     ebbbbbe  ",
      "va              ",
      "va              ",
      "va              ",
      "va  nnnnnnnnnnnn",
      "va              ",
      "vaaaaaaaaaoaaaaa",
      "viiiiiiiiiiiiiii",
      "vijjjjjjjjjjjjjj",
      "vijjjjjjjjjjjjjj",
      "vijjjjjjjjjjjjjj",
      "vijjjjjjjjjjjjjj",
      "vijjjjjjjjjjjjjj",
      "viiiiiiiiiiiiiii",
      "vvvvvvvvvvvvvvvv"
    ],
    [
      "va     bccdcpb  ",
      "va     ebbbbbe  ",
      "va              ",
      "va              ",
      "va              ",
      "va              ",
      "va              ",
      "vaaaaaaaaaoaaaaa",
      "vqqqqqqqilllllll",
      "vqqqqqqqillllr  ",
      "vqqqqqqqiiiiiiii",
      "vqqqqqqqiiiiiiii",
      "vqqqqqqqiiiiiiii",
      "vqqqqqqqqqqqqqqq",
      "vqqqqqqqqqqqqqqq",
      "vvvvvvvvvvvvvvvv"
    ],
    [
      "va    stpuduptw ",
      "va     ttttttt  ",
      "va      xxxxx   ",
      "va              ",
      "va              ",
      "va              ",
      "va        y     ",
      "vaaaaaaaaaAaaaaa",
      "vqqqqqqqilBlllll",
      "vqqqqqqqil  Clll",
      "vqqqqqqqiiiiiiii",
      "vqqqqqqqiiiiiiii",
      "vqqqqqqqiiiiiiii",
      "vqqqqqqqqqqqqqqq",
      "vqqqqqqqqqqqqqqq",
      "vvvvvvvvvvvvvvvv"
    ],
    [
      "vDDDDDDDDDDDDDDD",
      "vDDDDDDDDDDDDDDD",
      "vDDDDDDDDDDDDDDD",
      "vDDDDDDDDDDDDDDD",
      "vDDDDDDDDDDDDDDD",
      "vDDDDDDDDDDDDDDD",
      "vDDDDDDDDDDDDDDD",
      "vDDDDDDDDDDDDDDD",
      "vqqqqqqqiiiiiiii",
      "vqqqqqqqiiiiiiii",
      "vqqqqqqqiiiiiiii",
      "vqqqqqqqiiiiiiii",
      "vqqqqqqqiiiiiiii",
      "vqqqqqqqqqqqqqqq",
      "vqqqqqqqqqqqqqqq",
      "vvvvvvvvvvvvvvvv"
    ],
    [
      "vjEFFFF   jjjjjI",
      "vjEFFFF      JJI",
      "vjEFFFF      JJI",
      "vjEFFFF      KLI",
      "vjEFFFF       MI",
      "vjjjjjNNNNjjjjjI",
      "vqqqqqqqqqqqqqqq",
      "vqqqqqqqqqqqqqqq",
      "vqqqqqqqqqqqqqqq",
      "vqqqqqqqqqqqqqqq",
      "vqqqqqqqqqqqqqqq",
      "vqqqqqqqqqqqqqqq",
      "vqqqqqqqqqqqqqqq",
      "vqqqqqqqqqqqqqqq",
      "vqqqqqqqqqqqqqqq",
      "vvvvvvvvvvvvvvvv"
    ]
  ]
}