{
  "name": "multi_hospital_1_top",
  "refpalette": "deceasedcraft:multi_hospital_1/multi_hospital_1_top_palette",
  "xsize": 16,
  "zsize": 16,
  "slices": [
    [
      "   abcdddddddddd",
      "   abcdddddddddd",
      "   abcdddddddddd",
      "   abcdddddddddd",
      "   abcdddddddddd",
      "   abcdddddddddd",
      "   abbbbbbbbbbbb",
      "                ",
      "                ",
      "                ",
      "     e    f    f",
      "     f   fff  ff",
      "          f    e",
      "                ",
      "                ",
      "                "
    ],
    [
      "    gc          ",
      "     c          ",
      "    gc          ",
      "    gc          ",
      "     c hijh  h  ",
      "    gcj k  lj lj",
      "   abbbbbbbbbbbb",
      "                ",
      "                ",
      "                ",
      "          e     ",
      "     e   ff    f",
      "          e     ",
      "                ",
      "                ",
      "                "
    ],
    [
      "    gc          ",
      "     m          ",
      "    gc          ",
      "    gc          ",
      "     m          ",
      "    gc          ",
      "   abbbbbbbbbbbb",
      "                ",
      "                ",
      "                ",
      "                ",
      "          f    e",
      "                ",
      "                ",
      "                ",
      "                "
    ],
    [
      "    gc          ",
      "     m          ",
      "    gc          ",
      "    gc          ",
      "     m          ",
      "    gc          ",
      "   abbnoooonnooo",
      "                ",
      "                ",
      "                ",
      "                ",
      "                ",
      "                ",
      "                ",
      "                ",
      "                "
    ],
    [
      "    gc          ",
      "     m          ",
      "    gc          ",
      "    gc          ",
      "     m          ",
      "    gc          ",
      "   abbbbbbbbbbbb",
      "                ",
      "                ",
      "                ",
      "                ",
      "                ",
      "                ",
      "                ",
      "                ",
      "                "
    ],
    [
      "    gcpqqqqqqqqq",
      "     cpqqqqqqqqq",
      "    gcpqqqqqqqqq",
      "    gcpqqqqqqqqq",
      "     cpqqqqqqqqq",
      "    gcpqqqqqqqqq",
      "   abbbbbbbbbbbb",
      "                ",
      "                ",
      "                ",
      "                ",
      "                ",
      "                ",
      "                ",
      "                ",
      "                "
    ],
    [
      "   abrssstttssss",
      "   abrssstutssss",
      "   abrssstttssss",
      "   abrsssssssssw",
      "   abrssssssssss",
      "   abrssssssssss",
      "   abbbbbbbbbbbb",
      "                ",
      "                ",
      "                ",
      "                ",
      "                ",
      "                ",
      "                ",
      "                ",
      "                "
    ],
    [
      "     s xyAAAyx  ",
      "     sBxyyAyyxC ",
      "     s xyAAAyx  ",
      "     s xxyyyxxw ",
      "     s  xxxxx   ",
      "     s    D     ",
      "                ",
      "                ",
      "                ",
      "                ",
      "                ",
      "                ",
      "                ",
      "                ",
      "                ",
      "                "
    ],
    [
      "                ",
      "      E       F ",
      "                ",
      "                ",
      "                ",
      "          E     ",
      "                ",
      "                ",
      "                ",
      "                ",
      "                ",
      "                ",
      "                ",
      "                ",
      "                ",
      "                "
    ]
  ]
}