{
  "name": "multi_hospital_1_base1",
  "refpalette": "deceasedcraft:multi_hospital_1/multi_hospital_1_base1_palette",
  "xsize": 16,
  "zsize": 16,
  "slices": [
    [
      "vabcccc   aaaaa ",
      "vabd!e          ",
      "vabcccc         ",
      "vabd f          ",
      "vabcccc         ",
      "vaaaaaggggaaaaag",
      "vhhhhhhhhhhhhhhh",
      "vhhhhhhhhhhhhhhh",
      "vhhhhhhhhhhhhhhh",
      "vhhhhhhhhhhhhhhh",
      "vhhhhhhhhhhhhhhh",
      "vhhhhhhhhhhhhhhh",
      "vhhhhhhhhhhhhhhh",
      "vhhhhhhhhhhhhhhh",
      "vhhhhhhhhhhhhhhh",
      "vvvvvvvvvvvvvvvv"
    ],
    [
      "vabcccc   aaaaa ",
      "vabdiii    j    ",
      "vabcccc    j    ",
      "vabdiii    j    ",
      "vabcccc    j    ",
      "vaaaaaggggaaaaag",
      "vhhhhhhhhhhhhhhh",
      "vhhhhhhhhhhhhhhh",
      "vhhhhhhhhhhhhhhh",
      "vhhhhhhhhhhhhhhh",
      "vhhhhhhhhhhhhhhh",
      "vhhhhhhhhhhhhhhh",
      "vhhhhhhhhhhhhhhh",
      "vhhhhhhhhhhhhhhh",
      "vhhhhhhhhhhhhhhh",
      "vvvvvvvvvvvvvvvv"
    ],
    [
      "vabcccc   aaaaa ",
      "vabdkkk    j    ",
      "vabcccc    j    ",
      "vabdkkk    j    ",
      "vabcccc    j    ",
      "vaaaaaggggaaaaag",
      "vhhhhhhhhhhhhhhh",
      "vhhhhhhhhhhhhhhh",
      "vhhhhhhhhhhhhhhh",
      "vhhhhhhhhhhhhhhh",
      "vhhhhhhhhhhhhhhh",
      "vhhhhhhhhhhhhhhh",
      "vhhhhhhhhhhhhhhh",
      "vhhhhhhhhhhhhhhh",
      "vhhhhhhhhhhhhhhh",
      "vvvvvvvvvvvvvvvv"
    ],
    [
      "vabcccc   aaaaa ",
      "vabd       j    ",
      "vabcccc    j    ",
      "vabdl      j    ",
      "vabcccc    j    ",
      "vaaaaaggggaaaaag",
      "vhhhhhhhhhhhhhhh",
      "vhhhhhhhhhhhhhhh",
      "vhhhhhhhhhhhhhhh",
      "vhhhhhhhhhhhhhhh",
      "vhhhhhhhhhhhhhhh",
      "vhhhhhhhhhhhhhhh",
      "vhhhhhhhhhhhhhhh",
      "vhhhhhhhhhhhhhhh",
      "vhhhhhhhhhhhhhhh",
      "vvvvvvvvvvvvvvvv"
    ],
    [
      "vabcccc   aaaaam",
      "vabcccc    nommm",
      "vabcccc    nommm",
      "vabcicc    nommm",
      "vabcccc    nommm",
      "vaaaaaggggaaaaap",
      "vhhhhhhhhhhhhhhh",
      "vhhhhhhhhhhhhhhh",
      "vhhhhhhhhhhhhhhh",
      "vhhhhhhhhhhhhhhh",
      "vhhhhhhhhhhhhhhh",
      "vhhhhhhhhhhhhhhh",
      "vhhhhhhhhhhhhhhh",
      "vhhhhhhhhhhhhhhh",
      "vhhhhhhhhhhhhhhh",
      "vvvvvvvvvvvvvvvv"
    ],
    [
      "vabbbbbbbbaaaaab",
      "vabbbbbbbbbbobbb",
      "vabbbbbbbbbbobbb",
      "vabbbbbbbbbbobbb",
      "vabbbbbbbbbbobbb",
      "vaaaaabbbbaaaaab",
      "vhhhhhhhhhhhhhhh",
      "vhhhhhhhhhhhhhhh",
      "vhhhhhhhhhhhhhhh",
      "vhhhhhhhhhhhhhhh",
      "vhhhhhhhhhhhhhhh",
      "vhhhhqhhhhqhhhhq",
      "vhhhhhhhhhhhhhhh",
      "vhhhhhhhhhhhhhhh",
      "vhhhhhhhhhhhhhhh",
      "vvvvvvvvvvvvvvvv"
    ]
  ]
}