{
  "name": "multi_hospital_1_base5",
  "refpalette": "deceasedcraft:multi_hospital_1/multi_hospital_1_base5_palette",
  "xsize": 16,
  "zsize": 16,
  "slices": [
    [
      "vvvvvvvvvvvvvvvv",
      "vvvvvvvvvvvvvvvv",
      "vvvvvvvvvvvvvvvv",
      "vvvvvvvvvvvvvvvv",
      "vvvvvvvvvvvvvvvv",
      "vvvvvvvvvvvvvvvv",
      "vvvvvvvvvvvvvvvv",
      "vvvvvvvvvvvvvvvv",
      "vvvvvvvvvvvvvvvv",
      "vvvvvvvvvvvvvvvv",
      "vvvvvvvvvvvvvvvv",
      "vvvvvvvvvvvvvvvv",
      "vvvvvvvvvvvvvvvv",
      "vvvvvvvvvvvvvvvv",
      "vvvvvvvvvvvvvvvv",
      "vvvvvvvvvvvvvvvv"
    ],
    [
      "vaaaaaabbbbbbbaa",
      "vaaaaaaabbbbbaaa",
      "vaaaaaaaaaaaaaaa",
      "vaaaaaaaaaaaaaaa",
      "vaaaaaaaaaaaaaaa",
      "vaaaaaaaaaaaaaaa",
      "vaaaaaaaaaaaaaaa",
      "vaaaaaaaaaaaaaaa",
      "vaaaaaaaaaaaaaaa",
      "vaaaaaaaaaaaaaaa",
      "vaaaaaaaaaaaaaaa",
      "vaaaaaaaaaaaaaaa",
      "vaaaaaaaaaaaaaaa",
      "vaaaaaaaaaaaaaaa",
      "vaaaaaaaaaaaaaaa",
      "vvvvvvvvvvvvvvvv"
    ],
    [
      "vaaaaaabcccdcbaa",
      "vaaaaaaabbbbbaaa",
      "vaaaaaaaaaaaaaaa",
      "vaaaaaaaaaaaaaaa",
      "vaaaaaaaaaaaaaaa",
      "vaaaaaaaaaaaaaaa",
      "vaaaaaaaaaaaaaaa",
      "vaaaaaaaaaaaaaaa",
      "vaaaaaaaaaaaaaaa",
      "vaaaaaaaaaaaaaaa",
      "vaaaaaaaaaaaaaaa",
      "vaaaaaaaaaaaaaaa",
      "vaaaaaaaaaaaaaaa",
      "vaaaaaaaaaaaaaaa",
      "vaaaaaaaaaaaaaaa",
      "vvvvvvvvvvvvvvvv"
    ],
    [
      "veeeeeebfghicbee",
      "veeeeeeebbbbbeee",
      "veeeeeeeeeeeeeee",
      "veeeeeeeeeeeeeee",
      "veeeeeeeeeeeeeee",
      "veeeeeeeeeeeeeee",
      "veeeeeeeeeeeeeee",
      "veeeeeeeeeeeeeee",
      "vjjjjjjjjjjjjjjj",
      "vjkkkkkkkkkkkkkk",
      "vjkkkkkkkkkkkkkk",
      "vjkkkkkkkkkkkkkk",
      "vjkkkkkkkkkkkkkk",
      "vjkkkkkkkkkkkkkk",
      "vjjjjjjjjjjjjjjj",
      "vvvvvvvvvvvvvvvv"
    ],
    [
      "vl  m nbgghigbo ",
      "vl     bbbbbbb  ",
      "vl      ppqpp   ",
      "vl              ",
      "vl      rsssr   ",
      "vl        t     ",
      "vl              ",
      "vlllllllllllllll",
      "vjjuuuuuuuuuuuuu",
      "vjwxxxxxxxxxxxxx",
      "vjwxxxxxxxxxxxxx",
      "vjwxxxxxxxxxxxxx",
      "vjwjwwwwwwwwwwww",
      "vjwwwwwwwwwwwwww",
      "vjjjjjjjjjjjjjjj",
      "vvvvvvvvvvvvvvvv"
    ],
    [
      "vl  y  ughhigu  ",
      "vl     AuuuuuA  ",
      "vl        B     ",
      "vl              ",
      "vl      CyD E   ",
      "vl              ",
      "vl              ",
      "vlll            ",
      "vjjuuuuuuuuuuuuu",
      "vjwx            ",
      "vjwxFIIIIIIIIIII",
      "vjwxJJJJJJJJJJJJ",
      "vjwjKKKKKKKKKKKK",
      "vj              ",
      "vjjjjjjjjjjjjjjj",
      "vvvvvvvvvvvvvvvv"
    ]
  ]
}