{
  "name": "multi_hospital_1_base3",
  "refpalette": "deceasedcraft:multi_hospital_1/multi_hospital_1_base3_palette",
  "xsize": 16,
  "zsize": 16,
  "slices": [
    [
      "va     bccdecb  ",
      "va     fbbbbbf  ",
      "va              ",
      "va              ",
      "va              ",
      "va              ",
      "va              ",
      "vaaa            ",
      "vggbbbbbbbbbbbbb",
      "vghi            ",
      "vghij           ",
      "vgkilmnnonpnnqrn",
      "vgkggggggggggggg",
      "vgkkgggggggggggg",
      "vggggggggggggggg",
      "vvvvvvvvvvvvvvvv"
    ],
    [
      "va     bcsdecb  ",
      "va     fbbbbbf  ",
      "va              ",
      "va              ",
      "va              ",
      "va              ",
      "va              ",
      "vaaa            ",
      "vggbbbbbbbbbbbbb",
      "vghi            ",
      "vghij           ",
      "vg i   t   ttt  ",
      "vg guwuuxuuuuuwu",
      "vg ykkkkkkkkkkkk",
      "vggggggggggggggg",
      "vvvvvvvvvvvvvvvv"
    ],
    [
      "vaAA   bddcecb  ",
      "va     fbbbbbf  ",
      "va              ",
      "va              ",
      "va              ",
      "va              ",
      "va              ",
      "vaaa            ",
      "vggbbbbbbbbbbbbb",
      "vghi            ",
      "vghijBBBBBBBBBBB",
      "vgkiCCCCCCCCCCCC",
      "vgkgDDDDDDDDDDDD",
      "vgkk            ",
      "vggggggggggggggg",
      "vvvvvvvvvvvvvvvv"
    ],
    [
      "va E   bddceFb  ",
      "vaIJ   fbbbbbf  ",
      "va              ",
      "va              ",
      "va              ",
      "va              ",
      "va              ",
      "vaaa            ",
      "vggbbbbbbbbbbbbb",
      "vghi            ",
      "vghij           ",
      "vg inmnKlnnLnnMn",
      "vgNggggggggggggg",
      "vgkkgggggggggggg",
      "vggggggggggggggg",
      "vvvvvvvvvvvvvvvv"
    ],
    [
      "va     bdcceFb  ",
      "va     fbbbbbf  ",
      "vaIJ            ",
      "va              ",
      "va              ",
      "va              ",
      "va              ",
      "vaaa            ",
      "vggbbbbbbbbbbbbb",
      "vghi            ",
      "vghi            ",
      "vgkitt   t t   t",
      "vgkguuwuxuuuuxwu",
      "vg ykkkkkkkkkkkk",
      "vggggggggggggggg",
      "vvvvvvvvvvvvvvvv"
    ],
    [
      "va     bcccFFb  ",
      "va     fbbbbbf  ",
      "va              ",
      "vaIJ            ",
      "va              ",
      "va              ",
      "va              ",
      "vaaa            ",
      "vggbbbbbbbbbbbbb",
      "vghi            ",
      "vghi            ",
      "vgkiCCCCCCCCCCCC",
      "vgkgDDDDDDDDDDDD",
      "vgkk            ",
      "vggggggggggggggg",
      "vvvvvvvvvvvvvvvv"
    ]
  ]
}