{
  "name": "multi_hospital_1_floor1",
  "refpalette": "deceasedcraft:multi_hospital_1/multi_hospital_1_floor1_palette",
  "xsize": 16,
  "zsize": 16,
  "slices": [
    [
      "  a      bcccccc",
      "  a      bcccccc",
      "  bddddddbeccccc",
      "        fghhhhhh",
      "        fghhhhhh",
      "        fghhhhhh",
      "        fghhhhhh",
      "        fghhhhhh",
      "        fghhhhhh",
      "        fghhhhhh",
      "        fghhhhhh",
      "        fghhhhhh",
      "        fghhhhhh",
      "        fggggggg",
      "        fggggggg",
      "                "
    ],
    [
      "  iccjkccg  lm  ",
      "  iccccccgn !m  ",
      "  boooooobpqpp  ",
      "        fgr  s  ",
      "        fgr  s  ",
      "        fgt  u  ",
      "        fgw  s  ",
      "        fgxxxs  ",
      "        fg  ys  ",
      "        fg AAs  ",
      "        fg   B  ",
      "        fg CCs  ",
      "        fg D s  ",
      "        fgCEEbFF",
      "        fIIIII  ",
      "                "
    ],
    [
      "    JJcccg   m  ",
      "    JJcccg   m  ",
      "  bbbbbbbbpKpp  ",
      "        fgL  s  ",
      "        fgL  s  ",
      "        fg   M  ",
      "        fg   s  ",
      "        fgNNNs  ",
      "        fg   s  ",
      "        fg  Os  ",
      "        fg   P  ",
      "        fg Q s  ",
      "        fg   s  ",
      "        fgREEbFF",
      "        fIISII  ",
      "                "
    ],
    [
      "         N   m  ",
      "        fg   m  ",
      "        fbpppp  ",
      "        fg   s  ",
      "         N   s  ",
      "         N   s  ",
      "         N   s  ",
      "        fg   s  ",
      "        fg   s  ",
      "         N   s  ",
      "         N   s  ",
      "         N   s  ",
      "        fg   s  ",
      "        fg  TbFF",
      "        fISSSI  ",
      "                "
    ],
    [
      "        fU   m  ",
      "        fg   m  ",
      "        fbpppppp",
      "        fg   s  ",
      "        fU   s  ",
      "        fU   s  ",
      "        fU   s  ",
      "        fg   s  ",
      "        fg   s  ",
      "        fU   s  ",
      "        fU   s  ",
      "        fU   s  ",
      "        fg   s  ",
      "        fg   bFF",
      "        fIISII  ",
      "                "
    ],
    [
      "        fgvVVm  ",
      "        fgvVVm  ",
      "        fbpppppp",
      "        fg   s  ",
      "        fg   s  ",
      "        fg   s  ",
      "        fg   s  ",
      "        fg   s  ",
      "        fg   s  ",
      "        fg   s  ",
      "        fg   s  ",
      "        fg   s  ",
      "        fg   s  ",
      "        fg   bFF",
      "        fIIIII  ",
      "                "
    ]
  ]
}