{
  "name": "multi_hospital_1_ground",
  "refpalette": "deceasedcraft:multi_hospital_1/multi_hospital_1_ground_palette",
  "xsize": 16,
  "zsize": 16,
  "slices": [
    [
      "aaabbcdddddccccd",
      "aaabbcdddddccccd",
      "aaabbcdddddddddd",
      "aaabbcdddddddddd",
      "aaabbcdddddddddd",
      "aaabbccccccccccc",
      "aaabbbbbbbbbbbbb",
      "aaabbbbbbbbbbbbb",
      "aaabbbbbbbbbbbbb",
      "aaabbbbbbbbbbbbb",
      "aaabbbbbbbbbbbbb",
      "aaabbebbbbebbbbe",
      "aaabbbbbbbbbbbbb",
      "aaabbbbbbbbbbbbb",
      "aaaaaaaaaaaaaaaa",
      "aaaaaaaaaaaaaaaa"
    ],
    [
      "  f ghi  jkl  lm",
      "  f ghi noplqql ",
      "  f ghrsrrrrrrrr",
      "  f ght         ",
      "  f ghu wx  wx  ",
      "  f ghhyyyyyyyyy",
      "  f  AAAAAAAAAAA",
      "  f             ",
      "  fB            ",
      "  fC            ",
      "  f             ",
      "  f  D    D    D",
      "  f             ",
      "  f    EF   EF  ",
      "  Ifffffffffffff",
      "                "
    ],
    [
      "    ghi    l  l ",
      "    ghi  JKlLMlK",
      "    ghrNrrrOOOOr",
      "    gh          ",
      "    gh          ",
      "    ghhfffffffff",
      "     AAAAAAAAAAA",
      "                ",
      "                ",
      "                ",
      "                ",
      "     P    P    P",
      "                ",
      "                ",
      "                ",
      "                "
    ],
    [
      "    ghQ    l  l ",
      "    ghi    lMLl ",
      "    ghrRrrrSSSSr",
      "    gh          ",
      "    gh          ",
      "    ghh         ",
      "     AAAAAAAAAAA",
      "                ",
      "                ",
      "                ",
      "                ",
      "     T    T    T",
      "                ",
      "                ",
      "                ",
      "                "
    ],
    [
      "    ghi    l  l ",
      "    ghi   UlVWl ",
      "    ghrrrrrrrrrr",
      "    gh X   X   X",
      "    gh          ",
      "    ghhhhhhhhhhh",
      "     AAAAAAAAAAA",
      "                ",
      "                ",
      "                ",
      "               Y",
      "    ffY   fY   f",
      "     f          ",
      "                ",
      "                ",
      "                "
    ],
    [
      "    Z01111111111",
      "    Z01111111111",
      "    Z01111111111",
      "    Z01111111111",
      "    Z01111111111",
      "    Z01111111111",
      "    ZZZZZZZZZZZZ",
      "                ",
      "                ",
      "                ",
      "     f    Y    f",
      "    fff  Yff  Yf",
      "     Y    f    f",
      "                ",
      "                ",
      "                "
    ]
  ]
}