{
  "name": "multi_verticalschool_2_base1",
  "refpalette": "deceasedcraft:multi_verticalschool_2/multi_verticalschool_2_base1_palette",
  "xsize": 16,
  "zsize": 16,
  "slices": [
    [
      "v    aaaaaaaaaaa",
      "v    abcccb     ",
      "v    a          ",
      "v    d          ",
      "v    d          ",
      "v    d          ",
      "v    d          ",
      "v    d          ",
      "v    a          ",
      "v    abcccb bccc",
      "v    aaaaaaaaaaa",
      "v    d          ",
      "v    d          ",
      "v    d          ",
      "v    d          ",
      "v    aaaaaaaaaaa"
    ],
    [
      "v    aaaaaaaaaaa",
      "v    abeefb     ",
      "v    a          ",
      "v    d          ",
      "v    d          ",
      "v    d          ",
      "v    d          ",
      "v    d          ",
      "v    a          ",
      "v    abg!gb bhij",
      "v    aaaaaaaaaaa",
      "v    d          ",
      "v    d          ",
      "v    d          ",
      "v    d          ",
      "v    aaaaaaaaaaa"
    ],
    [
      "v    aaaaaaaaaaa",
      "v    abcccb     ",
      "v   ka          ",
      "v   kal         ",
      "v   kal         ",
      "v   kal         ",
      "v   kal         ",
      "v   kal         ",
      "v   ka          ",
      "v    abcccb bccc",
      "v   kaaaaaaaaaaa",
      "v   kal         ",
      "v   kal         ",
      "v   kal         ",
      "v   kal         ",
      "v   kaaaaaaaaaaa"
    ],
    [
      "v    aaaaaaaaaaa",
      "v    abme b     ",
      "v    a          ",
      "v    a          ",
      "v    a          ",
      "v    a          ",
      "v    a          ",
      "v    a          ",
      "v    a          ",
      "v    ab nob bpqr",
      "v    aaaaaaaaaaa",
      "v    a          ",
      "v    a          ",
      "v    a          ",
      "v    a s   s   s",
      "v    aaaaaaaaaaa"
    ],
    [
      "v    aaaaaaaaaaa",
      "v    abtttb     ",
      "v    a          ",
      "v    a          ",
      "v    a          ",
      "v    a          ",
      "v    a          ",
      "v    a          ",
      "v    a          ",
      "v    abtttb bttt",
      "v    aaaaaaaaaaa",
      "v    a          ",
      "v    a          ",
      "v    a          ",
      "v    uwxwwwxwwwx",
      "v    aawaaaaaaaa"
    ],
    [
      "vyyyyaaaaaaaaaaa",
      "vyyyyaAyyyAyyyyy",
      "vyyyyayyyyyyyyyy",
      "vyyyyayyByyyyyBy",
      "vyyyyayyyyyyyyyy",
      "vyyyyayyyyyyyyyy",
      "vyyyyayyyyyyyyyy",
      "vyyyyayyByyyyyCy",
      "vyyyyayyyyyyyyyy",
      "vyyyyaAyyyAyAyyy",
      "vyyyyaaaaaaaaaaa",
      "vyyyyayyyyyyyyyy",
      "vyyyyayyByyyyyBy",
      "vyyyyayyyyyyyyyy",
      "vyyyyayyyyyyyyyy",
      "vyyyyaaaaaaaaaaa"
    ]
  ]
}