{
  "name": "multi_verticalschool_2_floor15",
  "refpalette": "deceasedcraft:multi_verticalschool_2/multi_verticalschool_2_floor15_palette",
  "xsize": 16,
  "zsize": 16,
  "slices": [
    [
      "        a       ",
      "        a       ",
      "        abc     ",
      "        a       ",
      "        a       ",
      "        a       ",
      "        a       ",
      "        bbd     ",
      "        a       ",
      "        a       ",
      "        b       ",
      "        a       ",
      "        abc     ",
      "        a       ",
      "        a       ",
      "        a       "
    ],
    [
      "                ",
      "        ~       ",
      "         a      ",
      "                ",
      "                ",
      "                ",
      "                ",
      "         a      ",
      "                ",
      "                ",
      "                ",
      "        ~       ",
      "         a      ",
      "                ",
      "                ",
      "                "
    ],
    [
      "            e fg",
      "            e fg",
      "         h  e fg",
      "            e fg",
      "            e fg",
      "            e fg",
      "            e fg",
      "         h  e fg",
      "            e fg",
      "            e fg",
      "            e fg",
      "            e fg",
      "         h  e fg",
      "            e fg",
      "            e fg",
      "            e fg"
    ],
    [
      "            ijkk",
      "            ijkk",
      "        hh  ijkk",
      "         h  ijkk",
      "            ijkk",
      "            ijkk",
      "            ijkk",
      "        hhh ijkk",
      "         h  ijkk",
      "            ijkk",
      "            ijkk",
      "            ijkk",
      "        hh  ijkk",
      "         h  ijkk",
      "            ijkk",
      "            ijkk"
    ],
    [
      "            lj  ",
      "         h  lj  ",
      "        hh  lj  ",
      "         h  lj  ",
      "            lj  ",
      "            lj  ",
      "         h  lj  ",
      "        hhh lj  ",
      "         h  lj  ",
      "            lj  ",
      "            lj  ",
      "         h  lj  ",
      "        hhh lj  ",
      "         h  lj  ",
      "            lj  ",
      "            lj  "
    ],
    [
      "             m  ",
      "         h   m  ",
      "        hhh  m  ",
      "             m  ",
      "             m  ",
      "             m  ",
      "             m  ",
      "         h   m  ",
      "         h   m  ",
      "             m  ",
      "             m  ",
      "             m  ",
      "        hhh  m  ",
      "             m  ",
      "             m  ",
      "             m  "
    ]
  ]
}