{
  "name": "multi_verticalschool_2_floor7",
  "refpalette": "deceasedcraft:multi_verticalschool_2/multi_verticalschool_2_floor7_palette",
  "xsize": 16,
  "zsize": 16,
  "slices": [
    [
      "                ",
      "                ",
      "                ",
      "                ",
      "                ",
      "                ",
      "                ",
      "                ",
      "                ",
      "                ",
      "                ",
      "                ",
      "                ",
      "                ",
      "                ",
      "                "
    ],
    [
      "                ",
      "                ",
      "                ",
      "                ",
      "                ",
      "                ",
      "                ",
      "                ",
      "                ",
      "                ",
      "                ",
      "                ",
      "                ",
      "                ",
      "                ",
      "                "
    ],
    [
      "      a bcbbbbbb",
      "      a bcbbbbbb",
      "      a bcbbbbbb",
      "      a bcbbbbbb",
      "      a bcbbbbbb",
      "      a bcbbbbbb",
      "      a bcbbbbbb",
      "      a bcbbbbbb",
      "      a bcbbbbbb",
      "      a bcbbbbbb",
      "      a bcbbbbbb",
      "      a bcbbbbbb",
      "      a bcbbbbbb",
      "      a bcbbbbbb",
      "      a bcbbbbbb",
      "      a bcbbbbbb"
    ],
    [
      "     defgggggggg",
      "     defgggggggg",
      "     defgggggggg",
      "     defgggggggg",
      "     defgggggggg",
      "     defgggggggg",
      "     defgggggggg",
      "     defgggggggg",
      "     defgggggggg",
      "     defgggggggg",
      "     defgghhhhhh",
      "     defgghiiiii",
      "     defgghiiiii",
      "     defgghiiiii",
      "     defgghiiiii",
      "     defgghiiiii"
    ],
    [
      "     de      jkj",
      "     de    j    ",
      "     de    k    ",
      "     de    j  j ",
      "     de       k ",
      "     de       j ",
      "     del  jkj   ",
      "     de         ",
      "     de         ",
      "     de         ",
      "     de   hhhhhh",
      "     de   h  m n",
      "     de   ho pqq",
      "     de   h  r n",
      "     de   ho pqq",
      "     del  h  m n"
    ],
    [
      "     ds         ",
      "     ds         ",
      "     ds         ",
      "     ds         ",
      "     de       t ",
      "     de         ",
      "     deu   w    ",
      "     de         ",
      "     de         ",
      "     ds         ",
      "     ds   xxxxxx",
      "     ds   x yA  ",
      "     ds   x  pqq",
      "     de   x  B  ",
      "     de   x  pqq",
      "     deu  x  A  "
    ]
  ]
}