{
  "name": "multi_verticalschool_2_floor5",
  "refpalette": "deceasedcraft:multi_verticalschool_2/multi_verticalschool_2_floor5_palette",
  "xsize": 16,
  "zsize": 16,
  "slices": [
    [
      "     aabbbbbbbbb",
      "     aabbbbbbbbb",
      "     aabbbbbbbbb",
      "     aabbbbbbbbb",
      "     aabbbbbbbbb",
      "     aabbbbbbbbb",
      "     aabbbbbbbbb",
      "     aabbbbbbbbb",
      "     aabbbbbbbbb",
      "     aabbbbbbbbb",
      "     aabbbbbbbbb",
      "     aabbbbbbbbb",
      "     aabbbbbbbbb",
      "     aabbbbbbbbb",
      "     aabbbbbbbbb",
      "     aabbbbbbbbb"
    ],
    [
      "     accdcdcdcdc",
      "     accdcdcdcdc",
      "     accdcdcdcdc",
      "     accdcdcdcdc",
      "     accdcdcdcdc",
      "     accdcdcdcdc",
      "     accdcdcdcdc",
      "     accdcdcdcdc",
      "     accdcdcdcdc",
      "     accdcdcdcdc",
      "     accdcdcdcdc",
      "     accdcdcdcdc",
      "     accdcdcdcdc",
      "     accdcdcdcdc",
      "     accdcdcdcdc",
      "     accdcdcdcdc"
    ],
    [
      "     acefffffffg",
      "     acfffffffff",
      "     acfffffffff",
      "     acfffffffff",
      "     acfffffffff",
      "     acefffffffg",
      "     acfffffffff",
      "     acfffffffff",
      "     acfffffffff",
      "     acfffffffff",
      "     acefffffffg",
      "     acfffffffff",
      "     acfffffffff",
      "     acfffffffff",
      "     acfffffffff",
      "     acefffffffg"
    ],
    [
      "     acfffffffff",
      "     acfffffffff",
      "     acfffffffff",
      "     acfffffffff",
      "     acfffffffff",
      "     acfffffffff",
      "     acfffffffff",
      "     acfffffffff",
      "     acfffffffff",
      "     acfffffffff",
      "     acfffffffff",
      "     acfffffffff",
      "     acfffffffff",
      "     acfffffffff",
      "     acfffffffff",
      "     acfffffffff"
    ],
    [
      "     a          ",
      "     a          ",
      "     a          ",
      "     a          ",
      "     a          ",
      "     a          ",
      "     a          ",
      "     a          ",
      "     a          ",
      "     a          ",
      "     a          ",
      "     a          ",
      "     a          ",
      "     a          ",
      "     a          ",
      "     a          "
    ],
    [
      "     a          ",
      "     a          ",
      "     a          ",
      "     a          ",
      "     a          ",
      "     a          ",
      "     a          ",
      "     a          ",
      "     a          ",
      "     a          ",
      "     a          ",
      "     a          ",
      "     a          ",
      "     a          ",
      "     a          ",
      "     a          "
    ]
  ]
}