{
  "name": "multi_verticalschool_2_floor16",
  "refpalette": "deceasedcraft:multi_verticalschool_2/multi_verticalschool_2_floor16_palette",
  "xsize": 16,
  "zsize": 16,
  "slices": [
    [
      "             a  ",
      "             a  ",
      "        bb   a  ",
      "             a  ",
      "             a  ",
      "             a  ",
      "             a  ",
      "         b   a  ",
      "          ~  a  ",
      "             a  ",
      "             a  ",
      "             a  ",
      "         b   a  ",
      "             a  ",
      "             a  ",
      "             a  "
    ],
    [
      "             a  ",
      "             a  ",
      "         b   a  ",
      "          ~  a  ",
      "             a  ",
      "             a  ",
      "             a  ",
      "             a  ",
      "             a  ",
      "             a  ",
      "             a  ",
      "             a  ",
      "             a  ",
      "          ~  a  ",
      "             a  ",
      "             a  "
    ],
    [
      "             a  ",
      "             a  ",
      "             a  ",
      "             a  ",
      "             a  ",
      "             a  ",
      "             a  ",
      "             a  ",
      "             a  ",
      "             a  ",
      "             a  ",
      "             a  ",
      "             a  ",
      "             a  ",
      "             a  ",
      "             a  "
    ],
    [
      "            cadd",
      "            cadd",
      "            cadd",
      "            cadd",
      "            cadd",
      "            cadd",
      "            cadd",
      "            cadd",
      "            cadd",
      "            cadd",
      "            cadd",
      "            cadd",
      "            cadd",
      "            cadd",
      "            cadd",
      "            cadd"
    ],
    [
      "            efgd",
      "            efgd",
      "            efhd",
      "            efhd",
      "            efgd",
      "            efgd",
      "            efgd",
      "            efhd",
      "            efhd",
      "            efgd",
      "            efgd",
      "            efgd",
      "            efhd",
      "            efhd",
      "            efgd",
      "            efgd"
    ],
    [
      "            ifee",
      "            ifee",
      "            ifee",
      "            ifee",
      "            ifee",
      "            ifee",
      "            ifee",
      "            ifee",
      "            ifee",
      "            ifee",
      "            ifee",
      "            ifee",
      "            ifee",
      "            ifee",
      "            ifee",
      "            ifee"
    ]
  ]
}