{
  "name": "multi_verticalschool_2_floor8",
  "refpalette": "deceasedcraft:multi_verticalschool_2/multi_verticalschool_2_floor8_palette",
  "xsize": 16,
  "zsize": 16,
  "slices": [
    [
      "     ab         ",
      "     ab         ",
      "     ab         ",
      "     ab         ",
      "     ab         ",
      "     ab         ",
      "     abc        ",
      "     ab         ",
      "     ab         ",
      "     ab         ",
      "     ab   dddddd",
      "     ab   de f  ",
      "     ab   dg fhh",
      "     ab   dg f  ",
      "     ab   dg fhh",
      "     abc  dg f  "
    ],
    [
      "     abijjjjjjjj",
      "     abijjjjjjjj",
      "     abijjjjjjjj",
      "     abijjjjjjjj",
      "     abijjjjjjjj",
      "     abijjjjjjjj",
      "     abijjjjjjjj",
      "     abijjjjjjjj",
      "     abijjjjjjjj",
      "     abijjjjjjjj",
      "     abijjdddddd",
      "     abijjdjjjjk",
      "     abijjdjjjjl",
      "     abijjdjjjj!",
      "     abijjdjjjjl",
      "     abijjdjjjjk"
    ],
    [
      "     abbmnnnnnnn",
      "     abbmnnnnnnn",
      "     abbmnnnnnnn",
      "     abbmnnnnnnn",
      "     abbmnnnnnnn",
      "     abbmnnnnnnn",
      "     abbmnnnnnnn",
      "     abbmnnnnnnn",
      "     abbmnnnnnnn",
      "     abbmnnnnnnn",
      "     abbmnnnnnnn",
      "     abbmnnnnnnn",
      "     abbmnnnnnnn",
      "     abbmnnnnnnn",
      "     abbmnnnnnnn",
      "     abbmnnnnnnn"
    ],
    [
      "        opq     ",
      "        o       ",
      "        o       ",
      "        p       ",
      "        o       ",
      "        opq     ",
      "        o       ",
      "        o       ",
      "        o       ",
      "        o       ",
      "        opr     ",
      "        o       ",
      "        o       ",
      "        o       ",
      "        o       ",
      "        opq     "
    ],
    [
      "         o      ",
      "                ",
      "                ",
      "                ",
      "                ",
      "         o      ",
      "                ",
      "                ",
      "                ",
      "        ~       ",
      "         o      ",
      "                ",
      "                ",
      "                ",
      "                ",
      "         o      "
    ],
    [
      "         s   t u",
      "         s  t uu",
      "            t uw",
      "            t uw",
      "            t uw",
      "         ss t uw",
      "            t uw",
      "            t uw",
      "            t uw",
      "            t uw",
      "         s  t uw",
      "            t uw",
      "            t uw",
      "            t uw",
      "            t uw",
      "        ss  t uw"
    ]
  ]
}