{
  "name": "multi_verticalschool_2_floor22",
  "refpalette": "deceasedcraft:multi_verticalschool_2/multi_verticalschool_2_floor22_palette",
  "xsize": 16,
  "zsize": 16,
  "slices": [
    [
      "                ",
      "                ",
      "                ",
      "                ",
      "                ",
      "                ",
      "                ",
      "                ",
      "                ",
      "                ",
      "                ",
      "                ",
      "                ",
      "                ",
      "                ",
      "                "
    ],
    [
      "           abbcb",
      "           abbcb",
      "           abbcb",
      "           abbcb",
      "           abbcb",
      "           abbcb",
      "           abbcb",
      "           abbcb",
      "           abbcb",
      "           abbcb",
      "           abbcb",
      "           abbcb",
      "           abbcb",
      "           abbcb",
      "           abbcb",
      "           abbcb"
    ],
    [
      "           deeee",
      "           deeee",
      "           deeee",
      "           deeee",
      "           deeee",
      "           deeee",
      "           deeee",
      "           deeee",
      "           deeee",
      "           deeee",
      "           deeee",
      "           deeee",
      "           deeee",
      "           deeee",
      "           deeee",
      "           deeee"
    ],
    [
      "           df   ",
      "           dg   ",
      "           dg   ",
      "           dg   ",
      "           dg   ",
      "           dg   ",
      "           dg   ",
      "           dg   ",
      "           dg   ",
      "           dg   ",
      "           dg   ",
      "           dg   ",
      "           dg   ",
      "           dg   ",
      "           dg   ",
      "           df   "
    ],
    [
      "           dh   ",
      "           dg   ",
      "           dg   ",
      "           dg   ",
      "           dg   ",
      "           dg   ",
      "           dg   ",
      "           dg   ",
      "           dg   ",
      "           dg   ",
      "           dg   ",
      "           dg   ",
      "           dg   ",
      "           dg   ",
      "           dg   ",
      "           dh   "
    ],
    [
      "           di   ",
      "           dg   ",
      "           dg   ",
      "           dg   ",
      "           dg   ",
      "           dg   ",
      "           dg   ",
      "           dg   ",
      "           dg   ",
      "           dg   ",
      "           dg   ",
      "           dg   ",
      "           dg   ",
      "           dg   ",
      "           dg   ",
      "           dj   "
    ]
  ]
}