{
  "name": "multi_verticalschool_2_floor25",
  "refpalette": "deceasedcraft:multi_verticalschool_2/multi_verticalschool_2_floor25_palette",
  "xsize": 16,
  "zsize": 16,
  "slices": [
    [
      "            abcc",
      "            abcc",
      "            abcc",
      "            abcc",
      "            abcc",
      "            abcc",
      "            abcc",
      "            abcc",
      "            abcc",
      "            abcc",
      "            abcc",
      "            abcc",
      "            abcc",
      "            abcc",
      "            abcc",
      "            abcc"
    ],
    [
      "            db e",
      "            dbfe",
      "            dbfe",
      "            db e",
      "            dbfe",
      "            dbfe",
      "            dbfe",
      "            dbfe",
      "            dbfe",
      "            dbfe",
      "            dbfe",
      "            dbfe",
      "            dbfe",
      "            dbfe",
      "            dbfe",
      "            db e"
    ],
    [
      "             g h",
      "             g h",
      "             g h",
      "             g h",
      "             g h",
      "             g h",
      "             g h",
      "             g h",
      "             g h",
      "             g h",
      "             g h",
      "             g h",
      "             g h",
      "             g h",
      "             g h",
      "             g h"
    ],
    [
      "             g  ",
      "             g  ",
      "             g  ",
      "             g  ",
      "             g  ",
      "             g  ",
      "             g  ",
      "             g  ",
      "             g  ",
      "             g  ",
      "             g  ",
      "             g  ",
      "             g  ",
      "             g  ",
      "             g  ",
      "             g  "
    ],
    [
      "             g  ",
      "             g  ",
      "             g  ",
      "             g  ",
      "             g  ",
      "             g  ",
      "             g  ",
      "             g  ",
      "             g  ",
      "             g  ",
      "             g  ",
      "             g  ",
      "             g  ",
      "             g  ",
      "             g  ",
      "             g  "
    ],
    [
      "            igjj",
      "            igjj",
      "            igjj",
      "            igjj",
      "            igjj",
      "            igjj",
      "            igjj",
      "            igjj",
      "            igjj",
      "            igjj",
      "            igjj",
      "            igjj",
      "            igjj",
      "            igjj",
      "            igjj",
      "            igjj"
    ]
  ]
}