{
  "name": "multi_verticalschool_2_floor23",
  "refpalette": "deceasedcraft:multi_verticalschool_2/multi_verticalschool_2_floor23_palette",
  "xsize": 16,
  "zsize": 16,
  "slices": [
    [
      "           a    ",
      "           ab   ",
      "           ab   ",
      "           ab   ",
      "           ab   ",
      "           a    ",
      "           ab   ",
      "           ab   ",
      "           ab   ",
      "           ab   ",
      "           a    ",
      "           ab   ",
      "           ab   ",
      "           ab   ",
      "           ab   ",
      "           a    "
    ],
    [
      "           acdee",
      "           acdee",
      "           acdee",
      "           acdee",
      "           acdee",
      "           acdee",
      "           acdee",
      "           acdee",
      "           acdee",
      "           acdee",
      "           acdee",
      "           acdee",
      "           acdee",
      "           acdee",
      "           acdee",
      "           acdee"
    ],
    [
      "           aafaa",
      "           aafaa",
      "           aafaa",
      "           aafaa",
      "           aafaa",
      "           aafaa",
      "           aafaa",
      "           aafaa",
      "           aafaa",
      "           aafaa",
      "           aafaa",
      "           aafaa",
      "           aafaa",
      "           aafaa",
      "           aafaa",
      "           aafaa"
    ],
    [
      "           g   g",
      "           g   g",
      "           g   g",
      "           g   g",
      "           g   g",
      "           g   g",
      "           g   g",
      "           g   g",
      "           g   g",
      "           g   g",
      "           g   g",
      "           g   g",
      "           g   g",
      "           g   g",
      "           g   g",
      "           g   g"
    ],
    [
      "                ",
      "                ",
      "                ",
      "                ",
      "                ",
      "                ",
      "                ",
      "                ",
      "                ",
      "                ",
      "                ",
      "                ",
      "                ",
      "                ",
      "                ",
      "                "
    ],
    [
      "                ",
      "                ",
      "                ",
      "                ",
      "                ",
      "                ",
      "                ",
      "                ",
      "                ",
      "                ",
      "                ",
      "                ",
      "                ",
      "                ",
      "                ",
      "                "
    ]
  ]
}