{
  "name": "multi_verticalschool_2_floor4",
  "refpalette": "deceasedcraft:multi_verticalschool_2/multi_verticalschool_2_floor4_palette",
  "xsize": 16,
  "zsize": 16,
  "slices": [
    [
      "             ab ",
      "             ab ",
      "             ab ",
      "             ab ",
      "             ab ",
      "             ab ",
      "             ab ",
      "             ab ",
      "             ab ",
      "             ab ",
      "             ab ",
      "             ab ",
      "             ab ",
      "             ab ",
      "             ab ",
      "             ab "
    ],
    [
      "                ",
      "              c ",
      "              c ",
      "              c ",
      "              c ",
      "              c ",
      "              c ",
      "              c ",
      "              c ",
      "              c ",
      "              c ",
      "              c ",
      "              c ",
      "              c ",
      "              c ",
      "                "
    ],
    [
      "                ",
      "                ",
      "                ",
      "                ",
      "                ",
      "                ",
      "                ",
      "                ",
      "                ",
      "                ",
      "                ",
      "                ",
      "                ",
      "                ",
      "                ",
      "                "
    ],
    [
      "                ",
      "                ",
      "                ",
      "                ",
      "                ",
      "                ",
      "                ",
      "                ",
      "                ",
      "                ",
      "                ",
      "                ",
      "                ",
      "                ",
      "                ",
      "                "
    ],
    [
      "                ",
      "                ",
      "                ",
      "                ",
      "                ",
      "                ",
      "                ",
      "                ",
      "                ",
      "                ",
      "                ",
      "                ",
      "                ",
      "                ",
      "                ",
      "                "
    ],
    [
      "     deefeeefeee",
      "     deefeeefeee",
      "     deefeeefeee",
      "     deefeeefeee",
      "     deefeeefeee",
      "     deefeeefeee",
      "     deefeeefeee",
      "     deefeeefeee",
      "     deefeeefeee",
      "     deefeeefeee",
      "     deefeeefeee",
      "     deefeeefeee",
      "     deefeeefeee",
      "     deefeeefeee",
      "     deefeeefeee",
      "     deefeeefeee"
    ]
  ]
}