{
  "name": "multi_verticalschool_2_floor19",
  "refpalette": "deceasedcraft:multi_verticalschool_2/multi_verticalschool_2_floor19_palette",
  "xsize": 16,
  "zsize": 16,
  "slices": [
    [
      "             a  ",
      "             a  ",
      "             a  ",
      "             a  ",
      "             a  ",
      "             a  ",
      "             a  ",
      "             a  ",
      "             a  ",
      "             a  ",
      "             a  ",
      "             a  ",
      "             a  ",
      "             a  ",
      "             a  ",
      "             ab "
    ],
    [
      "             a  ",
      "             a  ",
      "             a  ",
      "             a  ",
      "             a  ",
      "             a  ",
      "             a  ",
      "             a  ",
      "             a  ",
      "             a  ",
      "             a  ",
      "             a  ",
      "             a  ",
      "             a  ",
      "             a  ",
      "             a  "
    ],
    [
      "            cadd",
      "            cadd",
      "            cadd",
      "            cadd",
      "            cadd",
      "            cadd",
      "            cadd",
      "            cadd",
      "            cadd",
      "            cadd",
      "            cadd",
      "            cadd",
      "            cadd",
      "            cadd",
      "            cadd",
      "            cadd"
    ],
    [
      "            efgg",
      "            efgg",
      "            efgg",
      "            efgg",
      "            efgg",
      "            efgg",
      "            efgg",
      "            efgg",
      "            efgg",
      "            efgg",
      "            efhh",
      "            efhh",
      "            efhh",
      "            efhh",
      "            efhh",
      "            efhh"
    ],
    [
      "            if  ",
      "            if  ",
      "            if  ",
      "            if  ",
      "            if  ",
      "            if  ",
      "            if  ",
      "            if  ",
      "            if  ",
      "            if  ",
      "            ifjj",
      "            ifkl",
      "            ifml",
      "            ifkl",
      "            ifkl",
      "            ifml"
    ],
    [
      "             a  ",
      "             a  ",
      "             a  ",
      "             a  ",
      "             a  ",
      "             a  ",
      "             a  ",
      "             a  ",
      "             a  ",
      "             a  ",
      "             a  ",
      "             a  ",
      "             an ",
      "             a  ",
      "             a  ",
      "             an "
    ]
  ]
}