{
  "name": "multi_verticalschool_2_floor27",
  "refpalette": "deceasedcraft:multi_verticalschool_2/multi_verticalschool_2_floor27_palette",
  "xsize": 16,
  "zsize": 16,
  "slices": [
    [
      "            abcc",
      "            abcc",
      "            abcc",
      "            abcc",
      "            abcc",
      "            abcc",
      "            abcc",
      "            abcc",
      "            abcc",
      "            abcc",
      "            abcc",
      "            abcc",
      "            abcc",
      "            abcc",
      "            abcc",
      "            abcc"
    ],
    [
      "            db e",
      "            dbfe",
      "            dbfe",
      "            dbfe",
      "            dbfg",
      "            dbfe",
      "            dbfe",
      "            dbfe",
      "            dbfe",
      "            dbfe",
      "            dbfe",
      "            dbfe",
      "            dbfe",
      "            dbhe",
      "            dbhg",
      "            dbhe"
    ],
    [
      "             i j",
      "             i j",
      "             i j",
      "             i j",
      "             i  ",
      "             i j",
      "             i j",
      "             i j",
      "             i j",
      "             i j",
      "             i j",
      "             i  ",
      "             i j",
      "             i  ",
      "             i  ",
      "             i  "
    ],
    [
      "             i  ",
      "             i  ",
      "             i  ",
      "             i  ",
      "             i  ",
      "             i  ",
      "             i  ",
      "             i  ",
      "             i  ",
      "             i  ",
      "             i  ",
      "             i  ",
      "             i  ",
      "             i  ",
      "             i  ",
      "             i  "
    ],
    [
      "             i  ",
      "             i  ",
      "             i  ",
      "             i  ",
      "             i  ",
      "             i  ",
      "             i  ",
      "             i  ",
      "             i  ",
      "             i  ",
      "             i  ",
      "             i  ",
      "             i  ",
      "             i  ",
      "             i  ",
      "             i  "
    ],
    [
      "            kill",
      "            kill",
      "            kill",
      "            kill",
      "            kill",
      "            kill",
      "            kill",
      "            kill",
      "            kill",
      "            kill",
      "            kill",
      "            kill",
      "            kill",
      "            kill",
      "            kill",
      "            kill"
    ]
  ]
}