{
  "name": "multi_verticalschool_2_base2",
  "refpalette": "deceasedcraft:multi_verticalschool_2/multi_verticalschool_2_base2_palette",
  "xsize": 16,
  "zsize": 16,
  "slices": [
    [
      "vvvvvvvvvvvvvvvv",
      "vvvvvvvvvvvvvvvv",
      "vvvvvvvvvvvvvvvv",
      "vvvvvvvvvvvvvvvv",
      "vvvvvvvvvvvvvvvv",
      "vvvvvvvvvvvvvvvv",
      "vvvvvvvvvvvvvvvv",
      "vvvvvvvvvvvvvvvv",
      "vvvvvvvvvvvvvvvv",
      "vvvvvvvvvvvvvvvv",
      "vvvvvvvvvvvvvvvv",
      "vvvvvvvvvvvvvvvv",
      "vvvvvvvvvvvvvvvv",
      "vvvvvvvvvvvvvvvv",
      "vvvvvvvvvvvvvvvv",
      "vvvvvvvvvvvvvvvv"
    ],
    [
      "vaaaaaaaaaaaaaaa",
      "vaaaaaaaaaaaaaaa",
      "vaaaaaaaaaaaaaaa",
      "vaaaaaaaaaaaaaaa",
      "vaaaaaaaaaaaaaaa",
      "vaaaaaaaaaaaaaaa",
      "vaaaaaaaaaaaaaaa",
      "vaaaaaaaaaaaaaaa",
      "vaaaaaaaaaaaaaaa",
      "vaaaaaaaaaaaaaaa",
      "vaaaaaaaaaaaaaaa",
      "vaaaaaaaaaaaaaaa",
      "vaaaaaaaaaaaaaaa",
      "vaaaaaaaaaaaaaaa",
      "vaaaaaaaaaaaaaaa",
      "vaaaaaaaaaaaaaaa"
    ],
    [
      "vaaaaaaaaaaaaaaa",
      "vaaaaaaaaaaaaaaa",
      "vaaaaaaaaaaaaaaa",
      "vaaaaaaaaaaaaaaa",
      "vaaaaaaaaaaaaaaa",
      "vaaaaaaaaaaaaaaa",
      "vaaaaaaaaaaaaaaa",
      "vaaaaaaaaaaaaaaa",
      "vaaaaaaaaaaaaaaa",
      "vaaaaaaaaaaaaaaa",
      "vaaaaaaaaaaaaaaa",
      "vaaaaaaaaaaaaaaa",
      "vaaaaaaaaaaaaaaa",
      "vaaaaaaaaaaaaaaa",
      "vaaaaaaaaaaaaaaa",
      "vaaaaaaaaaaaaaaa"
    ],
    [
      "vbbbbccccccccccc",
      "vbbbbcdddddddddd",
      "vbbbbcdddddddddd",
      "vbbbbcdddddddddd",
      "vbbbbcdddddddddd",
      "vbbbbcdddddddddd",
      "vbbbbcdddddddddd",
      "vbbbbcdddddddddd",
      "vbbbbcdddddddddd",
      "vbbbbcdddddddddd",
      "vbbbbccccccccccc",
      "vbbbbcdddddddddd",
      "vbbbbcdddddddddd",
      "vbbbbcdddddddddd",
      "vbbbbcdddddddddd",
      "vbbbbcddcccccccc"
    ],
    [
      "v    ccccccccccc",
      "v   ecfgggfhijih",
      "v    c   k lmn l",
      "v         oilmjn",
      "v           n  o",
      "v               ",
      "v               ",
      "v               ",
      "v    c       p  ",
      "v   ecfqrsf fttt",
      "v    ccccccccccc",
      "v    u          ",
      "v    u     w    ",
      "v    u   xy AyA ",
      "v    u xBBBACCCC",
      "v    ccccccccccc"
    ],
    [
      "v    ccccccccccc",
      "v    cfD Df  i  ",
      "v    c     o   !",
      "v    u        i ",
      "v    u          ",
      "v    u          ",
      "v    u          ",
      "v    u          ",
      "v   Ec          ",
      "v    cfF  f fIJ ",
      "v   Kccccccccccc",
      "v    u          ",
      "v    u          ",
      "v    u          ",
      "v    u         A",
      "v    ccccccccccc"
    ]
  ]
}