{
  "name": "multi_verticalschool_2_floor18",
  "refpalette": "deceasedcraft:multi_verticalschool_2/multi_verticalschool_2_floor18_palette",
  "xsize": 16,
  "zsize": 16,
  "slices": [
    [
      "             a  ",
      "             a  ",
      "             a  ",
      "             a  ",
      "             a  ",
      "             a  ",
      "             a  ",
      "             a  ",
      "             a  ",
      "             a  ",
      "             a  ",
      "             a  ",
      "             ab ",
      "             a  ",
      "             a  ",
      "             a  "
    ],
    [
      "             a  ",
      "             a  ",
      "             a  ",
      "             a  ",
      "             a  ",
      "             a  ",
      "             a  ",
      "             a  ",
      "             a  ",
      "             a  ",
      "             a  ",
      "             a  ",
      "             a  ",
      "             a  ",
      "             a  ",
      "             a  "
    ],
    [
      "            cadd",
      "            cadd",
      "            cadd",
      "            cadd",
      "            cadd",
      "            cadd",
      "            cadd",
      "            cadd",
      "            cadd",
      "            cadd",
      "            cadd",
      "            cadd",
      "            cadd",
      "            cadd",
      "            cadd",
      "            cadd"
    ],
    [
      "            efgg",
      "            efgg",
      "            efgg",
      "            efgg",
      "            efgg",
      "            efgg",
      "            efgg",
      "            efgg",
      "            efgg",
      "            efgg",
      "            efhh",
      "            efhh",
      "            efhh",
      "            efhh",
      "            efhh",
      "            efhh"
    ],
    [
      "            if  ",
      "            if  ",
      "            if  ",
      "            if  ",
      "            if  ",
      "            if  ",
      "            if  ",
      "            if  ",
      "            if  ",
      "            if  ",
      "            ifjj",
      "            ifkl",
      "            ifml",
      "            ifkl",
      "            ifkn",
      "            ifml"
    ],
    [
      "             a  ",
      "             a  ",
      "             a  ",
      "             a  ",
      "             a  ",
      "             a  ",
      "             a  ",
      "             a  ",
      "             a  ",
      "             a  ",
      "             a  ",
      "             a  ",
      "             ao ",
      "             a  ",
      "             a  ",
      "             ao "
    ]
  ]
}