{
  "name": "multi_verticalschool_2_floor9",
  "refpalette": "deceasedcraft:multi_verticalschool_2/multi_verticalschool_2_floor9_palette",
  "xsize": 16,
  "zsize": 16,
  "slices": [
    [
      "        aaa  bcc",
      "         a  bccc",
      "            bccc",
      "            bccc",
      "            bccc",
      "        aaa bccc",
      "         a  bccc",
      "            bccc",
      "            bccc",
      "            bccc",
      "        aa  bccc",
      "         a  bccc",
      "            bccc",
      "            bccc",
      "         a  bccc",
      "        aaa bccc"
    ],
    [
      "         aa  b  ",
      "         a  b   ",
      "            b   ",
      "            b   ",
      "            b   ",
      "        aa  b   ",
      "         a  b   ",
      "            b   ",
      "            b   ",
      "         a  b   ",
      "        aaa b   ",
      "         a  b   ",
      "            b   ",
      "            b   ",
      "         a  b   ",
      "        aaa b   "
    ],
    [
      "         aa  b  ",
      "            b   ",
      "            b   ",
      "            b   ",
      "         a  b   ",
      "        aa  b   ",
      "            b   ",
      "            b   ",
      "            b   ",
      "         a  b   ",
      "         aa b   ",
      "         a  b   ",
      "            b   ",
      "            b   ",
      "            b   ",
      "         aa b   "
    ],
    [
      "         a   b  ",
      "            b   ",
      "            b   ",
      "            b   ",
      "            b   ",
      "         a  b   ",
      "          ~ b   ",
      "            b   ",
      "            b   ",
      "         a  b   ",
      "         a  b   ",
      "            b   ",
      "            b   ",
      "            b   ",
      "            b   ",
      "         a  b   "
    ],
    [
      "             bde",
      "          ~ bdee",
      "            bdee",
      "            bdee",
      "            bdee",
      "            bdee",
      "            bdee",
      "            bdee",
      "            bdee",
      "            bdee",
      "         a  bdee",
      "          ~ bdee",
      "            bdee",
      "            bdee",
      "            bdee",
      "            bdee"
    ],
    [
      "             bfg",
      "            bfgg",
      "            bfgg",
      "            bfgg",
      "            bfgg",
      "            bfgg",
      "            bfhh",
      "            bfhh",
      "            bfhh",
      "            bfhh",
      "            bfhh",
      "            bfhh",
      "            bfhh",
      "            bfhh",
      "            bfhh",
      "            bfhh"
    ]
  ]
}