{
  "name": "multi_verticalschool_2_floor3",
  "refpalette": "deceasedcraft:multi_verticalschool_2/multi_verticalschool_2_floor3_palette",
  "xsize": 16,
  "zsize": 16,
  "slices": [
    [
      "             a  ",
      "             a  ",
      "             a  ",
      "             a  ",
      "             a  ",
      "             a  ",
      "             a  ",
      "             a  ",
      "             a  ",
      "             a  ",
      "             a  ",
      "             a  ",
      "             a  ",
      "             a  ",
      "             a  ",
      "             a  "
    ],
    [
      "             a  ",
      "             a  ",
      "             a  ",
      "             a  ",
      "             a  ",
      "             a  ",
      "             a  ",
      "             a  ",
      "             a  ",
      "             a  ",
      "             a  ",
      "             a  ",
      "             a  ",
      "             a  ",
      "             a  ",
      "             a  "
    ],
    [
      "             a  ",
      "             a  ",
      "             a  ",
      "             a  ",
      "             a  ",
      "             a  ",
      "             a  ",
      "             a  ",
      "             a  ",
      "             a  ",
      "             a  ",
      "             a  ",
      "             a  ",
      "             a  ",
      "             a  ",
      "             a  "
    ],
    [
      "            ba  ",
      "            ba  ",
      "            ba  ",
      "            ba  ",
      "            ba  ",
      "            ba  ",
      "            ba  ",
      "            ba  ",
      "            ba  ",
      "            ba  ",
      "            ba  ",
      "            ba  ",
      "            ba  ",
      "            ba  ",
      "            ba  ",
      "            ba  "
    ],
    [
      "            cdef",
      "            cdee",
      "            cdee",
      "            cdee",
      "            cdee",
      "            cdef",
      "            cdee",
      "            cdee",
      "            cdee",
      "            cdee",
      "            cdef",
      "            cdee",
      "            cdee",
      "            cdee",
      "            cdee",
      "            cdef"
    ],
    [
      "            gdhi",
      "            gdhi",
      "            gdhi",
      "            gdhi",
      "            gdhi",
      "            gdhi",
      "            gdhi",
      "            gdhi",
      "            gdhi",
      "            gdhi",
      "            gdhj",
      "            gdhi",
      "            gdhi",
      "            gdhi",
      "            gdhi",
      "            gdhi"
    ]
  ]
}