{
  "name": "multi_verticalschool_2_floor14",
  "refpalette": "deceasedcraft:multi_verticalschool_2/multi_verticalschool_2_floor14_palette",
  "xsize": 16,
  "zsize": 16,
  "slices": [
    [
      "     ab         ",
      "     abc        ",
      "     ab         ",
      "     ab         ",
      "     ab         ",
      "     ab         ",
      "     ab         ",
      "     ab         ",
      "     abc        ",
      "     ab         ",
      "     ab     dddd",
      "     ab    de e ",
      "     ab    df f ",
      "     ab    d    ",
      "     ab    d    ",
      "     abc   ddggd"
    ],
    [
      "     ab         ",
      "     ab         ",
      "     ab         ",
      "     ab         ",
      "     ab         ",
      "     ab         ",
      "     ab         ",
      "     ab         ",
      "     ab         ",
      "     ab         ",
      "     ab     dddd",
      "     ab    dhhhh",
      "     ab    di j ",
      "     ab    d    ",
      "     ab    d    ",
      "     ab    ddddd"
    ],
    [
      "     ab         ",
      "     ab         ",
      "     ab         ",
      "     ab         ",
      "     ab         ",
      "     ab         ",
      "     ab         ",
      "     ab         ",
      "     ab         ",
      "     ab         ",
      "     ab     dddd",
      "     ab    d    ",
      "     ab    d    ",
      "     ab    d    ",
      "     ab    d    ",
      "     ab    ddddd"
    ],
    [
      "     ab         ",
      "     ab         ",
      "     ab         ",
      "     ab         ",
      "     ab         ",
      "     ab         ",
      "     ab         ",
      "     ab         ",
      "     ab         ",
      "     ab         ",
      "     ab     dddd",
      "     ab    d    ",
      "     ab    d    ",
      "     ab    d    ",
      "     ab    d    ",
      "     ab    ddddd"
    ],
    [
      "     abkllllllll",
      "     abkllllllll",
      "     abkllllllll",
      "     abkllllllll",
      "     abkllllllll",
      "     abkllllllll",
      "     abkllllllll",
      "     abkllllllll",
      "     abkllllllll",
      "     abkllllllll",
      "     abklllldddd",
      "     abkllldmmmm",
      "     abkllldmnmn",
      "     abkllldmnmn",
      "     abkllldmmmm",
      "     abklllddddd"
    ],
    [
      "     abboppppppp",
      "     abboppppppp",
      "     abboppppppp",
      "     abboppppppp",
      "     abboppppppp",
      "     abboppppppp",
      "     abboppppppp",
      "     abboppppppp",
      "     abboppppppp",
      "     abboppppppp",
      "     abboppppppp",
      "     abboppppppp",
      "     abboppppppp",
      "     abboppppppp",
      "     abboppppppp",
      "     abboppppppp"
    ]
  ]
}