{
  "name": "multi_verticalschool_2_floor6",
  "refpalette": "deceasedcraft:multi_verticalschool_2/multi_verticalschool_2_floor6_palette",
  "xsize": 16,
  "zsize": 16,
  "slices": [
    [
      "     a          ",
      "     a          ",
      "     a          ",
      "     a          ",
      "     a          ",
      "     a          ",
      "     a          ",
      "     a          ",
      "     a          ",
      "     a          ",
      "     a          ",
      "     a          ",
      "     a          ",
      "     a          ",
      "     a          ",
      "     a          "
    ],
    [
      "     abc       d",
      "     abc       d",
      "     abc       d",
      "     abc       d",
      "     abc       d",
      "     abc       d",
      "     abc       d",
      "     abc       d",
      "     abc       d",
      "     abc       d",
      "     abc       d",
      "     abc       d",
      "     abc       d",
      "     abc       d",
      "     abc       d",
      "     abc       d"
    ],
    [
      "     aaefffffffe",
      "     aaefffffffe",
      "     aaefffffffe",
      "     aaefffffffe",
      "     aaefffffffe",
      "     aaefffffffe",
      "     aaefffffffe",
      "     aaefffffffe",
      "     aaefffffffe",
      "     aaefffffffe",
      "     aaefffffffe",
      "     aaefffffffe",
      "     aaefffffffe",
      "     aaefffffffe",
      "     aaefffffffe",
      "     aaefffffffe"
    ],
    [
      "     g          ",
      "     g          ",
      "     g          ",
      "     g          ",
      "     g          ",
      "     g          ",
      "     g          ",
      "     g          ",
      "     g          ",
      "     g          ",
      "     g          ",
      "     g          ",
      "     g          ",
      "     g          ",
      "     g          ",
      "     g          "
    ],
    [
      "                ",
      "                ",
      "                ",
      "                ",
      "                ",
      "                ",
      "                ",
      "                ",
      "                ",
      "                ",
      "                ",
      "                ",
      "                ",
      "                ",
      "                ",
      "                "
    ],
    [
      "                ",
      "                ",
      "                ",
      "                ",
      "                ",
      "                ",
      "                ",
      "                ",
      "                ",
      "                ",
      "                ",
      "                ",
      "                ",
      "                ",
      "                ",
      "                "
    ]
  ]
}