{
  "name": "multi_verticalschool_2_floor13",
  "refpalette": "deceasedcraft:multi_verticalschool_2/multi_verticalschool_2_floor13_palette",
  "xsize": 16,
  "zsize": 16,
  "slices": [
    [
      "                ",
      "                ",
      "             abb",
      "            cdee",
      "             d  ",
      "                ",
      "                ",
      "                ",
      "                ",
      "                ",
      "                ",
      "                ",
      "                ",
      "                ",
      "                ",
      "                "
    ],
    [
      "                ",
      "             abb",
      "            cdee",
      "             d  ",
      "                ",
      "                ",
      "                ",
      "                ",
      "                ",
      "                ",
      "                ",
      "                ",
      "                ",
      "                ",
      "                ",
      "                "
    ],
    [
      "      f ghgggabb",
      "      f ghgggdee",
      "      f ghgggd  ",
      "      f ghggg   ",
      "      f ghggg   ",
      "      f ghggg   ",
      "      f ghgggggg",
      "      f ghgggggg",
      "      f ghgggggg",
      "      f ghgggggg",
      "      f ghgggggg",
      "      f ghgggggg",
      "      f ghgggggg",
      "      f ghgggggg",
      "      f ghgggggg",
      "      f ghgggggg"
    ],
    [
      "     ijkllllldmm",
      "     ijkllllld  ",
      "     ijklllll   ",
      "     ijklllll   ",
      "     ijklllll   ",
      "     ijklllll   ",
      "     ijkllllllll",
      "     ijkllllllll",
      "     ijkllllllll",
      "     ijkllllllll",
      "     ijkllllaaaa",
      "     ijklllakkkk",
      "     ijklllakkkk",
      "     ijklllakkkk",
      "     ijklllakkkk",
      "     ijklllaaaaa"
    ],
    [
      "     ij     nd  ",
      "     ijo    n   ",
      "     ij     n   ",
      "     ij     n   ",
      "     ij     n   ",
      "     ij     nppp",
      "     ij         ",
      "     ij         ",
      "     ijo        ",
      "     ij         ",
      "     ij     aaaa",
      "     ij    aq q ",
      "     ij    aq q ",
      "     ij    a    ",
      "     ij    a    ",
      "     ijo   aarsa"
    ],
    [
      "     ij         ",
      "     ijt        ",
      "     ij         ",
      "     ij         ",
      "     iu         ",
      "     iu         ",
      "     ij         ",
      "     ij         ",
      "     ijt        ",
      "     ij         ",
      "     ij     aaaa",
      "     iu    aw w ",
      "     iu    ax x ",
      "     ij    a    ",
      "     ij    a    ",
      "     ijt   aayAa"
    ]
  ]
}