{
  "name": "multi_verticalschool_2_floor29",
  "refpalette": "deceasedcraft:multi_verticalschool_2/multi_verticalschool_2_floor29_palette",
  "xsize": 16,
  "zsize": 16,
  "slices": [
    [
      "            abcc",
      "            abcc",
      "            abcc",
      "            abcc",
      "            abcc",
      "            abcc",
      "            abcc",
      "            abcc",
      "            abcc",
      "            abcc",
      "            abcc",
      "            abcc",
      "            abcc",
      "            abcc",
      "            abcc",
      "            abcc"
    ],
    [
      "            dbef",
      "            dbef",
      "            dbef",
      "            dbeg",
      "            db f",
      "            dbhf",
      "            dbef",
      "            dbhf",
      "            dbhf",
      "            dbef",
      "            dbef",
      "            dbef",
      "            dbef",
      "            dbef",
      "            dbef",
      "            db g"
    ],
    [
      "             i j",
      "             i j",
      "             i j",
      "             i  ",
      "             i j",
      "             i j",
      "             i j",
      "             i j",
      "             i j",
      "             i j",
      "             i  ",
      "             i j",
      "             i j",
      "             i j",
      "             i  ",
      "             i  "
    ],
    [
      "             i  ",
      "             i  ",
      "             i  ",
      "             i  ",
      "             i  ",
      "             i  ",
      "             i  ",
      "             i  ",
      "             i  ",
      "             i  ",
      "             i  ",
      "             i  ",
      "             i  ",
      "             i  ",
      "             i  ",
      "             i  "
    ],
    [
      "             i  ",
      "             i  ",
      "             i  ",
      "             i  ",
      "             i  ",
      "             i  ",
      "             i  ",
      "             i  ",
      "             i  ",
      "             i  ",
      "             i  ",
      "             i  ",
      "             i  ",
      "             i  ",
      "             i  ",
      "             i  "
    ],
    [
      "            kill",
      "            kill",
      "            kill",
      "            kill",
      "            kill",
      "            kill",
      "            kill",
      "            kill",
      "            kill",
      "            kill",
      "            kill",
      "            kill",
      "            kill",
      "            kill",
      "            kill",
      "            kill"
    ]
  ]
}