{
  "name": "multi_courtyardofficetower_7_base1",
  "refpalette": "deceasedcraft:multi_courtyardofficetower_7/multi_courtyardofficetower_7_base1_palette",
  "xsize": 16,
  "zsize": 16,
  "slices": [
    [
      "vvvvvvvvaaaaaaaa",
      "vvvvvvvvvvvvaaaa",
      "vvvvvvvvvvvvaaaa",
      "vvvvvvvvvvvvaaaa",
      "vvvvvvvvvvvvaaaa",
      "vvvvvvvvvvvvaaaa",
      "vvvvvvvvvvvvaaaa",
      "aaavvvvvvvvvaaaa",
      "aaaaaaaaaaavaaaa",
      "aaaaaaaaaaaaaaaa",
      "aaaaaaaaaaaaaaaa",
      "aaaaaaaaaaaaaaaa",
      "aaaaaaaaaaaaaaaa",
      "aaaaaaaaaaaaaaaa",
      "aaaaaaaaaaaaaaaa",
      "vvvvvvvvvvvvvvvv"
    ],
    [
      "vvvvvvvvaaaaaaaa",
      "bbbbbbbbvvvvvvva",
      "HHHHHHHbbbbbvvva",
      "HHHHHHHHHHHHvvva",
      "HHHHHHHHHHHHvvva",
      "bbbbHHHHHHHHvvva",
      "vvvbbbbbbbbbvvva",
      "aaavvvvvvvvbvvva",
      "aaaaaaaaaaavvvva",
      "aaaaaaaaaaaaaaaa",
      "aaaaaaaaaaaaaaaa",
      "aaaaaaaaaaaaaaaa",
      "aaaaaaaaaaaaaaaa",
      "aaaaaaaaaaaaaaaa",
      "aaaaaaaaaaaaaaaa",
      "vvvvvvvvvvvvvvvv"
    ],
    [
      "vvvvvvvvaaaaaaaa",
      "        vvvvvvvv",
      "           cdbbv",
      "           efHHv",
      "           efHHv",
      "           efHHv",
      "vvv        cfHHv",
      "aaavvvvvvvvcdbbv",
      "aaaaaaaaaaavvvvv",
      "aaaaaaaaaaaaaaaa",
      "aaaaaaaaaaaaaaaa",
      "aaaaaaaaaaaaaaaa",
      "aaaaaaaaaaaaaaaa",
      "aaaaaaaaaaaaaaaa",
      "aaaaaaaaaaaaaaaa",
      "vvvvvvvvvvvvvvvv"
    ],
    [
      "vvvvvvvvaaaaaaaa",
      "        vvvvvvvv",
      "              cd",
      "              ed",
      "              ef",
      "              ef",
      "vvv           ef",
      "aaavvvvvvvv   cd",
      "aaaaaaaaaaavvvvv",
      "aaaaaaaaaaaaaaaa",
      "aaaaaaaaaaaaaaaa",
      "aaaaaaaaaaaaaaaa",
      "aaaaaaaaaaaaaaaa",
      "aaaaaaaaaaaaaaaa",
      "aaaaaaaaaaaaaaaa",
      "vvvvvvvvvvvvvvvv"
    ],
    [
      "vvvvvvvvaaaaaaaa",
      "        vvvvvvvv",
      "                ",
      "                ",
      "                ",
      "                ",
      "vvv             ",
      "aaavvvvvvvv     ",
      "aaaaaaaaaaavvvvv",
      "aaaaaaaaaaaaaaaa",
      "aaaaaaaaaaaaaaaa",
      "aaaaaaaaaaaaaaaa",
      "aaaaaaaaaaaaaaaa",
      "aaaaaaaaaaaaaaaa",
      "aaaaaaaaaaaaaaaa",
      "vvvvvvvvvvvvvvvv"
    ],
    [
      "vvvvvvvvaaaaaaaa",
      "ggggggggvvvvvvvv",
      "ggggggggggg     ",
      "ggggggggggg     ",
      "ggggggggggg     ",
      "ggggggggggg     ",
      "vvvgggggggg     ",
      "aaavvvvvvvv     ",
      "aaaaaaaaaaavvvvv",
      "aaaaaaaaaaaaaaaa",
      "aaaaaaaaaaaaaaaa",
      "aaaaaaaaaaaaaaaa",
      "aaaaaaaaaaaaaaaa",
      "aaaaaaaaaaaaaaaa",
      "aaaaaaaaaaaaaaaa",
      "vvvvvvvvvvvvvvvv"
    ]
  ]
}