{
  "name": "multi_courtyardofficetower_7_ground",
  "refpalette": "deceasedcraft:multi_courtyardofficetower_7/multi_courtyardofficetower_7_ground_palette",
  "xsize": 16,
  "zsize": 16,
  "slices": [
    [
      "aaaaaaaaaaaaaaaa",
      "aaaaaaaaaaabbbbb",
      "aaaaaaaaaaabc   ",
      "aaaaaadaaaabc   ",
      "aaaaaaaaaaabc   ",
      "aaaaaaaaaaabc   ",
      "aaaaaaaaaaabc   ",
      "aaaaaaaaaaabc   ",
      "aaaaaaaaaaabbbbb",
      "aaaaaaaaaaaaaaaa",
      "aaaaaaaaaaaaaaaa",
      "aaaaaaaaaaaaaaaa",
      "aaaaaaaaaaaaaaaa",
      "aaaaaaaaaaaaaaaa",
      "aaaaaaaaaaaaaaaa",
      "aaaaaaaaaaaaaaaa"
    ],
    [
      "e               ",
      "    ee e e fffff",
      " e e   ee  f    ",
      " e   eg    f    ",
      "  e   ee e f    ",
      "e       e  f    ",
      "     ee    f    ",
      "eee        f    ",
      "  eeeeeeeeefffff",
      "       e  eeeeee",
      " e   e          ",
      "e  e  h   e   eh",
      "   h     e      ",
      " h       h e h  ",
      "     h          ",
      "     e          "
    ],
    [
      "                ",
      "                ",
      "       e        ",
      "      g         ",
      "                ",
      "                ",
      "                ",
      "                ",
      "                ",
      "                ",
      "                ",
      "      i        i",
      "   i            ",
      " i       i   i  ",
      "     i          ",
      "                "
    ],
    [
      "                ",
      "                ",
      "      j         ",
      "     jgj        ",
      "      j         ",
      "                ",
      "                ",
      "                ",
      "                ",
      "                ",
      "                ",
      "      e        e",
      "   e            ",
      " e       e   e  ",
      "     e          ",
      "                "
    ],
    [
      "                ",
      "     kkk        ",
      "    kkkkk       ",
      "    kkgkk       ",
      "    kkkkk       ",
      "     kkk        ",
      "                ",
      "                ",
      "                ",
      "                ",
      "                ",
      "      e        e",
      "   e            ",
      " e       e   e  ",
      "     e          ",
      "                "
    ],
    [
      "e               ",
      "                ",
      "     jkj        ",
      "     kgk        ",
      "     jkj        ",
      "                ",
      "                ",
      "                ",
      "                ",
      "                ",
      "                ",
      "      e        e",
      "   e            ",
      " e       e   e  ",
      "     e          ",
      "                "
    ]
  ]
}