{
  "name": "multi_sunkenclub_2_base2",
  "refpalette": "deceasedcraft:multi_sunkenclub_2/multi_sunkenclub_2_base2_palette",
  "xsize": 16,
  "zsize": 16,
  "slices": [
    [
      "vvvvvvvvvvvvvvvv",
      "vvvvvvvvvvvvvvvv",
      "vvvvvvvvvvvvvvvv",
      "vvvvvvvaaaaaaaaa",
      "vvvvvvvaaaaaaaaa",
      "vvvvvvvaaaaaaaaa",
      "vvvvvvvaaaaaaaaa",
      "vvvvvvvaaaaaaaaa",
      "vvvvvvvaaaaaaaaa",
      "vvvvvvvvvvvvvvvv",
      "vvvvvvvvvvvvvvvv",
      "vvvvvvvvvvvvvvvv",
      "vvvvvvvvvvvvvvvv",
      "vvvvvvvvvvvvvvvv",
      "vvvvvvvvvvvvvvvv",
      "vvvvvvvvvvvvvvvv"
    ],
    [
      "vbbbbbbccccccbbb",
      "vbbbbbbccccccbbb",
      "vbbbbbdaaaaaadaa",
      "vbbbbbaefefeffef",
      "vbbbbbafeffffeff",
      "vbbbbbaeffefffff",
      "vbbbbbafeffffffe",
      "vbbbbbaegffeffff",
      "vbbbbbafffeffefe",
      "vbbbbbdaaaaaadaa",
      "vbbbbhibijhiklll",
      "vbbbbbihijilikll",
      "vbbbbbbbbbbbbbbb",
      "vbbbkkmkkkkkknkk",
      "vbbboopoooooopoo",
      "vvvvvvvvvvvvvvvv"
    ],
    [
      "vbbb qrstuwwwxqy",
      "vbbb  rwwwwwwxqq",
      "vbbb  dAAAAAAd  ",
      "vbbb            ",
      "vbbb   B  B     ",
      "vbbb    B       ",
      "vbbbC  B     B  ",
      "vbbb     BB     ",
      "vbbb C B B B    ",
      "vbbb  d      d  ",
      "vbbb    DE      ",
      "vbbb    DE      ",
      "vbbbFIJJJFJIJJJF",
      "vbbb K  KKKKK KK",
      "vbbbLMpMMMMMMpMM",
      "vvvvvvvvvvvvvvvv"
    ],
    [
      "vbbb  r      x N",
      "vbbb  r      x  ",
      "vbbb  d      d  ",
      "vbbb            ",
      "vbbb            ",
      "vbbb            ",
      "vbbb            ",
      "vbbb            ",
      "vbbb            ",
      "vbbb  d      d  ",
      "vbbb   DE       ",
      "vbbb   DE       ",
      "vbbb            ",
      "vbbb O  OOOOO OO",
      "vbbbLMpMMLMMMpMM",
      "vvvvvvvvvvvvvvvv"
    ],
    [
      "vbbb  P      Q  ",
      "vbbb  P      Q  ",
      "vbbb  d      d  ",
      "vbbb            ",
      "vbbb            ",
      "vbbb            ",
      "vbbb            ",
      "vbbb            ",
      "vbbb            ",
      "vbbb  d      d  ",
      "vbbb  DE        ",
      "vbbb  DE        ",
      "vbbb            ",
      "vbbb            ",
      "vbbbMMpMMLMMMpMM",
      "vvvvvvvvvvvvvvvv"
    ],
    [
      "vbbb  R      R  ",
      "vbbb  R      R  ",
      "vbbb  dRRRRRRd  ",
      "vbbb            ",
      "vbbb            ",
      "vbbb            ",
      "vbbb            ",
      "vbbb            ",
      "vbbb            ",
      "vbbb  d      d  ",
      "vbbb DE         ",
      "vbbb DE         ",
      "vbbb            ",
      "vbbb            ",
      "vbbb MpM LM MpLM",
      "vvvvvvvvvvvvvvvv"
    ]
  ]
}