{
  "name": "multi_filmworkstower_18_floor1",
  "refpalette": "deceasedcraft:multi_filmworkstower_18/multi_filmworkstower_18_floor1_palette",
  "xsize": 16,
  "zsize": 16,
  "slices": [
    [
      "                ",
      "                ",
      "                ",
      "                ",
      "                ",
      "                ",
      "                ",
      "                ",
      "                ",
      "         ab     ",
      "                ",
      "   c            ",
      "  dd            ",
      "                ",
      "                ",
      "                "
    ],
    [
      "                ",
      "                ",
      "                ",
      "                ",
      "                ",
      "                ",
      "                ",
      "                ",
      "                ",
      "          ab    ",
      "                ",
      "                ",
      "   d            ",
      "                ",
      "                ",
      "                "
    ],
    [
      "                ",
      "                ",
      "                ",
      "                ",
      "                ",
      "                ",
      "                ",
      "                ",
      "                ",
      "           abe  ",
      "                ",
      "                ",
      "                ",
      "                ",
      "                ",
      "                "
    ],
    [
      "                ",
      "                ",
      "                ",
      "                ",
      "                ",
      "                ",
      "                ",
      "                ",
      "                ",
      "eeeeeeeeeeefggge",
      "                ",
      "                ",
      "                ",
      "                ",
      "                ",
      "                "
    ],
    [
      "                ",
      "                ",
      "                ",
      "                ",
      "                ",
      "                ",
      "                ",
      "                ",
      "                ",
      "gggggggggggggggg",
      "                ",
      "   h       h    ",
      "                ",
      "                ",
      "   h       h    ",
      "                "
    ],
    [
      "                ",
      "                ",
      "                ",
      "                ",
      "                ",
      "                ",
      "                ",
      "iiiiiiiiiiiiiiii",
      "jjjjjjjjjjjjjjjj",
      "gggggggggggggggg",
      "jjjjjjjjjjjjjjjj",
      "kkkkkkkkkkkkkkkk",
      "jjjjjjjjjjjjjjjj",
      "jjjjjjjjjjjjjjjj",
      "kkkkkkkkkkkkkkkk",
      "jjjjjjjjjjjjjjjj"
    ]
  ]
}