{
  "name": "multi_filmworkstower_18_ground",
  "refpalette": "deceasedcraft:multi_filmworkstower_18/multi_filmworkstower_18_ground_palette",
  "xsize": 16,
  "zsize": 16,
  "slices": [
    [
      "HaaaaaaHHHHHHHHH",
      "HHHHHHHHHHHHHHHH",
      "HHHHHHHHHHHHHHHH",
      "HHHHHHHHHHHHHHHH",
      "HHHHHHHHHHHHHHHH",
      "HaaaaaaHHHHHHHHH",
      "abbbbbbaHHHHHHHH",
      "bbccccbbaHHHHHHH",
      "bccccccbbaHHHHHH",
      "ccccd ccbaHHHHHH",
      "ccccccccbaHHHHHH",
      "ccccccccbaHHHHHH",
      "ccccccccbaHHHHHH",
      "ccccccccbaHHHHHH",
      "eeeeeeeebaHHHHHH",
      "ffffffffbaHHHHHH"
    ],
    [
      "                ",
      "                ",
      "              gh",
      "               i",
      "                ",
      "              jk",
      " llllll       gh",
      "llmmmmll        ",
      "lm    mll       ",
      "m   no ml     jk",
      "m      ml       ",
      "m      ml       ",
      "m  p   ml       ",
      "m      ml       ",
      "              gh",
      "                "
    ],
    [
      "                ",
      "                ",
      "                ",
      "                ",
      "                ",
      "                ",
      "                ",
      "                ",
      "                ",
      "     no         ",
      "                ",
      "                ",
      "   q            ",
      "                ",
      "                ",
      "                "
    ],
    [
      "                ",
      "                ",
      "                ",
      "                ",
      "                ",
      "                ",
      "                ",
      "                ",
      "                ",
      "      no        ",
      "                ",
      "                ",
      "   m            ",
      "                ",
      "                ",
      "                "
    ],
    [
      "                ",
      "                ",
      "                ",
      "                ",
      "                ",
      "                ",
      "                ",
      "                ",
      "                ",
      "       no       ",
      "                ",
      "   m            ",
      "   m            ",
      "   m            ",
      "                ",
      "                "
    ],
    [
      "                ",
      "                ",
      "                ",
      "                ",
      "                ",
      "                ",
      "                ",
      "                ",
      "                ",
      "        no      ",
      "                ",
      "   m            ",
      "  mmm           ",
      "   r            ",
      "                ",
      "                "
    ]
  ]
}