{
  "name": "multi_filmworkstower_18_base2",
  "refpalette": "deceasedcraft:multi_filmworkstower_18/multi_filmworkstower_18_base2_palette",
  "xsize": 16,
  "zsize": 16,
  "slices": [
    [
      "aaaaab          ",
      "aaaaab          ",
      "aaaaab          ",
      "aaaaab          ",
      "aaaaab          ",
      "aaaaab          ",
      "aaaaab          ",
      "aaaaab        cd",
      "aaaaab        ef",
      "aaaaab       fgg",
      "aaaaab       fhi",
      "aaaaab       ejj",
      "aaaaab      klff",
      "aaaaab       mnn",
      "aaaaab       mop",
      "aaaaab          "
    ],
    [
      "     b          ",
      "     b          ",
      "     b          ",
      "     b          ",
      "     b          ",
      "     b          ",
      "     b          ",
      "     b          ",
      "     b          ",
      "   qrb          ",
      "     b          ",
      "     b          ",
      "     b          ",
      "     b          ",
      "     b          ",
      "     b          "
    ],
    [
      "     b          ",
      "     b          ",
      "     b          ",
      "     b          ",
      "     b          ",
      "     b          ",
      "     b          ",
      "     b          ",
      "     b          ",
      "    rb          ",
      "     b          ",
      "     b          ",
      "     b          ",
      "     b          ",
      "     b          ",
      "     b          "
    ],
    [
      "     b          ",
      "     b          ",
      "     b          ",
      "     b          ",
      "     b          ",
      "     b          ",
      "     b          ",
      "     b          ",
      "    sb          ",
      "    rb          ",
      "    tb          ",
      "     b          ",
      "     b          ",
      "     b          ",
      "     b          ",
      "     b          "
    ],
    [
      "    ub          ",
      "    ub          ",
      "    ub          ",
      "    ub          ",
      "    ub          ",
      "    ub          ",
      "    ub          ",
      "    ub          ",
      "    ub          ",
      "   wrb          ",
      "    ub          ",
      "    ub          ",
      "    ub          ",
      "    ub          ",
      "    ub          ",
      "    ub          "
    ],
    [
      "     b          ",
      "     b          ",
      "     b          ",
      "     b          ",
      "     b          ",
      "     b          ",
      "     b          ",
      "     b          ",
      "     b          ",
      "x   rb          ",
      "     b          ",
      "     b          ",
      "     b          ",
      "     b          ",
      "     b          ",
      "     b          "
    ]
  ]
}