{
  "name": "multi_filmworkstower_18_base3",
  "refpalette": "deceasedcraft:multi_filmworkstower_18/multi_filmworkstower_18_base3_palette",
  "xsize": 16,
  "zsize": 16,
  "slices": [
    [
      "aaaabbbbbbbbbbbb",
      "aaaabbbbbbbbbbbb",
      "aaaabbbbbbbbbbbb",
      "aaaabbbbbbbbbbbb",
      "aaaabbbbbbbbbbbb",
      "aaaabbbbbbbbbbbb",
      "aaaabbbbbbbbbbbb",
      "aaaabbbbbbbbbbbb",
      "aaaabbbbbbbbbbbb",
      "aaaabbbbbbbbbbbb",
      "aaaabbbbbbbbbbbb",
      "aaaabbbbbbbbbbbb",
      "aaaabbbbbbbbbbbb",
      "aaaabbbbbbbbbbbb",
      "aaaabbbbbbbbbbbb",
      "aaaabbbbbbbbbbbb"
    ],
    [
      "aaaabcdddddddddd",
      "aaaabcdddddddddd",
      "aaaabcdddddddddd",
      "aaaabcdddddddddd",
      "aaaabcdddddddddd",
      "aaaabcddddddeddd",
      "aaaabcddddddeddd",
      "aaaabcfdfdddgddd",
      "aaaabcfdddddeddd",
      "aaaabcddddddeddd",
      "aaaabcddddddeddd",
      "aaaabcddddddeddd",
      "aaaabcddddddeddd",
      "aaaabcddddddeddd",
      "aaaabcddddfdeddd",
      "aaaabcddddddeddd"
    ],
    [
      "aaaabcddf f   f ",
      "aaaabcddff      ",
      "aaaabcdf h h    ",
      "aaaabcij f   k  ",
      "aaaabc        k ",
      "aaaabcf  h      ",
      "aaaabc      lmnn",
      "aaaabc     fom  ",
      "aaaabc      lmnn",
      "aaaabc   fp  mqq",
      "aaaabc      lmqr",
      "aaaabcij     mqq",
      "aaaabc f  h lmnn",
      "aaaabc          ",
      "aaaabc         s",
      "aaaabcf         "
    ],
    [
      "aaaabc t        ",
      "aaaabc t        ",
      "aaaabcut        ",
      "aaaabciw        ",
      "aaaabc t        ",
      "aaaabc t     xyy",
      "aaaabc t    ABBB",
      "aaaabc t   C DDE",
      "aaaabc t   CBDFI",
      "aaaabc t   CBDJK",
      "aaaabc t   CBb L",
      "aaaabciw   CBD M",
      "aaaabc t   CB  N",
      "aaaabc t   CyOmn",
      "aaaabc t    PsQR",
      "aaaabc t        "
    ],
    [
      "aaaabc S        ",
      "aaaabc S        ",
      "aaaabc S        ",
      "aaaabc S        ",
      "aaaabc T        ",
      "aaaabc U     VVW",
      "aaaabc S     XVX",
      "aaaabc S     YZ0",
      "aaaabc S    12  ",
      "aaaabc S    32  ",
      "aaaabc S    34 5",
      "aaaabc S    WY  ",
      "aaaabc S    V6O ",
      "aaaabc S    XB77",
      "aaaabc S    89##",
      "aaaabc S        "
    ],
    [
      "aaaabc          ",
      "aaaabc          ",
      "aaaabc         $",
      "aaaabc         $",
      "aaaabc %       ^",
      "aaaabc &       ^",
      "aaaabc         ^",
      "aaaabc        x*",
      "aaaabc       (  ",
      "aaaabc       )++",
      "aaaabc       ) -",
      "aaaabc       )++",
      "aaaabc       )  ",
      "aaaabc       BBB",
      "aaaabc       3[[",
      "aaaabc          "
    ]
  ]
}