{
  "name": "multi_filmworkstower_18_floor2",
  "refpalette": "deceasedcraft:multi_filmworkstower_18/multi_filmworkstower_18_floor2_palette",
  "xsize": 16,
  "zsize": 16,
  "slices": [
    [
      "                ",
      "                ",
      "                ",
      "                ",
      "                ",
      "                ",
      "aaaaaaaaaaaaaaaa",
      "bbbbbbbbbbbbbbbb",
      "cccccccccccccccc",
      "ddddddddddddddbe",
      "dddddddddddddddd",
      "dddddddddddddddd",
      "dddddddddddddddd",
      "dddddddddddddddd",
      "dddddddddddddddd",
      "dddddddddddddddd"
    ],
    [
      "                ",
      "                ",
      "                ",
      "                ",
      "                ",
      "ff              ",
      "aaaaaaaaaaaaaaaa",
      "gggggggggggggggg",
      "hhhhhhhhhhhhhhhh",
      "             ibj",
      "                ",
      "                ",
      "                ",
      "                ",
      "                ",
      "   kkkkk        "
    ],
    [
      "                ",
      "                ",
      "                ",
      "                ",
      "                ",
      "ff              ",
      "aaaaaaaaaaaaaaaa",
      "llllllllllllllll",
      "                ",
      " m nnnnn m  io p",
      "                ",
      "                ",
      "                ",
      "                ",
      "                ",
      "                "
    ],
    [
      "                ",
      "                ",
      "                ",
      "                ",
      "                ",
      "ff              ",
      "aaaaaaaaaaaaaaaa",
      "llllllllllllllll",
      "                ",
      " q rrrrr q io  s",
      "                ",
      "                ",
      "                ",
      "                ",
      "                ",
      "                "
    ],
    [
      "                ",
      "                ",
      "                ",
      "                ",
      "                ",
      "ff              ",
      "aaaaaaaaaaaaaaaa",
      "lllll  lllll lll",
      "                ",
      "tu wwwww uio   s",
      "                ",
      "                ",
      "                ",
      "                ",
      "                ",
      "                "
    ],
    [
      "                ",
      "                ",
      "                ",
      "                ",
      "                ",
      "ff              ",
      "aaaaaaaaaaaaaaaa",
      " ll l   ll l    ",
      "                ",
      "xt y   y io    s",
      "                ",
      "                ",
      "                ",
      "                ",
      "                ",
      "                "
    ]
  ]
}