{
  "name": "multi_filmworkstower_18_base1",
  "refpalette": "deceasedcraft:multi_filmworkstower_18/multi_filmworkstower_18_base1_palette",
  "xsize": 16,
  "zsize": 16,
  "slices": [
    [
      "     a          ",
      "     a          ",
      "     a          ",
      "     a          ",
      "     a          ",
      "     a          ",
      "     a          ",
      "     a          ",
      "     a          ",
      "b   ca          ",
      "     a          ",
      "     a          ",
      "     a          ",
      "     a          ",
      "     a          ",
      "     a          "
    ],
    [
      "     a          ",
      "     a          ",
      "     a          ",
      "     a          ",
      "     a          ",
      "     a          ",
      "     a          ",
      "     a          ",
      "    da          ",
      "be fca          ",
      "    ga          ",
      "     a          ",
      "     a          ",
      "     a          ",
      "     a          ",
      "     a          "
    ],
    [
      "    ha          ",
      "    ha          ",
      "    ha          ",
      "    ha          ",
      "    ha          ",
      "    ha          ",
      "    ha          ",
      "    ha          ",
      "    ha          ",
      "bbiica          ",
      "    ha          ",
      "    ha          ",
      "    ha          ",
      "    ha          ",
      "    ha          ",
      "    ha          "
    ],
    [
      "           j   j",
      "           k   k",
      "           k   k",
      "           k   k",
      "           k   k",
      "           j   l",
      "           k   k",
      "           k   k",
      "           k   k",
      "mbenco     k   k",
      "           l   l",
      "           k   k",
      "           k   k",
      "           k   k",
      "           k   k",
      "           j   j"
    ],
    [
      "ppppppqrstsrstsr",
      "ppppppqruwuuuwuu",
      "ppppppqruwuuuwuu",
      "ppppppqruwuuuwuu",
      "ppppppqruwuuuwuu",
      "ppppppqrstsrstsr",
      "ppppppqruwuuuwuu",
      "ppppppqruwuuuwuu",
      "ppppppqruwuuuwuu",
      "pbbpxpqruwuuuwuu",
      "ppppppqrstsrstsr",
      "ppppppqruwuuuwuu",
      "ppppppqruwuuuwuu",
      "ppppppqruwuuuwuu",
      "ppppppqruwuuuwuu",
      "ppppppqrstsrstsr"
    ],
    [
      "bbbbbbbbbbbbbbbb",
      "bbbbbbbbbbbbbbbb",
      "bbbbbbbbbbbbbbbb",
      "bbbbbbbbbbbbbbbb",
      "bbbbbbbbbbbbbbbb",
      "bbbbbbbbbbbbbbbb",
      "bbbbbbbbbbbbbbbb",
      "bbbbbbbbbbbbbbbb",
      "bbbbbbbbbbbbbbbb",
      "bbbbb bbbbbbbbbb",
      "bbbbbbbbbbbbbbbb",
      "bbbbbbbbbbbbbbbb",
      "bbbbbbbbbbbbbbbb",
      "bbbbbbbbbbbbbbbb",
      "bbbbbbbbbbbbbbbb",
      "bbbbbbbbbbbbbbbb"
    ]
  ]
}