{
  "name": "multi_officethefirst_0_base2",
  "refpalette": "deceasedcraft:multi_officethefirst_0/multi_officethefirst_0_base2_palette",
  "xsize": 16,
  "zsize": 16,
  "slices": [
    [
      "vvvvvvvvvvvvvvvv",
      "vaaaaaaaaaaaaaba",
      "va   cdaefffg   ",
      "va    dahhhh    ",
      "va    da iiij   ",
      "va    daefffg   ",
      "va    dahhhh    ",
      "va    da ikkj   ",
      "va    dalfffg   ",
      "va    dahhhh    ",
      "va    da kkkj   ",
      "va    daefffg   ",
      "va    dahhhh    ",
      "va    da kkkj   ",
      "va    dalfffg   ",
      "va    dahhhh    "
    ],
    [
      "vvvvvvvvvvvvvvvv",
      "vaaaaaaaaaaaaaba",
      "va     amnnof   ",
      "va    pqrrrs    ",
      "va    pa tttj   ",
      "va    pamnnof   ",
      "va    purrrs    ",
      "va    pa tttj   ",
      "va    pamnnof   ",
      "va    pqrrrs    ",
      "va    pa tttj   ",
      "va    pamnnof   ",
      "va    pqrrrs    ",
      "va    pa tttw   ",
      "va    pamnnof   ",
      "va    pqrrrs    "
    ],
    [
      "vvvvvvvvvvvvvvvv",
      "vaaaaaaaaaaaaaba",
      "va     axyyAf   ",
      "va     B   C    ",
      "va     a tttj   ",
      "va     axyyDf   ",
      "va     E        ",
      "va     a tttj   ",
      "va     axFyDf   ",
      "va     B        ",
      "va     a tttj   ",
      "va     axyyDf   ",
      "va     B        ",
      "va     a ttt    ",
      "va     axFy!f   ",
      "va     B        "
    ],
    [
      "vvvvvvvvvvvvvvvv",
      "vaaaaaaaaaaaaaba",
      "vad    axFy!f   ",
      "vad   Ia        ",
      "vad    a tttj   ",
      "vad    axyFDf   ",
      "vad   Ja        ",
      "vad    a tttj   ",
      "vad    axFyDf   ",
      "vad   Ia        ",
      "vad    a tttj   ",
      "vad    axyFDf   ",
      "vad   Ia        ",
      "vad    a tttK   ",
      "vad    axFyDf   ",
      "vad   Ia        "
    ],
    [
      "vvvvvvvvvvvvvvvv",
      "vaaaaaaaaaaaaaba",
      "va c   axyyDf   ",
      "vaL    a        ",
      "vaL    a tttj   ",
      "vaL    axyyDf   ",
      "vaL    a        ",
      "vaL    a tttj   ",
      "vaL    ax!FDf   ",
      "vaL    a        ",
      "vaL    a tttj   ",
      "vaL    axyFDf   ",
      "vaL    a        ",
      "vaL    a tttj   ",
      "vaL    axyFDf   ",
      "vaL    a        "
    ],
    [
      "vvvvvvvvvvvvvvvv",
      "vaaaaaaaaaaaaaba",
      "va  c  aMyFDf   ",
      "va     aN       ",
      "va     aNtttj   ",
      "va     aMFFDf   ",
      "va     aN       ",
      "va     aNtttj   ",
      "va     aMyyDf   ",
      "va     aN       ",
      "va     aNtttj   ",
      "va     aMyyDf   ",
      "va     aN       ",
      "va     aNtttj   ",
      "va     aMyyDf   ",
      "va     aN       "
    ]
  ]
}