{
  "name": "multi_officethefirst_0_ground",
  "refpalette": "deceasedcraft:multi_officethefirst_0/multi_officethefirst_0_ground_palette",
  "xsize": 16,
  "zsize": 16,
  "slices": [
    [
      "HHHHHHHHHHHHHHHH",
      "HHHHHHHHHHHHHHHH",
      "HHHaaaaaaaaaaaaa",
      "HHabbbbbbbbbbbbb",
      "HHabccccdccccdcc",
      "HHabceeefeeeefee",
      "HHabcegggggggggg",
      "HHabcegggggggggg",
      "HHabcegggggggggg",
      "HHabcegggggggggg",
      "HHabceeeeeeeeeee",
      "HHabcehhhhhhhhhh",
      "HHabceeeeeeeeeee",
      "HHabceaaaaaaaaaa",
      "HHabceaiiiiiiiii",
      "HHabceaiiiiiiiii"
    ],
    [
      "                ",
      "                ",
      "                ",
      "                ",
      "    cccccccccccc",
      "    cjjjjjjjjjjj",
      "    cj          ",
      "    cj          ",
      "    cj          ",
      "    ck          ",
      "    cellllllllll",
      "    cehhhhhhhhhh",
      "    cemmmmmmmmmm",
      "    ceffffffffff",
      "    cefn        ",
      "    cef       l "
    ],
    [
      "                ",
      "                ",
      "                ",
      "                ",
      "                ",
      "                ",
      "                ",
      "                ",
      "                ",
      "    c           ",
      "    cj          ",
      "    cjoooooooooo",
      "    cj          ",
      "    ckpppppppppp",
      "    cepo        ",
      "    cep         "
    ],
    [
      "                ",
      "                ",
      "                ",
      "                ",
      "                ",
      "                ",
      "                ",
      "                ",
      "                ",
      "                ",
      "                ",
      "                ",
      "                ",
      "    c pppppppppp",
      "    cjpq        ",
      "    cjp         "
    ],
    [
      "                ",
      "                ",
      "                ",
      "                ",
      "                ",
      "                ",
      "                ",
      "                ",
      "                ",
      "                ",
      "                ",
      "                ",
      "                ",
      "      pppppppppp",
      "      p         ",
      "      p         "
    ],
    [
      "                ",
      "                ",
      "                ",
      "                ",
      "                ",
      "                ",
      "                ",
      "                ",
      "                ",
      "                ",
      "                ",
      "                ",
      "                ",
      "      ffffffffff",
      "      f        r",
      "      f       ss"
    ]
  ]
}