{
  "name": "multi_officethefirst_0_base4",
  "refpalette": "deceasedcraft:multi_officethefirst_0/multi_officethefirst_0_base4_palette",
  "xsize": 16,
  "zsize": 16,
  "slices": [
    [
      "vvvvvvvvvvvvvvvv",
      "vaaaaaaaaaaaaaaa",
      "vabbbbbabbbbbbbb",
      "vabbbbbabbbbbbbb",
      "vabbbbbabbbbbbbb",
      "vabbbbbabbbbbbbb",
      "vabbbbbabbbbbbbb",
      "vabbbbbabbbbbbbb",
      "vabbbbbabbbbbbbb",
      "vabbbbbabbbbbbbb",
      "vabbbbbabbbbbbbb",
      "vabbbbbabbbbbbbb",
      "vabbbbbabbbbbbbb",
      "vabbbbbabbbbbbbb",
      "vabbbbbabbbbbbbb",
      "vabbbbbabbbbbbbb"
    ],
    [
      "vvvvvvvvvvvvvvvv",
      "vaaaaaaaaaaaaaaa",
      "vac  deafgghi   ",
      "vaj  k a        ",
      "vajl   a mmmn   ",
      "vao    afgghi   ",
      "vao p qa        ",
      "vao   ra mmmn   ",
      "vao  stafgghi   ",
      "vao  uta        ",
      "vao   ra mmmn   ",
      "vao   wafgghi   ",
      "vao   xa        ",
      "vao   xa mmmn   ",
      "vaoy  qafgghi   ",
      "vao y ra        "
    ],
    [
      "vvvvvvvvvvvvvvvv",
      "vaaaaaaaaaaaaaaa",
      "vaA    aBCCDi   ",
      "vaA k  a        ",
      "vaA    a mmmE   ",
      "vaF    aBCCDi   ",
      "vaA    a        ",
      "vaA   Ia mmmE   ",
      "vaA   JaBKCDi   ",
      "vaA   La        ",
      "vaA   Ma mmmE   ",
      "vaA    aBCCDi   ",
      "vaA    a        ",
      "vaA    a mmmE   ",
      "vaA    aBCCDi   ",
      "vaF    a        "
    ],
    [
      "vvvvvvvvvvvvvvvv",
      "vaaaaaaaaaaaaaaN",
      "vaO    aBCCDi   ",
      "vaOk   a        ",
      "va     a mmmE   ",
      "va     aBCCDi   ",
      "va     a        ",
      "va     a mmmE   ",
      "va     aBCCDi   ",
      "va     a        ",
      "va     a mmmE   ",
      "va     aBCKDi   ",
      "va    Pa        ",
      "va     a mmmE   ",
      "va     aBCCDi   ",
      "va     a        "
    ],
    [
      "vvvvvvvvvvvvvvvv",
      "vaaaaaaaaaaaaaNa",
      "va Q   aBCCDi   ",
      "vaR    a        ",
      "va     a mmmE   ",
      "va     aBKKDi   ",
      "va     a        ",
      "va     a mmmE   ",
      "va     aBCCDi   ",
      "va     a        ",
      "va     a mmmE   ",
      "va     aBCCDi   ",
      "va     a        ",
      "va     a mmmE   ",
      "va     aBCCDi   ",
      "va     a        "
    ],
    [
      "vvvvvvvvvvvvvvvv",
      "vaaaaaaaaaaaaaNa",
      "va  Q  aSKCDi   ",
      "va     aT       ",
      "va     aTmmmE   ",
      "va     aSCCDi   ",
      "va     aT       ",
      "va     aTmmmE   ",
      "va     aSCCUi   ",
      "va     aT  V    ",
      "va     aTmmmE   ",
      "va     aSCCDi   ",
      "va     aT       ",
      "va     aTmmmE   ",
      "va     aSCKDi   ",
      "va     aT       "
    ]
  ]
}