{
  "name": "multi_officethefirst_0_base1",
  "refpalette": "deceasedcraft:multi_officethefirst_0/multi_officethefirst_0_base1_palette",
  "xsize": 16,
  "zsize": 16,
  "slices": [
    [
      "vvvvvvvvvvvvvvvv",
      "vaaaaaaaaaaaaaba",
      "va   cdaefffg   ",
      "va    da        ",
      "va    da hhhi   ",
      "va    daefffg   ",
      "va    da        ",
      "va    da jjji   ",
      "va    daefffg   ",
      "va    da        ",
      "va    da jjji   ",
      "va    daefffg   ",
      "va    da        ",
      "va    da jhhi   ",
      "va    daefffg   ",
      "va    da        "
    ],
    [
      "vvvvvvvvvvvvvvvv",
      "vaaaaaaaaaaaaaab",
      "va     ak       ",
      "va    la        ",
      "va    la        ",
      "va    lak       ",
      "va    la        ",
      "va    la        ",
      "va    lak       ",
      "va    la        ",
      "va    la        ",
      "va    lak       ",
      "va    la        ",
      "va    la        ",
      "va    lak       ",
      "va    la        "
    ],
    [
      "vvvvvvvvvvvvvvvv",
      "vaaaaaaaaaaaaaaa",
      "va     a        ",
      "va     a        ",
      "va     a        ",
      "va     a        ",
      "va     a        ",
      "va     a        ",
      "va     a        ",
      "va     a        ",
      "va     a        ",
      "va     a        ",
      "va     a        ",
      "va     a        ",
      "va     a        ",
      "va     a        "
    ],
    [
      "vvvvvvvvvvvvvvvv",
      "vaaaaaaaaaaaaaaa",
      "va     a        ",
      "va     a        ",
      "va     a        ",
      "va     a        ",
      "va     a        ",
      "va     a        ",
      "va     a        ",
      "va     a        ",
      "va     a        ",
      "va     a        ",
      "va     a        ",
      "va     a        ",
      "va     a        ",
      "va     a        "
    ],
    [
      "vvvvvvvvvvvvvvvv",
      "vaaaaaaaaaaaaaaa",
      "vammmmmammmmmmmm",
      "vammmmmammmmmmmm",
      "vammnmmammnnmmmo",
      "vammmmmammnnmmmn",
      "vammmmmammmmmmmm",
      "vammmmmammmmmmmm",
      "vammommammmmmmmm",
      "vammmmmammmmmmmm",
      "vammmmmammmmmmmm",
      "vammmmmammonmmmn",
      "vammommammonmmmn",
      "vammmmmammmmmmmm",
      "vammmmmammmmmmmm",
      "vammmmmammmmmmmm"
    ],
    [
      "vvvvvvvvvvvvvvvv",
      "vppppppppppppppp",
      "vppppppppppppppp",
      "vppppppppppppppp",
      "vppppppppppppppp",
      "vppppqqqqqqqqqqq",
      "vppppprrrrrrrrrr",
      "vppppprrrrrrrrrr",
      "vppppprrrrrrrrrr",
      "vppppprrrrrrrrrr",
      "vppppppppppppppp",
      "vppppppppppppppp",
      "vppppppppppppppp",
      "vppppppppppppppp",
      "vppppppppppppppp",
      "vppppppppppppppp"
    ]
  ]
}