{
  "name": "multi_officethefirst_0_base3",
  "refpalette": "deceasedcraft:multi_officethefirst_0/multi_officethefirst_0_base3_palette",
  "xsize": 16,
  "zsize": 16,
  "slices": [
    [
      "vvvvvvvvvvvvvvvv",
      "vaaaaaaaaaaaaaba",
      "va   cdaefffg   ",
      "va    dahhhh    ",
      "va    da ijjk   ",
      "va    dalfffg   ",
      "va    dahhhh    ",
      "va    da jjjk   ",
      "va    dalfffg   ",
      "va    dahhhh    ",
      "va    da iiik   ",
      "va    daefffg   ",
      "va    dahhhh    ",
      "va    da ijjk   ",
      "va    dalfffg   ",
      "va    dahhhh    "
    ],
    [
      "vvvvvvvvvvvvvvvv",
      "vaaaaaaaaaaaaaba",
      "va     amnnof   ",
      "va    pqrrrs    ",
      "va    pa tttk   ",
      "va    pamnnof   ",
      "va    pqrrrs    ",
      "va    pa tttk   ",
      "va    pamnnof   ",
      "va    pqrrrs    ",
      "va    pa tttk   ",
      "va    pamnnof   ",
      "va    pqrrrs    ",
      "va    pa tttk   ",
      "va    pamnnof   ",
      "va    purrrs    "
    ],
    [
      "vvvvvvvvvvvvvvvv",
      "vaaaaaaaaaaaaaba",
      "va     awxxyf   ",
      "va     A        ",
      "va     a tttk   ",
      "va     awBxyf   ",
      "va     A        ",
      "va     a tttk   ",
      "va     awxxyf   ",
      "va     A        ",
      "va     a tttk   ",
      "va     awxByf   ",
      "va     A        ",
      "va     a tttk   ",
      "va     awxxCf   ",
      "va     D   E    "
    ],
    [
      "vvvvvvvvvvvvvvvv",
      "vaaaaaaaaaaaaaba",
      "vad    awxxyf   ",
      "vad   Fa        ",
      "vad    a tttk   ",
      "vad    awxxyf   ",
      "vad   Fa        ",
      "vad    a tttk   ",
      "vad    awxxyf   ",
      "vad   Fa        ",
      "vad    a tttk   ",
      "vad    awxByf   ",
      "vad   Fa        ",
      "vad    a tttk   ",
      "vad    awBxyf   ",
      "vad   Ia        "
    ],
    [
      "vvvvvvvvvvvvvvvv",
      "vaaaaaaaaaaaaaba",
      "va c   awxByf   ",
      "vaJ    a        ",
      "vaJ    a tttk   ",
      "vaJ    awxxKf   ",
      "vaJ    a   E    ",
      "vaJ    a tttk   ",
      "vaJ    awxxyf   ",
      "vaJ    a        ",
      "vaJ    a tttk   ",
      "vaJ    awxxyf   ",
      "vaJ    a        ",
      "vaJ    a tttk   ",
      "vaJ    awxxyf   ",
      "vaJ    a        "
    ],
    [
      "vvvvvvvvvvvvvvvv",
      "vaaaaaaaaaaaaaba",
      "va  c  aL!Byf   ",
      "va     aM       ",
      "va     aMtttk   ",
      "va     aLxxyf   ",
      "va     aM       ",
      "va     aMtttk   ",
      "va     aLxxyf   ",
      "va     aM       ",
      "va     aMtttk   ",
      "va     aLxxyf   ",
      "va     aM       ",
      "va     aMtttk   ",
      "va     aLxxyf   ",
      "va     aM       "
    ]
  ]
}