{
  "name": "multi_gallery_11_base1",
  "refpalette": "deceasedcraft:multi_gallery_11/multi_gallery_11_base1_palette",
  "xsize": 16,
  "zsize": 16,
  "slices": [
    [
      "  a           bv",
      "              bv",
      "  c           bv",
      "bbbbbbbbbbbbbbdv",
      "effffffffffffffv",
      "effffffffffffffv",
      "effffffffffffffv",
      "effffffffffffffv",
      "effffffffffffffv",
      "effffffffffffffv",
      "effffffffffffffv",
      "effffffffffffffv",
      "edfffffffffffffv",
      "dgdffffffffffffv",
      "fdfffffffffffffv",
      "vvvvvvvvvvvvvvvv"
    ],
    [
      "  ~           bv",
      "              bv",
      "  h           bv",
      "bbbbbbbbbbbbbbdv",
      "effffffffffffffv",
      "effffffffffffffv",
      "effffffffffffffv",
      "effffffffffffffv",
      "effffffffffffffv",
      "effffffffffffffv",
      "effffffffffffffv",
      "effffffffffffffv",
      "edfffffffffffffv",
      "dgdffffffffffffv",
      "fdfffffffffffffv",
      "vvvvvvvvvvvvvvvv"
    ],
    [
      "              bv",
      "              bv",
      "              bv",
      "bbbbbbbbbbbbbbdv",
      "effffffffffffffv",
      "effffffffffffffv",
      "effffffffffffffv",
      "effffffffffffffv",
      "effffffffffffffv",
      "effffffffffffffv",
      "effffffffffffffv",
      "effffffffffffffv",
      "edfffffffffffffv",
      "dgdffffffffffffv",
      "fdfffffffffffffv",
      "vvvvvvvvvvvvvvvv"
    ],
    [
      "              bv",
      "              bv",
      "              bv",
      "bbbbbbbbbbbbbbdv",
      "effffffffffffffv",
      "effffffffffffffv",
      "effffffffffffffv",
      "effffffffffffffv",
      "effffffffffffffv",
      "effffffffffffffv",
      "effffffffffffffv",
      "effffffffffffffv",
      "edfffffffffffffv",
      "dgdffffffffffffv",
      "fdfffffffffffffv",
      "vvvvvvvvvvvvvvvv"
    ],
    [
      "iiiiiiiiiiiiiibv",
      "iiiiiiiiiiiiiibv",
      "iiiiiiiiiiiiiibv",
      "bbbbbbbbbbbbbbdv",
      "effffffffffffffv",
      "effffffffffffffv",
      "effffffffffffffv",
      "effffffffffffffv",
      "effffffffffffffv",
      "effffffffffffffv",
      "effffffffffffffv",
      "effffffffffffffv",
      "edfffffffffffffv",
      "dgdffffffffffffv",
      "fdfffffffffffffv",
      "vvvvvvvvvvvvvvvv"
    ],
    [
      "bbbbbbbbbbbbbbdv",
      "bbbbbbbbbbbbbbdv",
      "bbbbbbbbbbbbbbdv",
      "bbbbbbbbbbbbbbdv",
      "effffffffffffffv",
      "effffffffffffffv",
      "effffffffffffffv",
      "effffffffffffffv",
      "effffffffffffffv",
      "effffffffffffffv",
      "bjfffffffffffffv",
      "bjfffffffffffffv",
      "ekfffffffffffffv",
      "dldffffffffffffv",
      "fdfffffffffffffv",
      "vvvvvvvvvvvvvvvv"
    ]
  ]
}