{
  "name": "multi_gallery_11_base2",
  "refpalette": "deceasedcraft:multi_gallery_11/multi_gallery_11_base2_palette",
  "xsize": 16,
  "zsize": 16,
  "slices": [
    [
      "aaaaaaaaaaaaaabv",
      "aaaaaaaaaaaaaabv",
      "aaaaaaaaaaaaaabv",
      "bbbbbbbbbbbbbbbv",
      "cddddddddddddddv",
      "cddddddddddddddv",
      "cddddddddddddddv",
      "cddddddddddddddv",
      "cddddddddddddddv",
      "cddddddddddddddv",
      "cddddddddddddddv",
      "cddddddddddddddv",
      "cddddddddddddddv",
      "dddddddddddddddv",
      "dddddddddddddddv",
      "vvvvvvvvvvvvvvvv"
    ],
    [
      "eeeeeeeeeeeeeeav",
      "eeeeeeeeeeeeeeav",
      "eeeeeeeeeeeeeeav",
      "aaaaaaaaaaaaaabv",
      "cddddddddddddddv",
      "cddddddddddddddv",
      "cddddddddddddddv",
      "cddddddddddddddv",
      "cddddddddddddddv",
      "cddddddddddddddv",
      "cddddddddddddddv",
      "cddddddddddddddv",
      "cddddddddddddddv",
      "bbdddddddddddddv",
      "dddddddddddddddv",
      "vvvvvvvvvvvvvvvv"
    ],
    [
      "f g f  f h  i av",
      "  if g  f  f fav",
      "  f   f   f   av",
      "aaaaaaaaaaaaaabv",
      "cddddddddddddddv",
      "cddddddddddddddv",
      "cddddddddddddddv",
      "cddddddddddddddv",
      "cddddddddddddddv",
      "cddddddddddddddv",
      "cddddddddddddddv",
      "cddddddddddddddv",
      "cbdddddddddddddv",
      "jkbddddddddddddv",
      "bbdddddddddddddv",
      "vvvvvvvvvvvvvvvv"
    ],
    [
      "l g m  l n    av",
      "   m o  l  l mav",
      "  m   m   m   av",
      "aaaaaaaaaaaaaabv",
      "cddddddddddddddv",
      "cddddddddddddddv",
      "cddddddddddddddv",
      "cddddddddddddddv",
      "cddddddddddddddv",
      "cddddddddddddddv",
      "cddddddddddddddv",
      "cddddddddddddddv",
      "cbdddddddddddddv",
      "bpbddddddddddddv",
      "dbdddddddddddddv",
      "vvvvvvvvvvvvvvvv"
    ],
    [
      "  o m    ~    av",
      "   l o       lav",
      "  m   l   m   av",
      "aaaaaaaaaaaaaabv",
      "cddddddddddddddv",
      "cddddddddddddddv",
      "cddddddddddddddv",
      "cddddddddddddddv",
      "cddddddddddddddv",
      "cddddddddddddddv",
      "cddddddddddddddv",
      "cddddddddddddddv",
      "cbdddddddddddddv",
      "bqbddddddddddddv",
      "dbdddddddddddddv",
      "vvvvvvvvvvvvvvvv"
    ],
    [
      "  r l         av",
      "     ~        av",
      "  m   !   l   av",
      "aaaaaaaaaaaaaabv",
      "cddddddddddddddv",
      "cddddddddddddddv",
      "cddddddddddddddv",
      "cddddddddddddddv",
      "cddddddddddddddv",
      "cddddddddddddddv",
      "cddddddddddddddv",
      "cddddddddddddddv",
      "cbdddddddddddddv",
      "bqbddddddddddddv",
      "dbdddddddddddddv",
      "vvvvvvvvvvvvvvvv"
    ]
  ]
}