{
  "name": "multi_gallery_11_floor2",
  "refpalette": "deceasedcraft:multi_gallery_11/multi_gallery_11_floor2_palette",
  "xsize": 16,
  "zsize": 16,
  "slices": [
    [
      "a               ",
      "b               ",
      "b               ",
      "b        cd     ",
      "          e     ",
      "                ",
      "                ",
      "                ",
      "                ",
      "                ",
      "                ",
      "       cd       ",
      "        e       ",
      "                ",
      "                ",
      "                "
    ],
    [
      "ffa             ",
      "ghb             ",
      "ghb             ",
      "ghb       d     ",
      "hbb       ei    ",
      "hb              ",
      "hb              ",
      "hb              ",
      "bb              ",
      "b               ",
      "b               ",
      "a       d       ",
      "        ei      ",
      "                ",
      "                ",
      "                "
    ],
    [
      " jf             ",
      " kgffff         ",
      " kghhhhffff     ",
      " kghhhhhhhhffff ",
      "kgghhhhhhhhhhhf ",
      "kghhhhhhhhhhhhf ",
      "kghhhhhhhhhhhhf ",
      "kghhhhhhhhhhhf  ",
      "gghhhhhhhhhhhf  ",
      "ghhhhhhhhhhhhf  ",
      "ghhhhhhhhhhhhf  ",
      "fhhhhhhhhhhhf   ",
      " ffffhhhhhhhf   ",
      "     ffffhhhf   ",
      "         ffff   ",
      "                "
    ],
    [
      "                ",
      "   jjjj         ",
      "   kkkkjjjj     ",
      "   kkkkkkkkjjjj ",
      "   kkkkkkkkkkkj ",
      "  kkkkkkkkkkkkj ",
      "  kkkkkkkkkkkkj ",
      "  kkkkkkkkkkkj  ",
      "  kkkkkkkkkkkj  ",
      " kkkkkkkkkkkkj  ",
      " kkkkkkkkkkkkj  ",
      "jkkkkkkkkkkkj   ",
      " jjjjkkkkkkkj   ",
      "     jjjjkkkj   ",
      "         jjjj   ",
      "                "
    ],
    [
      "                ",
      "                ",
      "                ",
      "                ",
      "                ",
      "                ",
      "                ",
      "                ",
      "                ",
      "                ",
      "                ",
      "                ",
      "                ",
      "                ",
      "                ",
      "                "
    ],
    [
      "                ",
      "                ",
      "                ",
      "                ",
      "                ",
      "                ",
      "                ",
      "                ",
      "                ",
      "                ",
      "                ",
      "                ",
      "                ",
      "                ",
      "                ",
      "                "
    ]
  ]
}