{
  "name": "multi_terraceplaza_13_base2",
  "refpalette": "deceasedcraft:multi_terraceplaza_13/multi_terraceplaza_13_base2_palette",
  "xsize": 16,
  "zsize": 16,
  "slices": [
    [
      "aaaaaaaaaaaaaaaa",
      "aaaaaaaaaaaaaaaa",
      "aaaaaaaaaaaaaaaa",
      "aaaaaaaaaaaaaaaa",
      "aaaaaaaaaaaaaaaa",
      "aaaaaaaaaaaaaaaa",
      "aaaaaaaaaaaaaaaa",
      "aaaaaaaaaaaaaaaa",
      "aaaaaaaaaaaaaaaa",
      "aaaaaaaaaaaaaaaa",
      "aaaaaaaaaaaaaaaa",
      "aaaaaaaaaaaaaaaa",
      "aaaaaaaaaaaaaaaa",
      "bbbbbbbbbbbbbbbb",
      "cccccccccccccccc",
      "vvvvvvvvvvvvvvvv"
    ],
    [
      "    dd ddd     e",
      "   ff    ff     ",
      "  ghhi  ghhi  j ",
      "  ghhi  ghhi  j ",
      "   kk    kk   j ",
      "              j ",
      "   ff    ff   j ",
      "  ghhi  ghhi  j ",
      "  ghhi  ghhi    ",
      "   kk    kk    e",
      "lllllllllllllll ",
      "mmmmmmmmmmmmmmmn",
      "mmmmmmmmmmmmmmmn",
      "bbbbbbbbbbbbbbbb",
      "cccccccccccccccc",
      "vvvvvvvvvvvvvvvv"
    ],
    [
      "               e",
      "                ",
      "         o      ",
      "    o    p      ",
      "                ",
      "                ",
      "                ",
      "          o     ",
      "   q            ",
      "               e",
      "                ",
      "rrrrrrrrrrrrrrrn",
      "sssssssssssssssn",
      "bbbbbbbbbbbbbbbb",
      "cccccccccccccccc",
      "vvvvvvvvvvvvvvvv"
    ],
    [
      "               e",
      "                ",
      "                ",
      "                ",
      "                ",
      "                ",
      "                ",
      "                ",
      "                ",
      "               e",
      "                ",
      "               n",
      "sssssssssssssssn",
      "bbbbbbbbbbbbbbbb",
      "cccccccccccccccc",
      "vvvvvvvvvvvvvvvv"
    ],
    [
      "               e",
      "                ",
      "                ",
      "                ",
      "                ",
      "                ",
      "                ",
      "                ",
      "                ",
      "               e",
      "                ",
      "               n",
      "sss s ss  s  ssn",
      "bbbbbbbbbbbbbbbb",
      "cccccccccccccccc",
      "vvvvvvvvvvvvvvvv"
    ],
    [
      "               e",
      "               e",
      "               e",
      "               e",
      "               e",
      "               e",
      "               e",
      "               e",
      "               e",
      "               e",
      "                ",
      "nnnnnnnnnnnnnnnn",
      "tututuwtutututun",
      "bbbbbbbbbbbbbbbb",
      "cccccccccccccccc",
      "vvvvvvvvvvvvvvvv"
    ]
  ]
}