{
  "name": "multi_terraceplaza_13_base1",
  "refpalette": "deceasedcraft:multi_terraceplaza_13/multi_terraceplaza_13_base1_palette",
  "xsize": 16,
  "zsize": 16,
  "slices": [
    [
      "               a",
      "               a",
      "               a",
      "               a",
      "               a",
      "               a",
      "               a",
      "               a",
      "               a",
      "               a",
      "                ",
      "bbbbbbbbbbbbbbbb",
      "cccccccccccccccb",
      "dddddddddddddddd",
      "eeeeeeeeeeeeeeee",
      "vvvvvvvvvvvvvvvv"
    ],
    [
      "               a",
      "               a",
      "               a",
      "               a",
      "               a",
      "               a",
      "               a",
      "               a",
      "               a",
      "               a",
      "                ",
      "bbbbbbbbbbbbbbbb",
      "   f     f     b",
      "dddddddddddddddd",
      "eeeeeeeeeeeeeeee",
      "vvvvvvvvvvvvvvvv"
    ],
    [
      "              ga",
      "              ga",
      "              ga",
      "              ga",
      "              ga",
      "              ga",
      "              ga",
      "              ga",
      "              ga",
      "              ga",
      "                ",
      "bbbbbbbbbbbbbbbb",
      "hhhhhhhhhhhhhhhh",
      "dddddddddddddddd",
      "eeeeeeeeeeeeeeee",
      "vvvvvvvvvvvvvvvv"
    ],
    [
      "aaaaaaaaaaaaaaaa",
      "aaaaaaaaaaaaaaaa",
      "aaaaaaaaaaaaaaaa",
      "aaaaaaaaaaaaaaaa",
      "aaaaaaaaaaaaaaaa",
      "aaaaaaaaaaaaaaaa",
      "aaaaaaaaaaaaaaaa",
      "aaaaaaaaaaaaaaaa",
      "aaaaaaaaaaaaaaaa",
      "aaaaaaaaaaaaaaaa",
      "iiiiiiiiiiiiiiii",
      "bbbbbbbbbbbbbbbb",
      "eeeeeeeeeeeeeeee",
      "dddddddddddddddd",
      "eeeeeeeeeeeeeeee",
      "vvvvvvvvvvvvvvvv"
    ],
    [
      "hhhjhhhhhjhhhhhh",
      "eeeeeeeeeeeeeeee",
      "eeeeeeeeeeeeeeee",
      "eeeeeeeeeeeeeeee",
      "eeeeeeeeeeeeeeee",
      "eeeeeeeeeeeeeeee",
      "eeeeeeeeeeeeeeee",
      "eeeeeeeeeeeeeeee",
      "kkkkkkkkkkkkkkkk",
      "lkkklkkkkllkklkl",
      "kkllkkkklkkkllkk",
      "kkkkkkkkkkkkkkkk",
      "kkkkkkkkkkkkkkkk",
      "dddddddddddddddd",
      "eeeeeeeeeeeeeeee",
      "vvvvvvvvvvvvvvvv"
    ],
    [
      "eeeeeeeeeeeeeeee",
      "eeeeeeeeeeeeeeee",
      "eeeeeeeeeeeeeeee",
      "eeeeeeeeeeeeeeee",
      "eeeeeeeeeeeeeeee",
      "kkkkkkkkkkkkkkkk",
      "kkkkkkkkkkkkkkkk",
      "kkkkkkkkkkkkkkkk",
      "mmmmm    mmmmmmk",
      "                ",
      " n    n    n    ",
      "opqrsopqrsopqrso",
      "kkkkkkkkkkkkkkkk",
      "tttttttttttttttt",
      "eeeeeeeeeeeeeeee",
      "vvvvvvvvvvvvvvvv"
    ]
  ]
}