{
  "name": "multi_terraceplaza_13_ground",
  "refpalette": "deceasedcraft:multi_terraceplaza_13/multi_terraceplaza_13_ground_palette",
  "xsize": 16,
  "zsize": 16,
  "slices": [
    [
      "aaaaaaaaaaaaaaaa",
      "aaaaaaaaaaaaaaaa",
      "bbbbbbbbbbbbbaaa",
      "ccccccccccccbbba",
      "ccccccccccccccbb",
      "     ddddddccccb",
      "                ",
      "                ",
      "                ",
      "                ",
      "                ",
      " e    e    e    ",
      "fgfffffffffgffff",
      "bbbbbbbbbbbbbbbb",
      "aaaaaaaaaaaaaaaa",
      "aaaaaaaaaaaaaaaa"
    ],
    [
      "                ",
      "                ",
      "                ",
      "                ",
      "              hi",
      "               i",
      "                ",
      "                ",
      "                ",
      "                ",
      "                ",
      " j    j    j    ",
      "                ",
      "ikiiiiiiiiikiiii",
      "                ",
      "                "
    ],
    [
      "                ",
      "                ",
      "                ",
      "                ",
      "                ",
      "                ",
      "                ",
      "                ",
      "                ",
      "                ",
      "                ",
      " j    j    j    ",
      "                ",
      "                ",
      "                ",
      "                "
    ],
    [
      "                ",
      "                ",
      "                ",
      "                ",
      "                ",
      "                ",
      "                ",
      "                ",
      "                ",
      "                ",
      "                ",
      "                ",
      "                ",
      "                ",
      "                ",
      "                "
    ],
    [
      "                ",
      "                ",
      "                ",
      "                ",
      "                ",
      "                ",
      "                ",
      "                ",
      "                ",
      "                ",
      "                ",
      "                ",
      "                ",
      "                ",
      "                ",
      "                "
    ],
    [
      "lllllmnollllllll",
      "lllllmpollllllll",
      "lllllmqollllllll",
      "llllllrlllllllll",
      "                ",
      "                ",
      "                ",
      "                ",
      "                ",
      "                ",
      "                ",
      "                ",
      "                ",
      "                ",
      "                ",
      "                "
    ]
  ]
}